File: Lab10/HDPE_S6_1.csv
Results Table 1
,Specimen label,Thickness,Width,Length,Rate 1
,,(mm),(mm),(mm),(mm/min)
"1","hdpe","3.20","12.73","94.87","25.40"
"2","hdpe5","3.18","12.73","87.86","127.00"
"3","hdpe20","3.18","12.67","91.29","508.00"

Results Table 2


1,Time,Displacement,Force
,(s),(mm),(kN)
"","0.0000","0.0000","0.0249"
"","0.1600","0.0299","0.0491"
"","0.3200","0.1086","0.1075"
"","0.4800","0.1756","0.1508"
"","0.6400","0.2435","0.1911"
"","0.8000","0.3115","0.2286"
"","0.9600","0.3783","0.2627"
"","1.1200","0.4467","0.2960"
"","1.2800","0.5146","0.3277"
"","1.4400","0.5816","0.3574"
"","1.6000","0.6497","0.3865"
"","1.7600","0.7178","0.4140"
"","1.9200","0.7855","0.4405"
"","2.0800","0.8525","0.4650"
"","2.2400","0.9205","0.4894"
"","2.4000","0.9889","0.5125"
"","2.5600","1.0558","0.5338"
"","2.7200","1.1237","0.5548"
"","2.8800","1.1918","0.5749"
"","3.0400","1.2592","0.5937"
"","3.2000","1.3270","0.6120"
"","3.3600","1.3947","0.6291"
"","3.5200","1.4626","0.6461"
"","3.6800","1.5299","0.6614"
"","3.8400","1.5981","0.6773"
"","4.0000","1.6662","0.6919"
"","4.1600","1.7328","0.7052"
"","4.3200","1.8012","0.7191"
"","4.4800","1.8695","0.7326"
"","4.6400","1.9365","0.7448"
"","4.8000","2.0041","0.7566"
"","4.9600","2.0723","0.7684"
"","5.1200","2.1400","0.7802"
"","5.2800","2.2074","0.7907"
"","5.4400","2.2752","0.8012"
"","5.6000","2.3433","0.8120"
"","5.7600","2.4105","0.8212"
"","5.9200","2.4786","0.8310"
"","6.0800","2.5466","0.8405"
"","6.2400","2.6136","0.8494"
"","6.4000","2.6816","0.8581"
"","6.5600","2.7495","0.8667"
"","6.7200","2.8174","0.8752"
"","6.8800","2.8846","0.8828"
"","7.0400","2.9527","0.8909"
"","7.2000","3.0211","0.8988"
"","7.3600","3.0878","0.9055"
"","7.5200","3.1557","0.9123"
"","7.6800","3.2241","0.9197"
"","7.8400","3.2910","0.9258"
"","8.0000","3.3590","0.9324"
"","8.1600","3.4269","0.9388"
"","8.3200","3.4945","0.9449"
"","8.4800","3.5622","0.9508"
"","8.6400","3.6300","0.9566"
"","8.8000","3.6982","0.9622"
"","8.9600","3.7650","0.9671"
"","9.1200","3.8331","0.9726"
"","9.2800","3.9014","0.9779"
"","9.4400","3.9683","0.9825"
"","9.6000","4.0364","0.9875"
"","9.7600","4.1042","0.9918"
"","9.9200","4.1721","0.9967"
"","10.0800","4.2396","1.0008"
"","10.2400","4.3072","1.0052"
"","10.4000","4.3756","1.0094"
"","10.5600","4.4422","1.0128"
"","10.7200","4.5105","1.0168"
"","10.8800","4.5788","1.0209"
"","11.0400","4.6456","1.0240"
"","11.2000","4.7136","1.0274"
"","11.3600","4.7817","1.0311"
"","11.5200","4.8493","1.0340"
"","11.6800","4.9166","1.0368"
"","11.8400","4.9846","1.0400"
"","12.0000","5.0528","1.0433"
"","12.1600","5.1197","1.0456"
"","12.3200","5.1878","1.0482"
"","12.4800","5.2560","1.0509"
"","12.6400","5.3230","1.0532"
"","12.8000","5.3911","1.0556"
"","12.9600","5.4590","1.0578"
"","13.1200","5.5267","1.0600"
"","13.2800","5.5939","1.0619"
"","13.4400","5.6619","1.0639"
"","13.6000","5.7302","1.0663"
"","13.7600","5.7968","1.0676"
"","13.9200","5.8651","1.0697"
"","14.0800","5.9335","1.0717"
"","14.2400","6.0004","1.0729"
"","14.4000","6.0683","1.0746"
"","14.5600","6.1363","1.0761"
"","14.7200","6.2039","1.0775"
"","14.8800","6.2714","1.0788"
"","15.0400","6.3393","1.0803"
"","15.2000","6.4074","1.0818"
"","15.3600","6.4743","1.0825"
"","15.5200","6.5427","1.0838"
"","15.6800","6.6108","1.0852"
"","15.8400","6.6777","1.0857"
"","16.0000","6.7455","1.0868"
"","16.1600","6.8137","1.0878"
"","16.3200","6.8813","1.0888"
"","16.4800","6.9487","1.0891"
"","16.6400","7.0163","1.0898"
"","16.8000","7.0850","1.0910"
"","16.9600","7.1518","1.0913"
"","17.1200","7.2199","1.0922"
"","17.2800","7.2880","1.0931"
"","17.4400","7.3548","1.0928"
"","17.6000","7.4231","1.0934"
"","17.7600","7.4910","1.0943"
"","17.9200","7.5585","1.0944"
"","18.0800","7.6260","1.0946"
"","18.2400","7.6941","1.0951"
"","18.4000","7.7622","1.0957"
"","18.5600","7.8290","1.0958"
"","18.7200","7.8972","1.0959"
"","18.8800","7.9655","1.0964"
"","19.0400","8.0323","1.0960"
"","19.2000","8.1003","1.0964"
"","19.3600","8.1680","1.0962"
"","19.5200","8.2359","1.0966"
"","19.6800","8.3035","1.0964"
"","19.8400","8.3712","1.0963"
"","20.0000","8.4395","1.0967"
"","20.1600","8.5064","1.0962"
"","20.3200","8.5746","1.0964"
"","20.4800","8.6428","1.0964"
"","20.6400","8.7095","1.0958"
"","20.8000","8.7776","1.0956"
"","20.9600","8.8458","1.0961"
"","21.1200","8.9133","1.0956"
"","21.2800","8.9807","1.0950"
"","21.4400","9.0486","1.0950"
"","21.6000","9.1169","1.0948"
"","21.7600","9.1837","1.0941"
"","21.9200","9.2519","1.0940"
"","22.0800","9.3198","1.0939"
"","22.2400","9.3869","1.0930"
"","22.4000","9.4552","1.0931"
"","22.5600","9.5228","1.0925"
"","22.7200","9.5904","1.0921"
"","22.8800","9.6580","1.0914"
"","23.0400","9.7262","1.0912"
"","23.2000","9.7943","1.0910"
"","23.3600","9.8610","1.0901"
"","23.5200","9.9291","1.0901"
"","23.6800","9.9975","1.0895"
"","23.8400","10.0644","1.0890"
"","24.0000","10.1323","1.0883"
"","24.1600","10.2004","1.0879"
"","24.3200","10.2681","1.0873"
"","24.4800","10.3354","1.0865"
"","24.6400","10.4033","1.0858"
"","24.8000","10.4713","1.0856"
"","24.9600","10.5383","1.0846"
"","25.1200","10.6068","1.0842"
"","25.2800","10.6747","1.0836"
"","25.4400","10.7416","1.0826"
"","25.6000","10.8098","1.0821"
"","25.7600","10.8778","1.0814"
"","25.9200","10.9451","1.0807"
"","26.0800","11.0127","1.0800"
"","26.2400","11.0807","1.0794"
"","26.4000","11.1488","1.0787"
"","26.5600","11.2159","1.0780"
"","26.7200","11.2837","1.0771"
"","26.8800","11.3521","1.0767"
"","27.0400","11.4192","1.0758"
"","27.2000","11.4872","1.0750"
"","27.3600","11.5550","1.0743"
"","27.5200","11.6223","1.0735"
"","27.6800","11.6900","1.0726"
"","27.8400","11.7580","1.0718"
"","28.0000","11.8260","1.0712"
"","28.1600","11.8929","1.0699"
"","28.3200","11.9613","1.0694"
"","28.4800","12.0296","1.0689"
"","28.6400","12.0962","1.0674"
"","28.8000","12.1644","1.0667"
"","28.9600","12.2323","1.0665"
"","29.1200","12.2999","1.0654"
"","29.2800","12.3675","1.0643"
"","29.4400","12.4354","1.0635"
"","29.6000","12.5031","1.0628"
"","29.7600","12.5705","1.0619"
"","29.9200","12.6385","1.0609"
"","30.0800","12.7068","1.0603"
"","30.2400","12.7734","1.0591"
"","30.4000","12.8418","1.0585"
"","30.5600","12.9097","1.0574"
"","30.7200","12.9771","1.0566"
"","30.8800","13.0446","1.0556"
"","31.0400","13.1126","1.0547"
"","31.2000","13.1809","1.0541"
"","31.3600","13.2477","1.0528"
"","31.5200","13.3158","1.0523"
"","31.6800","13.3840","1.0514"
"","31.8400","13.4510","1.0502"
"","32.0000","13.5192","1.0494"
"","32.1600","13.5871","1.0483"
"","32.3200","13.6543","1.0476"
"","32.4800","13.7222","1.0466"
"","32.6400","13.7902","1.0458"
"","32.8000","13.8579","1.0446"
"","32.9600","13.9250","1.0435"
"","33.1200","13.9931","1.0426"
"","33.2800","14.0614","1.0420"
"","33.4400","14.1283","1.0409"
"","33.6000","14.1964","1.0400"
"","33.7600","14.2643","1.0390"
"","33.9200","14.3318","1.0383"
"","34.0800","14.3995","1.0372"
"","34.2400","14.4674","1.0362"
"","34.4000","14.5353","1.0356"
"","34.5600","14.6023","1.0342"
"","34.7200","14.6706","1.0335"
"","34.8800","14.7387","1.0325"
"","35.0400","14.8056","1.0312"
"","35.2000","14.8737","1.0304"
"","35.3600","14.9419","1.0297"
"","35.5200","15.0092","1.0287"
"","35.6800","15.0769","1.0276"
"","35.8400","15.1447","1.0267"
"","36.0000","15.2123","1.0258"
"","36.1600","15.2798","1.0245"
"","36.3200","15.3478","1.0236"
"","36.4800","15.4160","1.0231"
"","36.6400","15.4828","1.0216"
"","36.8000","15.5512","1.0209"
"","36.9600","15.6192","1.0200"
"","37.1200","15.6864","1.0191"
"","37.2800","15.7541","1.0179"
"","37.4400","15.8220","1.0167"
"","37.6000","15.8901","1.0161"
"","37.7600","15.9570","1.0147"
"","37.9200","16.0251","1.0139"
"","38.0800","16.0934","1.0132"
"","38.2400","16.1604","1.0116"
"","38.4000","16.2284","1.0108"
"","38.5600","16.2963","1.0097"
"","38.7200","16.3634","1.0086"
"","38.8800","16.4316","1.0078"
"","39.0400","16.4994","1.0067"
"","39.2000","16.5671","1.0057"
"","39.3600","16.6344","1.0047"
"","39.5200","16.7029","1.0039"
"","39.6800","16.7710","1.0030"
"","39.8400","16.8374","1.0017"
"","40.0000","16.9057","1.0005"
"","40.1600","16.9738","0.9996"
"","40.3200","17.0412","0.9987"
"","40.4800","17.1088","0.9976"
"","40.6400","17.1767","0.9967"
"","40.8000","17.2447","0.9960"
"","40.9600","17.3119","0.9946"
"","41.1200","17.3798","0.9935"
"","41.2800","17.4480","0.9926"
"","41.4400","17.5148","0.9914"
"","41.6000","17.5832","0.9906"
"","41.7600","17.6511","0.9894"
"","41.9200","17.7181","0.9882"
"","42.0800","17.7861","0.9872"
"","42.2400","17.8542","0.9865"
"","42.4000","17.9223","0.9855"
"","42.5600","17.9891","0.9842"
"","42.7200","18.0573","0.9832"
"","42.8800","18.1255","0.9825"
"","43.0400","18.1923","0.9810"
"","43.2000","18.2603","0.9801"
"","43.3600","18.3282","0.9793"
"","43.5200","18.3959","0.9781"
"","43.6800","18.4637","0.9770"
"","43.8400","18.5314","0.9762"
"","44.0000","18.5992","0.9751"
"","44.1600","18.6665","0.9736"
"","44.3200","18.7346","0.9731"
"","44.4800","18.8027","0.9719"
"","44.6400","18.8693","0.9705"
"","44.8000","18.9377","0.9697"
"","44.9600","19.0060","0.9687"
"","45.1200","19.0730","0.9675"
"","45.2800","19.1408","0.9662"
"","45.4400","19.2089","0.9654"
"","45.6000","19.2769","0.9646"
"","45.7600","19.3438","0.9632"
"","45.9200","19.4118","0.9623"
"","46.0800","19.4799","0.9613"
"","46.2400","19.5469","0.9597"
"","46.4000","19.6152","0.9591"
"","46.5600","19.6829","0.9579"
"","46.7200","19.7504","0.9567"
"","46.8800","19.8182","0.9558"
"","47.0400","19.8862","0.9548"
"","47.2000","19.9538","0.9536"
"","47.3600","20.0211","0.9523"
"","47.5200","20.0891","0.9515"
"","47.6800","20.1574","0.9507"
"","47.8400","20.2241","0.9492"
"","48.0000","20.2925","0.9482"
"","48.1600","20.3606","0.9474"
"","48.3200","20.4277","0.9459"
"","48.4800","20.4956","0.9449"
"","48.6400","20.5634","0.9438"
"","48.8000","20.6314","0.9430"
"","48.9600","20.6983","0.9415"
"","49.1200","20.7667","0.9407"
"","49.2800","20.8346","0.9396"
"","49.4400","20.9015","0.9384"
"","49.6000","20.9699","0.9372"
"","49.7600","21.0379","0.9365"
"","49.9200","21.1049","0.9349"
"","50.0800","21.1728","0.9334"
"","50.2400","21.2407","0.9324"
"","50.4000","21.3085","0.9314"
"","50.5600","21.3759","0.9299"
"","50.7200","21.4438","0.9287"
"","50.8800","21.5122","0.9279"
"","51.0400","21.5789","0.9263"
"","51.2000","21.6472","0.9253"
"","51.3600","21.7152","0.9242"
"","51.5200","21.7823","0.9227"
"","51.6800","21.8501","0.9216"
"","51.8400","21.9181","0.9204"
"","52.0000","21.9862","0.9195"
"","52.1600","22.0528","0.9178"
"","52.3200","22.1213","0.9170"
"","52.4800","22.1895","0.9159"
"","52.6400","22.2563","0.9140"
"","52.8000","22.3245","0.9130"
"","52.9600","22.3924","0.9120"
"","53.1200","22.4594","0.9106"
"","53.2800","22.5275","0.9089"
"","53.4400","22.5954","0.9080"
"","53.6000","22.6631","0.9064"
"","53.7600","22.7306","0.9051"
"","53.9200","22.7986","0.9042"
"","54.0800","22.8669","0.9031"
"","54.2400","22.9335","0.9012"
"","54.4000","23.0016","0.9001"
"","54.5600","23.0699","0.8989"
"","54.7200","23.1370","0.8973"
"","54.8800","23.2047","0.8960"
"","55.0400","23.2728","0.8950"
"","55.2000","23.3407","0.8934"
"","55.3600","23.4076","0.8919"
"","55.5200","23.4759","0.8908"
"","55.6800","23.5440","0.8895"
"","55.8400","23.6109","0.8880"
"","56.0000","23.6792","0.8869"
"","56.1600","23.7472","0.8854"
"","56.3200","23.8141","0.8839"
"","56.4800","23.8823","0.8829"
"","56.6400","23.9503","0.8817"
"","56.8000","24.0180","0.8805"
"","56.9600","24.0852","0.8787"
"","57.1200","24.1530","0.8773"
"","57.2800","24.2214","0.8764"
"","57.4400","24.2884","0.8745"
"","57.6000","24.3564","0.8730"
"","57.7600","24.4244","0.8720"
"","57.9200","24.4916","0.8702"
"","58.0800","24.5596","0.8685"
"","58.2400","24.6275","0.8673"
"","58.4000","24.6950","0.8661"
"","58.5600","24.7624","0.8645"
"","58.7200","24.8307","0.8632"
"","58.8800","24.8988","0.8616"
"","59.0400","24.9655","0.8600"
"","59.2000","25.0337","0.8585"
"","59.3600","25.1021","0.8575"
"","59.5200","25.1690","0.8559"
"","59.6800","25.2369","0.8546"
"","59.8400","25.3047","0.8532"
"","60.0000","25.3726","0.8517"
"","60.1600","25.4399","0.8504"
"","60.3200","25.5077","0.8490"
"","60.4800","25.5759","0.8481"
"","60.6400","25.6429","0.8459"
"","60.8000","25.7112","0.8447"
"","60.9600","25.7793","0.8435"
"","61.1200","25.8462","0.8417"
"","61.2800","25.9141","0.8404"
"","61.4400","25.9822","0.8388"
"","61.6000","26.0499","0.8377"
"","61.7600","26.1171","0.8360"
"","61.9200","26.1851","0.8348"
"","62.0800","26.2535","0.8332"
"","62.2400","26.3205","0.8315"
"","62.4000","26.3884","0.8300"
"","62.5600","26.4565","0.8289"
"","62.7200","26.5235","0.8268"
"","62.8800","26.5917","0.8256"
"","63.0400","26.6595","0.8240"
"","63.2000","26.7271","0.8225"
"","63.3600","26.7945","0.8208"
"","63.5200","26.8627","0.8192"
"","63.6800","26.9308","0.8176"
"","63.8400","26.9975","0.8158"
"","64.0000","27.0657","0.8143"
"","64.1600","27.1339","0.8130"
"","64.3200","27.2011","0.8111"
"","64.4800","27.2688","0.8096"
"","64.6400","27.3368","0.8080"
"","64.8000","27.4046","0.8063"
"","64.9600","27.4721","0.8045"
"","65.1200","27.5398","0.8031"
"","65.2800","27.6081","0.8015"
"","65.4400","27.6748","0.7995"
"","65.6000","27.7432","0.7980"
"","65.7600","27.8112","0.7965"
"","65.9200","27.8781","0.7945"
"","66.0800","27.9463","0.7932"
"","66.2400","28.0142","0.7915"
"","66.4000","28.0818","0.7897"
"","66.5600","28.1492","0.7876"
"","66.7200","28.2173","0.7862"
"","66.8800","28.2853","0.7845"
"","67.0400","28.3523","0.7825"
"","67.2000","28.4204","0.7811"
"","67.3600","28.4885","0.7797"
"","67.5200","28.5556","0.7774"
"","67.6800","28.6236","0.7759"
"","67.8400","28.6916","0.7741"
"","68.0000","28.7592","0.7722"
"","68.1600","28.8267","0.7705"
"","68.3200","28.8943","0.7688"
"","68.4800","28.9628","0.7674"
"","68.6400","29.0293","0.7651"
"","68.8000","29.0977","0.7634"
"","68.9600","29.1660","0.7620"
"","69.1200","29.2329","0.7599"
"","69.2800","29.3009","0.7583"
"","69.4400","29.3689","0.7566"
"","69.6000","29.4365","0.7546"
"","69.7600","29.5039","0.7529"
"","69.9200","29.5718","0.7511"
"","70.0800","29.6399","0.7494"
"","70.2400","29.7068","0.7473"
"","70.4000","29.7752","0.7457"
"","70.5600","29.8432","0.7441"
"","70.7200","29.9103","0.7419"
"","70.8800","29.9783","0.7402"
"","71.0400","30.0462","0.7383"
"","71.2000","30.1139","0.7364"
"","71.3600","30.1812","0.7346"
"","71.5200","30.2489","0.7327"
"","71.6800","30.3173","0.7312"
"","71.8400","30.3842","0.7289"
"","72.0000","30.4525","0.7271"
"","72.1600","30.5207","0.7255"
"","72.3200","30.5875","0.7232"
"","72.4800","30.6556","0.7212"
"","72.6400","30.7236","0.7195"
"","72.8000","30.7911","0.7175"
"","72.9600","30.8585","0.7156"
"","73.1200","30.9265","0.7138"
"","73.2800","30.9948","0.7119"
"","73.4400","31.0616","0.7099"
"","73.6000","31.1298","0.7079"
"","73.7600","31.1979","0.7060"
"","73.9200","31.2649","0.7041"
"","74.0800","31.3329","0.7020"
"","74.2400","31.4006","0.7000"
"","74.4000","31.4684","0.6982"
"","74.5600","31.5362","0.6959"
"","74.7200","31.6036","0.6937"
"","74.8800","31.6720","0.6922"
"","75.0400","31.7390","0.6899"
"","75.2000","31.8073","0.6880"
"","75.3600","31.8752","0.6863"
"","75.5200","31.9421","0.6838"
"","75.6800","32.0101","0.6818"
"","75.8400","32.0783","0.6797"
"","76.0000","32.1460","0.6779"
"","76.1600","32.2132","0.6754"
"","76.3200","32.2812","0.6735"
"","76.4800","32.3494","0.6716"
"","76.6400","32.4164","0.6694"
"","76.8000","32.4844","0.6670"
"","76.9600","32.5524","0.6652"
"","77.1200","32.6193","0.6632"
"","77.2800","32.6877","0.6610"
"","77.4400","32.7554","0.6589"
"","77.6000","32.8229","0.6569"
"","77.7600","32.8907","0.6547"
"","77.9200","32.9588","0.6526"
"","78.0800","33.0269","0.6509"
"","78.2400","33.0936","0.6484"
"","78.4000","33.1615","0.6466"
"","78.5600","33.2299","0.6445"
"","78.7200","33.2969","0.6426"
"","78.8800","33.3648","0.6402"
"","79.0400","33.4328","0.6381"
"","79.2000","33.5006","0.6363"
"","79.3600","33.5681","0.6341"
"","79.5200","33.6359","0.6319"
"","79.6800","33.7039","0.6302"
"","79.8400","33.7708","0.6278"
"","80.0000","33.8393","0.6261"
"","80.1600","33.9072","0.6240"
"","80.3200","33.9740","0.6217"
"","80.4800","34.0424","0.6201"
"","80.6400","34.1104","0.6181"
"","80.8000","34.1778","0.6164"
"","80.9600","34.2453","0.6140"
"","81.1200","34.3132","0.6124"
"","81.2800","34.3813","0.6107"
"","81.4400","34.4485","0.6088"
"","81.6000","34.5163","0.6070"
"","81.7600","34.5845","0.6053"
"","81.9200","34.6516","0.6035"
"","82.0800","34.7198","0.6015"
"","82.2400","34.7877","0.6001"
"","82.4000","34.8548","0.5983"
"","82.5600","34.9226","0.5968"
"","82.7200","34.9907","0.5950"
"","82.8800","35.0587","0.5938"
"","83.0400","35.1255","0.5919"
"","83.2000","35.1936","0.5905"
"","83.3600","35.2621","0.5892"
"","83.5200","35.3290","0.5877"
"","83.6800","35.3970","0.5862"
"","83.8400","35.4647","0.5848"
"","84.0000","35.5324","0.5836"
"","84.1600","35.6002","0.5821"
"","84.3200","35.6678","0.5810"
"","84.4800","35.7357","0.5799"
"","84.6400","35.8031","0.5786"
"","84.8000","35.8712","0.5776"
"","84.9600","35.9394","0.5766"
"","85.1200","36.0061","0.5754"
"","85.2800","36.0742","0.5742"
"","85.4400","36.1424","0.5733"
"","85.6000","36.2096","0.5723"
"","85.7600","36.2771","0.5711"
"","85.9200","36.3451","0.5706"
"","86.0800","36.4134","0.5698"
"","86.2400","36.4804","0.5689"
"","86.4000","36.5484","0.5681"
"","86.5600","36.6166","0.5676"
"","86.7200","36.6836","0.5666"
"","86.8800","36.7517","0.5660"
"","87.0400","36.8195","0.5652"
"","87.2000","36.8868","0.5647"
"","87.3600","36.9547","0.5640"
"","87.5200","37.0228","0.5635"
"","87.6800","37.0904","0.5631"
"","87.8400","37.1576","0.5622"
"","88.0000","37.2256","0.5618"
"","88.1600","37.2941","0.5615"
"","88.3200","37.3607","0.5607"
"","88.4800","37.4290","0.5605"
"","88.6400","37.4968","0.5604"
"","88.8000","37.5644","0.5598"
"","88.9600","37.6320","0.5594"
"","89.1200","37.6999","0.5590"
"","89.2800","37.7679","0.5589"
"","89.4400","37.8350","0.5582"
"","89.6000","37.9031","0.5582"
"","89.7600","37.9713","0.5579"
"","89.9200","38.0382","0.5575"
"","90.0800","38.1062","0.5574"
"","90.2400","38.1743","0.5574"
"","90.4000","38.2417","0.5569"
"","90.5600","38.3095","0.5569"
"","90.7200","38.3774","0.5566"
"","90.8800","38.4449","0.5562"
"","91.0400","38.5123","0.5561"
"","91.2000","38.5803","0.5559"
"","91.3600","38.6486","0.5559"
"","91.5200","38.7154","0.5558"
"","91.6800","38.7837","0.5555"
"","91.8400","38.8517","0.5552"
"","92.0000","38.9190","0.5550"
"","92.1600","38.9867","0.5550"
"","92.3200","39.0545","0.5547"
"","92.4800","39.1226","0.5548"
"","92.6400","39.1895","0.5545"
"","92.8000","39.2576","0.5545"
"","92.9600","39.3260","0.5548"
"","93.1200","39.3929","0.5543"
"","93.2800","39.4610","0.5542"
"","93.4400","39.5290","0.5543"
"","93.6000","39.5961","0.5544"
"","93.7600","39.6641","0.5542"
"","93.9200","39.7320","0.5542"
"","94.0800","39.7997","0.5542"
"","94.2400","39.8668","0.5542"
"","94.4000","39.9352","0.5543"
"","94.5600","40.0034","0.5547"
"","94.7200","40.0702","0.5542"
"","94.8800","40.1383","0.5542"
"","95.0400","40.2064","0.5543"
"","95.2000","40.2738","0.5546"
"","95.3600","40.3413","0.5546"
"","95.5200","40.4091","0.5546"
"","95.6800","40.4772","0.5549"
"","95.8400","40.5444","0.5546"
"","96.0000","40.6124","0.5547"
"","96.1600","40.6807","0.5552"
"","96.3200","40.7474","0.5548"
"","96.4800","40.8158","0.5550"
"","96.6400","40.8837","0.5551"
"","96.8000","40.9507","0.5552"
"","96.9600","41.0186","0.5554"
"","97.1200","41.0867","0.5555"
"","97.2800","41.1548","0.5558"
"","97.4400","41.2217","0.5557"
"","97.6000","41.2898","0.5561"
"","97.7600","41.3580","0.5565"
"","97.9200","41.4249","0.5561"
"","98.0800","41.4929","0.5563"
"","98.2400","41.5607","0.5565"
"","98.4000","41.6284","0.5566"
"","98.5600","41.6961","0.5568"
"","98.7200","41.7639","0.5568"
"","98.8800","41.8318","0.5572"
"","99.0400","41.8991","0.5572"
"","99.2000","41.9672","0.5573"
"","99.3600","42.0354","0.5574"
"","99.5200","42.1019","0.5572"
"","99.6800","42.1701","0.5573"
"","99.8400","42.2385","0.5578"
"","100.0000","42.3057","0.5576"
"","100.1600","42.3733","0.5578"
"","100.3200","42.4413","0.5581"
"","100.4800","42.5095","0.5582"
"","100.6400","42.5764","0.5583"
"","100.8000","42.6444","0.5583"
"","100.9600","42.7124","0.5585"
"","101.1200","42.7795","0.5584"
"","101.2800","42.8477","0.5589"
"","101.4400","42.9156","0.5588"
"","101.6000","42.9828","0.5591"
"","101.7600","43.0507","0.5593"
"","101.9200","43.1188","0.5595"
"","102.0800","43.1866","0.5597"
"","102.2400","43.2536","0.5594"
"","102.4000","43.3216","0.5600"
"","102.5600","43.3900","0.5603"
"","102.7200","43.4568","0.5601"
"","102.8800","43.5248","0.5603"
"","103.0400","43.5930","0.5608"
"","103.2000","43.6603","0.5607"
"","103.3600","43.7283","0.5609"
"","103.5200","43.7960","0.5611"
"","103.6800","43.8639","0.5612"
"","103.8400","43.9308","0.5615"
"","104.0000","43.9992","0.5618"
"","104.1600","44.0670","0.5617"
"","104.3200","44.1340","0.5620"
"","104.4800","44.2024","0.5624"
"","104.6400","44.2706","0.5625"
"","104.8000","44.3376","0.5624"
"","104.9600","44.4053","0.5626"
"","105.1200","44.4732","0.5626"
"","105.2800","44.5411","0.5632"
"","105.4400","44.6085","0.5632"
"","105.6000","44.6762","0.5631"
"","105.7600","44.7446","0.5636"
"","105.9200","44.8115","0.5634"
"","106.0800","44.8799","0.5636"
"","106.2400","44.9477","0.5637"
"","106.4000","45.0148","0.5638"
"","106.5600","45.0827","0.5639"
"","106.7200","45.1508","0.5641"
"","106.8800","45.2187","0.5646"
"","107.0400","45.2852","0.5643"
"","107.2000","45.3538","0.5646"
"","107.3600","45.4221","0.5650"
"","107.5200","45.4889","0.5650"
"","107.6800","45.5570","0.5652"
"","107.8400","45.6249","0.5655"
"","108.0000","45.6922","0.5656"
"","108.1600","45.7601","0.5656"
"","108.3200","45.8279","0.5661"
"","108.4800","45.8957","0.5663"
"","108.6400","45.9630","0.5661"
"","108.8000","46.0311","0.5665"
"","108.9600","46.0994","0.5667"
"","109.1200","46.1661","0.5664"
"","109.2800","46.2342","0.5670"
"","109.4400","46.3024","0.5673"
"","109.6000","46.3695","0.5672"
"","109.7600","46.4372","0.5672"
"","109.9200","46.5054","0.5677"
"","110.0800","46.5732","0.5678"
"","110.2400","46.6402","0.5674"
"","110.4000","46.7085","0.5679"
"","110.5600","46.7766","0.5682"
"","110.7200","46.8435","0.5678"
"","110.8800","46.9117","0.5683"
"","111.0400","46.9797","0.5687"
"","111.2000","47.0466","0.5686"
"","111.3600","47.1148","0.5687"
"","111.5200","47.1828","0.5687"
"","111.6800","47.2506","0.5691"
"","111.8400","47.3177","0.5691"
"","112.0000","47.3856","0.5693"
"","112.1600","47.4540","0.5695"
"","112.3200","47.5208","0.5696"
"","112.4800","47.5889","0.5700"
"","112.6400","47.6569","0.5702"
"","112.8000","47.7240","0.5702"
"","112.9600","47.7920","0.5702"
"","113.1200","47.8601","0.5705"
"","113.2800","47.9277","0.5710"
"","113.4400","47.9950","0.5708"
"","113.6000","48.0632","0.5713"
"","113.7600","48.1314","0.5716"
"","113.9200","48.1981","0.5713"
"","114.0800","48.2661","0.5716"
"","114.2400","48.3346","0.5720"
"","114.4000","48.4016","0.5718"
"","114.5600","48.4696","0.5720"
"","114.7200","48.5373","0.5719"
"","114.8800","48.6050","0.5722"
"","115.0400","48.6725","0.5723"
"","115.2000","48.7403","0.5724"
"","115.3600","48.8085","0.5725"
"","115.5200","48.8753","0.5726"
"","115.6800","48.9437","0.5730"
"","115.8400","49.0119","0.5730"
"","116.0000","49.0788","0.5728"
"","116.1600","49.1467","0.5732"
"","116.3200","49.2147","0.5734"
"","116.4800","49.2826","0.5735"
"","116.6400","49.3497","0.5737"
"","116.8000","49.4175","0.5740"
"","116.9600","49.4861","0.5743"
"","117.1200","49.5529","0.5741"
"","117.2800","49.6209","0.5744"
"","117.4400","49.6891","0.5747"
"","117.6000","49.7561","0.5747"
"","117.7600","49.8243","0.5748"
"","117.9200","49.8919","0.5748"
"","118.0800","49.9595","0.5752"
"","118.2400","50.0270","0.5753"
"","118.4000","50.0953","0.5757"
"","118.5600","50.1633","0.5758"
"","118.7200","50.2301","0.5757"
"","118.8800","50.2982","0.5761"
"","119.0400","50.3665","0.5763"
"","119.2000","50.4336","0.5761"
"","119.3600","50.5013","0.5763"
"","119.5200","50.5692","0.5767"
"","119.6800","50.6371","0.5768"
"","119.8400","50.7046","0.5767"
"","120.0000","50.7722","0.5769"
"","120.1600","50.8406","0.5773"
"","120.3200","50.9075","0.5770"
"","120.4800","50.9758","0.5774"
"","120.6400","51.0439","0.5777"
"","120.8000","51.1105","0.5774"
"","120.9600","51.1787","0.5777"
"","121.1200","51.2467","0.5777"
"","121.2800","51.3144","0.5778"
"","121.4400","51.3817","0.5778"
"","121.6000","51.4498","0.5782"
"","121.7600","51.5180","0.5783"
"","121.9200","51.5849","0.5782"
"","122.0800","51.6528","0.5779"
"","122.2400","51.7209","0.5783"
"","122.4000","51.7883","0.5784"
"","122.5600","51.8562","0.5783"
"","122.7200","51.9241","0.5784"
"","122.8800","51.9916","0.5784"
"","123.0400","52.0594","0.5784"
"","123.2000","52.1270","0.5785"
"","123.3600","52.1953","0.5788"
"","123.5200","52.2619","0.5786"
"","123.6800","52.3302","0.5787"
"","123.8400","52.3987","0.5790"
"","124.0000","52.4654","0.5789"
"","124.1600","52.5333","0.5790"
"","124.3200","52.6015","0.5790"
"","124.4800","52.6691","0.5790"
"","124.6400","52.7366","0.5786"
"","124.8000","52.8042","0.5791"
"","124.9600","52.8725","0.5793"
"","125.1200","52.9394","0.5788"
"","125.2800","53.0077","0.5791"
"","125.4400","53.0757","0.5790"
"","125.6000","53.1427","0.5789"
"","125.7600","53.2108","0.5790"
"","125.9200","53.2789","0.5794"
"","126.0800","53.3464","0.5793"
"","126.2400","53.4137","0.5790"
"","126.4000","53.4813","0.5790"
"","126.5600","53.5500","0.5792"
"","126.7200","53.6167","0.5792"
"","126.8800","53.6849","0.5790"
"","127.0400","53.7530","0.5794"
"","127.2000","53.8202","0.5792"
"","127.3600","53.8882","0.5794"
"","127.5200","53.9560","0.5795"
"","127.6800","54.0236","0.5794"
"","127.8400","54.0911","0.5794"
"","128.0000","54.1591","0.5793"
"","128.1600","54.2271","0.5795"
"","128.3200","54.2940","0.5798"
"","128.4800","54.3623","0.5796"
"","128.6400","54.4306","0.5798"
"","128.8000","54.4974","0.5795"
"","128.9600","54.5653","0.5799"
"","129.1200","54.6333","0.5797"
"","129.2800","54.7010","0.5797"
"","129.4400","54.7686","0.5797"
"","129.6000","54.8362","0.5797"
"","129.7600","54.9045","0.5801"
"","129.9200","54.9716","0.5800"
"","130.0800","55.0398","0.5800"
"","130.2400","55.1078","0.5801"
"","130.4000","55.1747","0.5798"
"","130.5600","55.2427","0.5798"
"","130.7200","55.3107","0.5804"
"","130.8800","55.3785","0.5806"
"","131.0400","55.4456","0.5802"
"","131.2000","55.5139","0.5805"
"","131.3600","55.5818","0.5805"
"","131.5200","55.6490","0.5803"
"","131.6800","55.7170","0.5805"
"","131.8400","55.7851","0.5808"
"","132.0000","55.8520","0.5807"
"","132.1600","55.9202","0.5804"
"","132.3200","55.9879","0.5807"
"","132.4800","56.0554","0.5809"
"","132.6400","56.1231","0.5808"
"","132.8000","56.1912","0.5811"
"","132.9600","56.2595","0.5813"
"","133.1200","56.3262","0.5811"
"","133.2800","56.3942","0.5813"
"","133.4400","56.4625","0.5815"
"","133.6000","56.5293","0.5814"
"","133.7600","56.5974","0.5817"
"","133.9200","56.6653","0.5817"
"","134.0800","56.7330","0.5819"
"","134.2400","56.8006","0.5822"
"","134.4000","56.8685","0.5822"
"","134.5600","56.9365","0.5824"
"","134.7200","57.0034","0.5826"
"","134.8800","57.0717","0.5826"
"","135.0400","57.1398","0.5829"
"","135.2000","57.2065","0.5828"
"","135.3600","57.2748","0.5831"
"","135.5200","57.3427","0.5830"
"","135.6800","57.4104","0.5836"
"","135.8400","57.4779","0.5836"
"","136.0000","57.5458","0.5837"
"","136.1600","57.6139","0.5843"
"","136.3200","57.6809","0.5841"
"","136.4800","57.7489","0.5844"
"","136.6400","57.8170","0.5847"
"","136.8000","57.8840","0.5849"
"","136.9600","57.9522","0.5851"
"","137.1200","58.0202","0.5854"
"","137.2800","58.0875","0.5853"
"","137.4400","58.1550","0.5852"
"","137.6000","58.2232","0.5857"
"","137.7600","58.2913","0.5858"
"","137.9200","58.3580","0.5856"
"","138.0800","58.4261","0.5860"
"","138.2400","58.4945","0.5865"
"","138.4000","58.5615","0.5862"
"","138.5600","58.6296","0.5866"
"","138.7200","58.6972","0.5864"
"","138.8800","58.7650","0.5866"
"","139.0400","58.8326","0.5869"
"","139.2000","58.9005","0.5869"
"","139.3600","58.9683","0.5870"
"","139.5200","59.0354","0.5869"
"","139.6800","59.1038","0.5872"
"","139.8400","59.1719","0.5874"
"","140.0000","59.2388","0.5876"
"","140.1600","59.3068","0.5875"
"","140.3200","59.3749","0.5875"
"","140.4800","59.4423","0.5875"
"","140.6400","59.5096","0.5876"
"","140.8000","59.5776","0.5879"
"","140.9600","59.6458","0.5883"
"","141.1200","59.7130","0.5883"
"","141.2800","59.7809","0.5885"
"","141.4400","59.8491","0.5888"
"","141.6000","59.9161","0.5885"
"","141.7600","59.9843","0.5889"
"","141.9200","60.0521","0.5891"
"","142.0800","60.1193","0.5892"
"","142.2400","60.1872","0.5894"
"","142.4000","60.2553","0.5896"
"","142.5600","60.3228","0.5898"
"","142.7200","60.3901","0.5897"
"","142.8800","60.4583","0.5900"
"","143.0400","60.5267","0.5902"
"","143.2000","60.5934","0.5899"
"","143.3600","60.6613","0.5900"
"","143.5200","60.7294","0.5901"
"","143.6800","60.7969","0.5903"
"","143.8400","60.8646","0.5903"
"","144.0000","60.9322","0.5904"
"","144.1600","61.0005","0.5908"
"","144.3200","61.0676","0.5904"
"","144.4800","61.1357","0.5906"
"","144.6400","61.2038","0.5907"
"","144.8000","61.2705","0.5904"
"","144.9600","61.3388","0.5907"
"","145.1200","61.4070","0.5907"
"","145.2800","61.4739","0.5909"
"","145.4400","61.5419","0.5908"
"","145.6000","61.6099","0.5910"
"","145.7600","61.6776","0.5909"
"","145.9200","61.7448","0.5911"
"","146.0800","61.8129","0.5907"
"","146.2400","61.8812","0.5912"
"","146.4000","61.9481","0.5909"
"","146.5600","62.0162","0.5909"
"","146.7200","62.0840","0.5907"
"","146.8800","62.1515","0.5909"
"","147.0400","62.2194","0.5908"
"","147.2000","62.2871","0.5907"
"","147.3600","62.3552","0.5910"
"","147.5200","62.4220","0.5907"
"","147.6800","62.4902","0.5908"
"","147.8400","62.5585","0.5913"
"","148.0000","62.6252","0.5905"
"","148.1600","62.6935","0.5908"
"","148.3200","62.7615","0.5911"
"","148.4800","62.8288","0.5909"
"","148.6400","62.8967","0.5909"
"","148.8000","62.9645","0.5912"
"","148.9600","63.0323","0.5911"
"","149.1200","63.0995","0.5910"
"","149.2800","63.1678","0.5915"
"","149.4400","63.2358","0.5913"
"","149.6000","63.3027","0.5912"
"","149.7600","63.3709","0.5914"
"","149.9200","63.4389","0.5913"
"","150.0800","63.5063","0.5914"
"","150.2400","63.5739","0.5915"
"","150.4000","63.6418","0.5913"
"","150.5600","63.7096","0.5917"
"","150.7200","63.7768","0.5916"
"","150.8800","63.8448","0.5915"
"","151.0400","63.9132","0.5920"
"","151.2000","63.9799","0.5920"
"","151.3600","64.0483","0.5918"
"","151.5200","64.1163","0.5924"
"","151.6800","64.1833","0.5919"
"","151.8400","64.2511","0.5921"
"","152.0000","64.3192","0.5922"
"","152.1600","64.3871","0.5924"
"","152.3200","64.4542","0.5923"
"","152.4800","64.5223","0.5927"
"","152.6400","64.5906","0.5924"
"","152.8000","64.6574","0.5924"
"","152.9600","64.7255","0.5922"
"","153.1200","64.7934","0.5923"
"","153.2800","64.8608","0.5926"
"","153.4400","64.9287","0.5925"
"","153.6000","64.9965","0.5926"
"","153.7600","65.0642","0.5927"
"","153.9200","65.1315","0.5924"
"","154.0800","65.1997","0.5927"
"","154.2400","65.2679","0.5931"
"","154.4000","65.3345","0.5925"
"","154.5600","65.4028","0.5928"
"","154.7200","65.4710","0.5931"
"","154.8800","65.5382","0.5929"
"","155.0400","65.6059","0.5930"
"","155.2000","65.6737","0.5930"
"","155.3600","65.7419","0.5929"
"","155.5200","65.8090","0.5928"
"","155.6800","65.8770","0.5929"
"","155.8400","65.9450","0.5932"
"","156.0000","66.0119","0.5928"
"","156.1600","66.0803","0.5931"
"","156.3200","66.1482","0.5932"
"","156.4800","66.2152","0.5929"
"","156.6400","66.2832","0.5928"
"","156.8000","66.3513","0.5930"
"","156.9600","66.4193","0.5930"
"","157.1200","66.4862","0.5927"
"","157.2800","66.5540","0.5930"
"","157.4400","66.6226","0.5932"
"","157.6000","66.6893","0.5927"
"","157.7600","66.7575","0.5929"
"","157.9200","66.8254","0.5929"
"","158.0800","66.8928","0.5931"
"","158.2400","66.9608","0.5931"
"","158.4000","67.0287","0.5925"
"","158.5600","67.0965","0.5929"
"","158.7200","67.1632","0.5927"
"","158.8800","67.2318","0.5924"
"","159.0400","67.2997","0.5928"
"","159.2000","67.3664","0.5926"
"","159.3600","67.4347","0.5927"
"","159.5200","67.5030","0.5931"
"","159.6800","67.5702","0.5928"
"","159.8400","67.6379","0.5929"
"","160.0000","67.7057","0.5929"
"","160.1600","67.7737","0.5927"
"","160.3200","67.8410","0.5926"
"","160.4800","67.9088","0.5926"
"","160.6400","67.9770","0.5929"
"","160.8000","68.0440","0.5925"
"","160.9600","68.1123","0.5928"
"","161.1200","68.1803","0.5930"
"","161.2800","68.2473","0.5931"
"","161.4400","68.3152","0.5932"
"","161.6000","68.3834","0.5931"
"","161.7600","68.4510","0.5933"
"","161.9200","68.5178","0.5931"
"","162.0800","68.5862","0.5932"
"","162.2400","68.6545","0.5937"
"","162.4000","68.7215","0.5935"
"","162.5600","68.7894","0.5934"
"","162.7200","68.8576","0.5937"
"","162.8800","68.9247","0.5936"
"","163.0400","68.9928","0.5935"
"","163.2000","69.0604","0.5935"
"","163.3600","69.1283","0.5937"
"","163.5200","69.1956","0.5936"
"","163.6800","69.2637","0.5937"
"","163.8400","69.3319","0.5938"
"","164.0000","69.3987","0.5935"
"","164.1600","69.4667","0.5939"
"","164.3200","69.5350","0.5939"
"","164.4800","69.6020","0.5937"
"","164.6400","69.6697","0.5935"
"","164.8000","69.7379","0.5938"
"","164.9600","69.8057","0.5939"
"","165.1200","69.8727","0.5937"
"","165.2800","69.9409","0.5939"
"","165.4400","70.0093","0.5939"
"","165.6000","70.0762","0.5936"
"","165.7600","70.1442","0.5938"
"","165.9200","70.2123","0.5940"
"","166.0800","70.2792","0.5939"
"","166.2400","70.3473","0.5939"
"","166.4000","70.4152","0.5938"
"","166.5600","70.4830","0.5940"
"","166.7200","70.5502","0.5937"
"","166.8800","70.6183","0.5940"
"","167.0400","70.6866","0.5941"
"","167.2000","70.7532","0.5936"
"","167.3600","70.8214","0.5938"
"","167.5200","70.8894","0.5941"
"","167.6800","70.9567","0.5940"
"","167.8400","71.0244","0.5937"
"","168.0000","71.0926","0.5940"
"","168.1600","71.1603","0.5941"
"","168.3200","71.2276","0.5940"
"","168.4800","71.2958","0.5944"
"","168.6400","71.3639","0.5945"
"","168.8000","71.4305","0.5943"
"","168.9600","71.4988","0.5943"
"","169.1200","71.5670","0.5946"
"","169.2800","71.6340","0.5947"
"","169.4400","71.7020","0.5948"
"","169.6000","71.7699","0.5947"
"","169.7600","71.8377","0.5950"
"","169.9200","71.9049","0.5948"
"","170.0800","71.9729","0.5948"
"","170.2400","72.0410","0.5953"
"","170.4000","72.1079","0.5950"
"","170.5600","72.1761","0.5949"
"","170.7200","72.2443","0.5956"
"","170.8800","72.3114","0.5951"
"","171.0400","72.3792","0.5954"
"","171.2000","72.4473","0.5954"
"","171.3600","72.5151","0.5954"
"","171.5200","72.5823","0.5957"
"","171.6800","72.6502","0.5958"
"","171.8400","72.7186","0.5958"
"","172.0000","72.7853","0.5954"
"","172.1600","72.8535","0.5956"
"","172.3200","72.9216","0.5957"
"","172.4800","72.9887","0.5955"
"","172.6400","73.0568","0.5959"
"","172.8000","73.1246","0.5957"
"","172.9600","73.1921","0.5955"
"","173.1200","73.2595","0.5954"
"","173.2800","73.3276","0.5958"
"","173.4400","73.3957","0.5956"
"","173.6000","73.4626","0.5955"
"","173.7600","73.5307","0.5954"
"","173.9200","73.5992","0.5961"
"","174.0800","73.6663","0.5955"
"","174.2400","73.7339","0.5955"
"","174.4000","73.8018","0.5957"
"","174.5600","73.8695","0.5956"
"","174.7200","73.9371","0.5956"
"","174.8800","74.0047","0.5955"
"","175.0400","74.0731","0.5957"
"","175.2000","74.1398","0.5954"
"","175.3600","74.2084","0.5956"
"","175.5200","74.2765","0.5955"
"","175.6800","74.3432","0.5957"
"","175.8400","74.4112","0.5954"
"","176.0000","74.4791","0.5957"
"","176.1600","74.5469","0.5955"
"","176.3200","74.6142","0.5952"
"","176.4800","74.6821","0.5957"
"","176.6400","74.7505","0.5955"
"","176.8000","74.8176","0.5955"
"","176.9600","74.8855","0.5954"
"","177.1200","74.9536","0.5957"
"","177.2800","75.0206","0.5955"
"","177.4400","75.0888","0.5954"
"","177.6000","75.1566","0.5955"
"","177.7600","75.2241","0.5955"
"","177.9200","75.2917","0.5958"
"","178.0800","75.3595","0.5955"
"","178.2400","75.4280","0.5959"
"","178.4000","75.4944","0.5957"
"","178.5600","75.5628","0.5960"
"","178.7200","75.6311","0.5962"
"","178.8800","75.6980","0.5960"
"","179.0400","75.7659","0.5957"
"","179.2000","75.8338","0.5961"
"","179.3600","75.9016","0.5963"
"","179.5200","75.9691","0.5959"
"","179.6800","76.0369","0.5964"
"","179.8400","76.1049","0.5963"
"","180.0000","76.1721","0.5963"
"","180.1600","76.2402","0.5968"
"","180.3200","76.3084","0.5967"
"","180.4800","76.3751","0.5967"
"","180.6400","76.4432","0.5969"
"","180.8000","76.5113","0.5968"
"","180.9600","76.5792","0.5968"
"","181.1200","76.6463","0.5968"
"","181.2800","76.7139","0.5969"
"","181.4400","76.7824","0.5973"
"","181.6000","76.8494","0.5971"
"","181.7600","76.9174","0.5972"
"","181.9200","76.9855","0.5975"
"","182.0800","77.0526","0.5974"
"","182.2400","77.1208","0.5974"
"","182.4000","77.1888","0.5977"
"","182.5600","77.2562","0.5976"
"","182.7200","77.3235","0.5976"
"","182.8800","77.3917","0.5980"
"","183.0400","77.4596","0.5978"
"","183.2000","77.5265","0.5976"
"","183.3600","77.5947","0.5979"
"","183.5200","77.6631","0.5982"
"","183.6800","77.7299","0.5978"
"","183.8400","77.7979","0.5979"
"","184.0000","77.8658","0.5978"
"","184.1600","77.9336","0.5982"
"","184.3200","78.0011","0.5983"
"","184.4800","78.0686","0.5980"
"","184.6400","78.1369","0.5985"
"","184.8000","78.2040","0.5983"
"","184.9600","78.2723","0.5984"
"","185.1200","78.3404","0.5984"
"","185.2800","78.4073","0.5984"
"","185.4400","78.4753","0.5984"
"","185.6000","78.5434","0.5986"
"","185.7600","78.6108","0.5985"
"","185.9200","78.6783","0.5983"
"","186.0800","78.7462","0.5983"
"","186.2400","78.8144","0.5985"
"","186.4000","78.8813","0.5983"
"","186.5600","78.9495","0.5985"
"","186.7200","79.0176","0.5987"
"","186.8800","79.0846","0.5984"
"","187.0400","79.1528","0.5984"
"","187.2000","79.2204","0.5985"
"","187.3600","79.2880","0.5985"
"","187.5200","79.3557","0.5985"
"","187.6800","79.4236","0.5986"
"","187.8400","79.4919","0.5987"
"","188.0000","79.5587","0.5985"
"","188.1600","79.6268","0.5986"
"","188.3200","79.6950","0.5989"
"","188.4800","79.7620","0.5985"
"","188.6400","79.8299","0.5985"
"","188.8000","79.8981","0.5988"
"","188.9600","79.9654","0.5986"
"","189.1200","80.0331","0.5987"
"","189.2800","80.1010","0.5987"
"","189.4400","80.1692","0.5988"
"","189.6000","80.2359","0.5988"
"","189.7600","80.3042","0.5990"
"","189.9200","80.3722","0.5989"
"","190.0800","80.4392","0.5990"
"","190.2400","80.5073","0.5989"
"","190.4000","80.5751","0.5990"
"","190.5600","80.6428","0.5992"
"","190.7200","80.7104","0.5992"
"","190.8800","80.7785","0.5991"
"","191.0400","80.8465","0.5998"
"","191.2000","80.9135","0.5993"
"","191.3600","80.9815","0.5995"
"","191.5200","81.0495","0.5999"
"","191.6800","81.1164","0.5997"
"","191.8400","81.1846","0.6000"
"","192.0000","81.2527","0.6003"
"","192.1600","81.3201","0.6004"
"","192.3200","81.3876","0.6005"
"","192.4800","81.4558","0.6008"
"","192.6400","81.5238","0.6007"
"","192.8000","81.5905","0.6007"
"","192.9600","81.6585","0.6011"
"","193.1200","81.7269","0.6013"
"","193.2800","81.7940","0.6014"
"","193.4400","81.8621","0.6016"
"","193.6000","81.9299","0.6016"
"","193.7600","81.9975","0.6019"
"","193.9200","82.0653","0.6017"
"","194.0800","82.1331","0.6018"
"","194.2400","82.2007","0.6022"
"","194.4000","82.2679","0.6020"
"","194.5600","82.3362","0.6022"
"","194.7200","82.4044","0.6025"
"","194.8800","82.4712","0.6024"
"","195.0400","82.5392","0.6026"
"","195.2000","82.6074","0.6027"
"","195.3600","82.6748","0.6027"
"","195.5200","82.7422","0.6026"
"","195.6800","82.8101","0.6028"
"","195.8400","82.8784","0.6026"
"","196.0000","82.9455","0.6027"
"","196.1600","83.0135","0.6027"
"","196.3200","83.0815","0.6033"
"","196.4800","83.1486","0.6030"
[...]
"","28.2400","59.6613","0.5909"
"","28.2800","59.7457","0.5907"
"","28.3200","59.8301","0.5906"
"","28.3600","59.9150","0.5905"
"","28.4000","59.9997","0.5906"
"","28.4400","60.0845","0.5908"
"","28.4800","60.1694","0.5904"
"","28.5200","60.2540","0.5904"
"","28.5600","60.3382","0.5902"
"","28.6000","60.4226","0.5901"
"","28.6400","60.5076","0.5901"
"","28.6800","60.5924","0.5903"
"","28.7200","60.6770","0.5900"
"","28.7600","60.7621","0.5898"
"","28.8000","60.8470","0.5898"
"","28.8400","60.9310","0.5895"
"","28.8800","61.0153","0.5895"
"","28.9200","61.1004","0.5895"
"","28.9600","61.1852","0.5891"
"","29.0000","61.2698","0.5890"
"","29.0400","61.3547","0.5892"
"","29.0800","61.4395","0.5890"
"","29.1200","61.5236","0.5886"
"","29.1600","61.6080","0.5885"
"","29.2000","61.6929","0.5885"
"","29.2400","61.7776","0.5883"
"","29.2800","61.8623","0.5881"
"","29.3200","61.9474","0.5880"
"","29.3600","62.0323","0.5879"
"","29.4000","62.1163","0.5876"
"","29.4400","62.2009","0.5876"
"","29.4800","62.2858","0.5875"
"","29.5200","62.3699","0.5870"
"","29.5600","62.4548","0.5872"
"","29.6000","62.5403","0.5872"
"","29.6400","62.6249","0.5872"
"","29.6800","62.7088","0.5868"
"","29.7200","62.7935","0.5868"
"","29.7600","62.8785","0.5870"
"","29.8000","62.9628","0.5868"
"","29.8400","63.0474","0.5866"
"","29.8800","63.1327","0.5865"
"","29.9200","63.2175","0.5865"
"","29.9600","63.3016","0.5860"
"","30.0000","63.3864","0.5863"
"","30.0400","63.4711","0.5862"
"","30.0800","63.5554","0.5859"
"","30.1200","63.6403","0.5858"
"","30.1600","63.7252","0.5861"
"","30.2000","63.8099","0.5860"
"","30.2400","63.8944","0.5859"
"","30.2800","63.9792","0.5859"
"","30.3200","64.0637","0.5856"
"","30.3600","64.1481","0.5855"
"","30.4000","64.2331","0.5854"
"","30.4400","64.3182","0.5854"
"","30.4800","64.4025","0.5854"
"","30.5200","64.4869","0.5852"
"","30.5600","64.5717","0.5851"
"","30.6000","64.6562","0.5849"
"","30.6400","64.7409","0.5849"
"","30.6800","64.8260","0.5851"
"","30.7200","64.9109","0.5849"
"","30.7600","64.9953","0.5848"
"","30.8000","65.0794","0.5844"
"","30.8400","65.1641","0.5844"
"","30.8800","65.2489","0.5847"
"","30.9200","65.3336","0.5847"
"","30.9600","65.4186","0.5846"
"","31.0000","65.5035","0.5846"
"","31.0400","65.5881","0.5845"
"","31.0800","65.6724","0.5842"
"","31.1200","65.7570","0.5840"
"","31.1600","65.8415","0.5838"
"","31.2000","65.9260","0.5835"
"","31.2400","66.0111","0.5835"
"","31.2800","66.0961","0.5838"
"","31.3200","66.1806","0.5836"
"","31.3600","66.2651","0.5831"
"","31.4000","66.3499","0.5833"
"","31.4400","66.4341","0.5830"
"","31.4800","66.5186","0.5826"
"","31.5200","66.6038","0.5831"
"","31.5600","66.6887","0.5831"
"","31.6000","66.7734","0.5829"
"","31.6400","66.8580","0.5827"
"","31.6800","66.9426","0.5826"
"","31.7200","67.0268","0.5824"
"","31.7600","67.1112","0.5824"
"","31.8000","67.1964","0.5822"
"","31.8400","67.2813","0.5823"
"","31.8800","67.3658","0.5822"
"","31.9200","67.4506","0.5821"
"","31.9600","67.5353","0.5822"
"","32.0000","67.6194","0.5819"
"","32.0400","67.7042","0.5816"
"","32.0800","67.7890","0.5816"
"","32.1200","67.8737","0.5813"
"","32.1600","67.9585","0.5814"
"","32.2000","68.0434","0.5811"
"","32.2400","68.1278","0.5809"
"","32.2800","68.2119","0.5802"
"","32.3200","68.2969","0.5805"
"","32.3600","68.3822","0.5806"
"","32.4000","68.4666","0.5804"
"","32.4400","68.5510","0.5803"
"","32.4800","68.6359","0.5805"
"","32.5200","68.7204","0.5804"
"","32.5600","68.8047","0.5804"
"","32.6000","68.8897","0.5807"
"","32.6400","68.9745","0.5808"
"","32.6800","69.0592","0.5808"
"","32.7200","69.1439","0.5807"
"","32.7600","69.2287","0.5810"
"","32.8000","69.3132","0.5809"
"","32.8400","69.3976","0.5809"
"","32.8800","69.4824","0.5810"
"","32.9200","69.5671","0.5810"
"","32.9600","69.6518","0.5810"
"","33.0000","69.7367","0.5811"
"","33.0400","69.8214","0.5809"
"","33.0800","69.9055","0.5809"
"","33.1200","69.9899","0.5809"
"","33.1600","70.0749","0.5810"
"","33.2000","70.1598","0.5811"
"","33.2400","70.2443","0.5810"
"","33.2800","70.3293","0.5813"
"","33.3200","70.4144","0.5814"
"","33.3600","70.4983","0.5812"
"","33.4000","70.5824","0.5811"
"","33.4400","70.6676","0.5814"
"","33.4800","70.7524","0.5817"
"","33.5200","70.8371","0.5814"
"","33.5600","70.9220","0.5816"
"","33.6000","71.0069","0.5818"
"","33.6400","71.0910","0.5816"
"","33.6800","71.1753","0.5817"
"","33.7200","71.2602","0.5819"
"","33.7600","71.3449","0.5820"
"","33.8000","71.4295","0.5821"
"","33.8400","71.5148","0.5823"
"","33.8800","71.5997","0.5821"
"","33.9200","71.6837","0.5819"
"","33.9600","71.7682","0.5822"
"","34.0000","71.8532","0.5823"
"","34.0400","71.9375","0.5822"
"","34.0800","72.0222","0.5821"
"","34.1200","72.1075","0.5823"
"","34.1600","72.1922","0.5823"
"","34.2000","72.2762","0.5819"
"","34.2400","72.3609","0.5819"
"","34.2800","72.4458","0.5819"
"","34.3200","72.5302","0.5817"
"","34.3600","72.6149","0.5815"
"","34.4000","72.7001","0.5816"
"","34.4400","72.7848","0.5813"
"","34.4800","72.8690","0.5813"
"","34.5200","72.9537","0.5809"
"","34.5600","73.0384","0.5810"
"","34.6000","73.1229","0.5807"
"","34.6400","73.2077","0.5808"
"","34.6800","73.2926","0.5805"
"","34.7200","73.3773","0.5801"
"","34.7600","73.4616","0.5802"
"","34.8000","73.5463","0.5803"
"","34.8400","73.6311","0.5801"
"","34.8800","73.7155","0.5795"
"","34.9200","73.8003","0.5794"
"","34.9600","73.8855","0.5795"
"","35.0000","73.9701","0.5794"
"","35.0400","74.0542","0.5790"
"","35.0800","74.1390","0.5788"
"","35.1200","74.2238","0.5786"
"","35.1600","74.3082","0.5785"
"","35.2000","74.3929","0.5787"
"","35.2400","74.4782","0.5786"
"","35.2800","74.5628","0.5785"
"","35.3200","74.6468","0.5781"
"","35.3600","74.7316","0.5783"
"","35.4000","74.8163","0.5782"
"","35.4400","74.9008","0.5780"
"","35.4800","74.9857","0.5780"
"","35.5200","75.0709","0.5779"
"","35.5600","75.1554","0.5777"
"","35.6000","75.2396","0.5778"
"","35.6400","75.3243","0.5776"
"","35.6800","75.4088","0.5773"
"","35.7200","75.4933","0.5772"
"","35.7600","75.5786","0.5772"
"","35.8000","75.6636","0.5770"
"","35.8400","75.7480","0.5770"
"","35.8800","75.8323","0.5769"
"","35.9200","75.9172","0.5767"
"","35.9600","76.0014","0.5765"
"","36.0000","76.0859","0.5767"
"","36.0400","76.1711","0.5764"
"","36.0800","76.2562","0.5763"
"","36.1200","76.3407","0.5757"
"","36.1600","76.4253","0.5757"
"","36.2000","76.5100","0.5754"
"","36.2400","76.5942","0.5751"
"","36.2800","76.6786","0.5751"
"","36.3200","76.7637","0.5749"
"","36.3600","76.8487","0.5749"
"","36.4000","76.9332","0.5746"
"","36.4400","77.0179","0.5743"
"","36.4800","77.1025","0.5742"
"","36.5200","77.1869","0.5737"
"","36.5600","77.2716","0.5740"
"","36.6000","77.3563","0.5737"
"","36.6400","77.4410","0.5739"
"","36.6800","77.5259","0.5739"
"","36.7200","77.6108","0.5739"
"","36.7600","77.6953","0.5740"
"","36.8000","77.7795","0.5737"
"","36.8400","77.8642","0.5737"
"","36.8800","77.9491","0.5738"
"","36.9200","78.0338","0.5739"
"","36.9600","78.1184","0.5737"
"","37.0000","78.2032","0.5738"
"","37.0400","78.2878","0.5738"
"","37.0800","78.3721","0.5738"
"","37.1200","78.4568","0.5739"
"","37.1600","78.5418","0.5738"
"","37.2000","78.6266","0.5737"
"","37.2400","78.7112","0.5739"
"","37.2800","78.7957","0.5738"
"","37.3200","78.8803","0.5735"
"","37.3600","78.9647","0.5735"
"","37.4000","79.0496","0.5734"
"","37.4400","79.1348","0.5734"
"","37.4800","79.2194","0.5734"
"","37.5200","79.3039","0.5737"
"","37.5600","79.3887","0.5736"
"","37.6000","79.4729","0.5734"
"","37.6400","79.5573","0.5733"
"","37.6800","79.6421","0.5735"
"","37.7200","79.7272","0.5737"
"","37.7600","79.8119","0.5734"
"","37.8000","79.8965","0.5734"
"","37.8400","79.9816","0.5735"
"","37.8800","80.0659","0.5735"
"","37.9200","80.1499","0.5733"
"","37.9600","80.2349","0.5736"
"","38.0000","80.3199","0.5735"
"","38.0400","80.4044","0.5735"
"","38.0800","80.4893","0.5736"
"","38.1200","80.5743","0.5734"
"","38.1600","80.6584","0.5733"
"","38.2000","80.7425","0.5729"
"","38.2400","80.8276","0.5734"
"","38.2800","80.9123","0.5734"
"","38.3200","80.9968","0.5734"
"","38.3600","81.0820","0.5734"
"","38.4000","81.1671","0.5734"
"","38.4400","81.2510","0.5731"
"","38.4800","81.3354","0.5730"
"","38.5200","81.4203","0.5731"
"","38.5600","81.5046","0.5728"
"","38.6000","81.5894","0.5727"
"","38.6400","81.6748","0.5728"
"","38.6800","81.7596","0.5725"
"","38.7200","81.8436","0.5726"
"","38.7600","81.9282","0.5723"
"","38.8000","82.0131","0.5723"
"","38.8400","82.0975","0.5720"
"","38.8800","82.1821","0.5719"
"","38.9200","82.2673","0.5720"
"","38.9600","82.3522","0.5715"
"","39.0000","82.4363","0.5713"
"","39.0400","82.5209","0.5712"
"","39.0800","82.6057","0.5707"
"","39.1200","82.6904","0.5707"
"","39.1600","82.7751","0.5708"
"","39.2000","82.8599","0.5700"
"","39.2400","82.9446","0.5697"
"","39.2800","83.0289","0.5694"
"","39.3200","83.1137","0.5690"
"","39.3600","83.1985","0.5690"
"","39.4000","83.2830","0.5684"
"","39.4400","83.3677","0.5682"
"","39.4800","83.4527","0.5677"
"","39.5200","83.5373","0.5673"
"","39.5600","83.6217","0.5669"
"","39.6000","83.7063","0.5664"
"","39.6400","83.7910","0.5658"
"","39.6800","83.8756","0.5652"
"","39.7200","83.9602","0.5652"
"","39.7600","84.0455","0.5648"
"","39.8000","84.1302","0.5645"
"","39.8400","84.2141","0.5638"
"","39.8800","84.2987","0.5633"
"","39.9200","84.3838","0.5629"
"","39.9600","84.4682","0.5623"
"","40.0000","84.5529","0.5619"
"","40.0400","84.6383","0.5616"
"","40.0800","84.7230","0.5608"
"","40.1200","84.8070","0.5599"
"","40.1600","84.8915","0.5589"
"","40.2000","84.9763","0.5581"
"","40.2400","85.0606","0.5571"
"","40.2800","85.1456","0.5561"
"","40.3200","85.2309","0.5551"
"","40.3600","85.3154","0.5536"
"","40.4000","85.3997","0.5522"
"","40.4400","85.4846","0.5511"
"","40.4800","85.5687","0.5492"
"","40.5200","85.6531","0.5472"
"","40.5600","85.7384","0.5456"
"","40.6000","85.8236","0.5433"
"","40.6400","85.9080","0.5409"
"","40.6800","85.9924","0.5375"
"","40.7200","86.0772","0.5339"
"","40.7600","86.1615","0.5298"
"","40.8000","86.2460","0.5252"
"","40.8400","86.3312","0.5196"
"","40.8800","86.4161","0.5123"
"","40.9190","86.4984","0.1268"
"","40.9590","86.5832","-0.0222"
"","40.9990","86.6679","-0.0026"
"","41.0390","86.7521","0.0004"
"","41.0790","86.8366","-0.0003"
"","41.1190","86.9215","-0.0006"
"","41.1590","87.0064","-0.0005"
"","41.1990","87.0911","-0.0004"
"","41.2390","87.1758","-0.0003"
"","41.2790","87.2606","-0.0004"
"","41.3190","87.3448","-0.0004"
"","41.3590","87.4295","-0.0004"
"","41.3990","87.5144","-0.0004"
"","41.4390","87.5991","-0.0005"
"","41.4790","87.6837","-0.0003"
"","41.5190","87.7684","-0.0002"
"","41.5590","87.8530","-0.0004"
"","41.5990","87.9375","-0.0005"
"","41.6390","88.0222","-0.0003"
"","41.6790","88.1070","-0.0003"
"","41.7190","88.1918","-0.0004"
"","41.7590","88.2764","-0.0006"
"","41.7990","88.3610","-0.0004"
"","41.8390","88.4458","-0.0004"
"","41.8790","88.5301","-0.0004"
"","41.9190","88.6147","-0.0004"
"","41.9590","88.6997","-0.0004"
"","41.9990","88.7845","-0.0003"
"","42.0390","88.8691","-0.0003"
"","42.0790","88.9538","-0.0003"
"","42.1190","89.0383","-0.0004"
"","42.1590","89.1225","-0.0004"
"","42.1990","89.2072","-0.0001"
"","42.2390","89.2924","-0.0004"
"","42.2790","89.3770","-0.0008"
"","42.3190","89.4617","-0.0005"
"","42.3590","89.5467","-0.0004"
"","42.3990","89.6310","-0.0004"
"","42.4390","89.7150","-0.0004"
"","42.4790","89.7999","-0.0002"
"","42.5190","89.8852","-0.0004"
"","42.5590","89.9700","-0.0003"
"","42.5990","90.0546","-0.0002"
"","42.6390","90.1394","-0.0004"
"","42.6790","90.2237","-0.0002"
"","42.7190","90.3078","-0.0003"
"","42.7590","90.3927","-0.0002"
"","42.7990","90.4776","-0.0002"
"","42.8390","90.5622","-0.0005"
"","42.8790","90.6471","-0.0005"
"","42.9190","90.7322","-0.0003"
"","42.9590","90.8165","-0.0004"
"","42.9990","90.9007","-0.0004"
"","43.0390","90.9855","-0.0004"
"","43.0790","91.0700","-0.0003"
"","43.1190","91.1547","-0.0002"
"","43.1590","91.2399","-0.0003"
"","43.1990","91.3249","-0.0002"
"","43.2390","91.4090","-0.0003"
"","43.2790","91.4933","-0.0004"
"","43.3190","91.5784","-0.0003"
"","43.3590","91.6628","-0.0003"
"","43.3990","91.7473","-0.0005"
"","43.4390","91.8325","-0.0003"
"","43.4790","91.9175","-0.0004"
"","43.5190","92.0016","-0.0001"
"","43.5590","92.0861","-0.0002"
"","43.5990","92.1709","-0.0003"
"","43.6390","92.2555","-0.0004"
"","43.6790","92.3401","-0.0005"
"","43.7190","92.4250","-0.0003"
"","43.7590","92.5099","-0.0004"
"","43.7990","92.5943","-0.0004"
"","43.8390","92.6788","-0.0004"
"","43.8790","92.7636","-0.0006"
"","43.9190","92.8483","-0.0002"
"","43.9590","92.9329","-0.0002"
"","43.9990","93.0179","-0.0001"
"","44.0060","93.0328","-0.0001"
3,Time,Displacement,Force
,(s),(mm),(kN)
"","0.0000","0.0000","0.0035"
"","0.0200","0.0005","0.0040"
"","0.0400","0.0174","0.0195"
"","0.0600","0.0973","0.0893"
"","0.0800","0.2476","0.2086"
"","0.1000","0.4149","0.3276"
"","0.1200","0.5748","0.4282"
"","0.1400","0.7339","0.5171"
"","0.1600","0.9018","0.6012"
"","0.1800","1.0788","0.6791"
"","0.2000","1.2588","0.7483"
"","0.2200","1.4361","0.8075"
"","0.2400","1.6084","0.8578"
"","0.2600","1.7769","0.9016"
"","0.2800","1.9441","0.9407"
"","0.3000","2.1118","0.9767"
"","0.3200","2.2807","1.0097"
"","0.3400","2.4505","1.0402"
"","0.3600","2.6207","1.0680"
"","0.3800","2.7906","1.0933"
"","0.4000","2.9601","1.1163"
"","0.4200","3.1293","1.1371"
"","0.4400","3.2984","1.1564"
"","0.4600","3.4676","1.1739"
"","0.4800","3.6370","1.1898"
"","0.5000","3.8062","1.2042"
"","0.5200","3.9755","1.2172"
"","0.5400","4.1450","1.2290"
"","0.5600","4.3146","1.2394"
"","0.5800","4.4840","1.2488"
"","0.6000","4.6533","1.2573"
"","0.6200","4.8227","1.2648"
"","0.6400","4.9920","1.2715"
"","0.6600","5.1611","1.2773"
"","0.6800","5.3304","1.2823"
"","0.7000","5.4998","1.2867"
"","0.7200","5.6692","1.2905"
"","0.7400","5.8383","1.2933"
"","0.7600","6.0076","1.2958"
"","0.7800","6.1769","1.2976"
"","0.8000","6.3463","1.2989"
"","0.8200","6.5156","1.3000"
"","0.8400","6.6850","1.3004"
"","0.8600","6.8545","1.3003"
"","0.8800","7.0238","1.2997"
"","0.9000","7.1931","1.2987"
"","0.9200","7.3624","1.2973"
"","0.9400","7.5316","1.2955"
"","0.9600","7.7009","1.2931"
"","0.9800","7.8704","1.2899"
"","1.0000","8.0399","1.2862"
"","1.0200","8.2093","1.2817"
"","1.0400","8.3786","1.2760"
"","1.0600","8.5478","1.2693"
"","1.0800","8.7171","1.2612"
"","1.1000","8.8864","1.2510"
"","1.1200","9.0558","1.2387"
"","1.1400","9.2252","1.2232"
"","1.1600","9.3946","1.2040"
"","1.1800","9.5640","1.1818"
"","1.2000","9.7334","1.1574"
"","1.2200","9.9026","1.1315"
"","1.2400","10.0717","1.1061"
"","1.2600","10.2410","1.0817"
"","1.2800","10.4105","1.0588"
"","1.3000","10.5798","1.0373"
"","1.3200","10.7492","1.0174"
"","1.3400","10.9185","0.9983"
"","1.3600","11.0878","0.9800"
"","1.3800","11.2569","0.9618"
"","1.4000","11.4263","0.9430"
"","1.4200","11.5958","0.9230"
"","1.4400","11.7652","0.9015"
"","1.4600","11.9346","0.8786"
"","1.4800","12.1041","0.8554"
"","1.5000","12.2735","0.8327"
"","1.5200","12.4427","0.8115"
"","1.5400","12.6119","0.7921"
"","1.5600","12.7811","0.7744"
"","1.5800","12.9504","0.7585"
"","1.6000","13.1198","0.7448"
"","1.6200","13.2892","0.7329"
"","1.6400","13.4586","0.7226"
"","1.6600","13.6279","0.7132"
"","1.6800","13.7971","0.7043"
"","1.7000","13.9663","0.6953"
"","1.7200","14.1355","0.6471"
"","1.7350","14.2625","0.3909"
"","1.7510","14.3982","0.1320"
"","1.7710","14.5678","-0.0112"
"","1.7910","14.7372","-0.0286"
"","1.8110","14.9066","-0.0133"
"","1.8310","15.0759","-0.0025"
"","1.8510","15.2451","0.0005"
"","1.8710","15.4142","0.0003"
"","1.8910","15.5835","-0.0005"
"","1.9110","15.7530","-0.0009"
"","1.9310","15.9225","-0.0008"
"","1.9510","16.0918","-0.0007"
"","1.9710","16.2610","-0.0008"
"","1.9910","16.4303","-0.0007"
"","2.0110","16.5994","-0.0007"
"","2.0310","16.7687","-0.0008"
"","2.0510","16.9381","-0.0009"
"","2.0710","17.1076","-0.0009"
"","2.0910","17.2770","-0.0007"
"","2.1110","17.4463","-0.0009"
"","2.1310","17.6156","-0.0011"
"","2.1510","17.7849","-0.0009"
"","2.1710","17.9542","-0.0007"
"","2.1910","18.1235","-0.0007"
"","2.2110","18.2928","-0.0007"
"","2.2310","18.4622","-0.0006"
"","2.2510","18.6317","-0.0007"
"","2.2710","18.8011","-0.0007"
"","2.2910","18.9702","-0.0007"
"","2.3110","19.1395","-0.0006"
"","2.3310","19.3088","-0.0006"
"","2.3510","19.4781","-0.0005"
"","2.3710","19.6475","-0.0005"
"","2.3910","19.8170","-0.0007"
"","2.4110","19.9864","-0.0006"
"","2.4310","20.1557","-0.0005"
"","2.4510","20.3250","-0.0006"
"","2.4710","20.4944","-0.0007"
"","2.4910","20.6637","-0.0008"
"","2.5110","20.8330","-0.0008"
"","2.5310","21.0023","-0.0007"
"","2.5510","21.1716","-0.0006"
"","2.5710","21.3409","-0.0007"
"","2.5910","21.5102","-0.0006"
"","2.6110","21.6795","-0.0007"
"","2.6310","21.8488","-0.0005"
"","2.6510","22.0182","-0.0005"
"","2.6710","22.1875","-0.0005"
"","2.6910","22.3569","-0.0004"
"","2.7110","22.5262","-0.0003"
"","2.7310","22.6956","-0.0006"
"","2.7510","22.8651","-0.0007"
"","2.7710","23.0345","-0.0006"
"","2.7910","23.2038","-0.0008"
"","2.8110","23.3731","-0.0006"
"","2.8310","23.5423","-0.0006"
"","2.8510","23.7115","-0.0008"
"","2.8710","23.8808","-0.0008"
"","2.8910","24.0502","-0.0006"
"","2.9110","24.2197","-0.0007"
"","2.9310","24.3890","-0.0008"
"","2.9510","24.5583","-0.0007"
"","2.9710","24.7276","-0.0007"
"","2.9910","24.8968","-0.0005"
"","3.0110","25.0660","-0.0006"
"","3.0310","25.2355","-0.0005"
"","3.0510","25.4049","-0.0004"
"","3.0710","25.5743","-0.0005"
"","3.0910","25.7437","-0.0007"
"","3.1110","25.9131","-0.0006"
"","3.1310","26.0824","-0.0006"
"","3.1510","26.2515","-0.0006"
"","3.1710","26.4208","-0.0006"
"","3.1910","26.5902","-0.0007"
"","3.2110","26.7596","-0.0007"
"","3.2310","26.9290","-0.0007"
"","3.2510","27.0983","-0.0006"
"","3.2710","27.2676","-0.0006"
"","3.2910","27.4369","-0.0005"
"","3.3110","27.6061","-0.0005"
"","3.3310","27.7755","-0.0007"
"","3.3510","27.9448","-0.0006"
"","3.3710","28.1143","-0.0005"
"","3.3910","28.2838","-0.0006"
"","3.4110","28.4531","-0.0007"
"","3.4310","28.6223","-0.0006"
"","3.4510","28.7916","-0.0006"
"","3.4710","28.9608","-0.0005"
"","3.4910","29.1300","-0.0007"
"","3.5110","29.2994","-0.0007"
"","3.5310","29.4690","-0.0005"
"","3.5510","29.6384","-0.0004"
"","3.5710","29.8077","-0.0006"
"","3.5910","29.9770","-0.0005"
"","3.6110","30.1463","-0.0004"
"","3.6310","30.3155","-0.0004"
"","3.6510","30.4848","-0.0005"
"","3.6710","30.6542","-0.0006"
"","3.6910","30.8236","-0.0007"
"","3.7110","30.9930","-0.0007"
"","3.7310","31.1624","-0.0007"
"","3.7510","31.3318","-0.0005"
"","3.7710","31.5011","-0.0002"
"","3.7910","31.6703","-0.0003"
"","3.8110","31.8396","-0.0006"
"","3.8310","32.0089","-0.0007"
"","3.8510","32.1783","-0.0006"
"","3.8710","32.3476","-0.0006"
"","3.8910","32.5169","-0.0004"
"","3.9110","32.6861","-0.0005"
"","3.9310","32.8555","-0.0007"
"","3.9510","33.0249","-0.0006"
"","3.9710","33.1941","-0.0005"
"","3.9910","33.3635","-0.0005"
"","4.0110","33.5330","-0.0003"
"","4.0310","33.7025","-0.0002"
"","4.0510","33.8718","-0.0004"
"","4.0710","34.0410","-0.0004"
"","4.0910","34.2103","-0.0006"
"","4.1110","34.3795","-0.0006"
"","4.1310","34.5487","-0.0006"
"","4.1510","34.7180","-0.0007"
"","4.1710","34.8876","-0.0006"
"","4.1910","35.0570","-0.0005"
"","4.2110","35.2263","-0.0005"
"","4.2310","35.3956","-0.0005"
"","4.2510","35.5649","-0.0007"
"","4.2710","35.7341","-0.0008"
"","4.2910","35.9034","-0.0006"
"","4.3110","36.0728","-0.0005"
"","4.3310","36.2422","-0.0005"
"","4.3510","36.4116","-0.0006"
"","4.3710","36.5811","-0.0006"
"","4.3910","36.7504","-0.0007"
"","4.4110","36.9197","-0.0007"
"","4.4310","37.0890","-0.0006"
"","4.4510","37.2583","-0.0006"
"","4.4710","37.4276","-0.0005"
"","4.4910","37.5969","-0.0004"
"","4.5110","37.7663","-0.0005"
"","4.5310","37.9356","-0.0005"
"","4.5510","38.1048","-0.0004"
"","4.5710","38.2741","-0.0005"