File: Lab10/LDPE_S6_1.csv
Results Table 1
,Specimen label,Thickness,Width,Length,Rate 1
,,(mm),(mm),(mm),(mm/min)
"1","LDPE 1IN/MIN","3.33","13.26","95.25","25.40"
"2","LDPE 5IN/MIN","3.30","13.00","87.12","127.00"
"3","LDPE 20IN/MIN","3.30","13.00","90.42","508.00"

Results Table 2


1,Time,Displacement,Force
,(s),(mm),(kN)
"","0.0000","0.0000","-0.0020"
"","0.2400","0.0763","0.0172"
"","0.4800","0.1768","0.0381"
"","0.7200","0.2783","0.0565"
"","0.9600","0.3799","0.0728"
"","1.2000","0.4816","0.0877"
"","1.4400","0.5831","0.1019"
"","1.6800","0.6852","0.1154"
"","1.9200","0.7869","0.1282"
"","2.1600","0.8887","0.1404"
"","2.4000","0.9904","0.1523"
"","2.6400","1.0919","0.1632"
"","2.8800","1.1933","0.1743"
"","3.1200","1.2949","0.1844"
"","3.3600","1.3961","0.1942"
"","3.6000","1.4979","0.2038"
"","3.8400","1.5996","0.2135"
"","4.0800","1.7011","0.2222"
"","4.3200","1.8027","0.2311"
"","4.5600","1.9044","0.2392"
"","4.8000","2.0055","0.2475"
"","5.0400","2.1071","0.2553"
"","5.2800","2.2088","0.2629"
"","5.5200","2.3103","0.2704"
"","5.7600","2.4119","0.2775"
"","6.0000","2.5136","0.2844"
"","6.2400","2.6152","0.2912"
"","6.4800","2.7168","0.2978"
"","6.7200","2.8189","0.3041"
"","6.9600","2.9202","0.3103"
"","7.2000","3.0226","0.3164"
"","7.4400","3.1241","0.3219"
"","7.6800","3.2255","0.3274"
"","7.9200","3.3269","0.3330"
"","8.1600","3.4283","0.3383"
"","8.4000","3.5297","0.3431"
"","8.6400","3.6316","0.3480"
"","8.8800","3.7331","0.3528"
"","9.1200","3.8346","0.3575"
"","9.3600","3.9364","0.3621"
"","9.6000","4.0378","0.3663"
"","9.8400","4.1392","0.3707"
"","10.0800","4.2410","0.3746"
"","10.3200","4.3422","0.3787"
"","10.5600","4.4436","0.3823"
"","10.8000","4.5457","0.3862"
"","11.0400","4.6471","0.3896"
"","11.2800","4.7492","0.3936"
"","11.5200","4.8509","0.3967"
"","11.7600","4.9525","0.4001"
"","12.0000","5.0542","0.4029"
"","12.2400","5.1561","0.4061"
"","12.4800","5.2575","0.4092"
"","12.7200","5.3590","0.4117"
"","12.9600","5.4604","0.4145"
"","13.2000","5.5618","0.4171"
"","13.4400","5.6633","0.4197"
"","13.6800","5.7651","0.4221"
"","13.9200","5.8666","0.4247"
"","14.1600","5.9685","0.4270"
"","14.4000","6.0697","0.4293"
"","14.6400","6.1713","0.4314"
"","14.8800","6.2728","0.4334"
"","15.1200","6.3740","0.4354"
"","15.3600","6.4757","0.4372"
"","15.6000","6.5775","0.4391"
"","15.8400","6.6792","0.4413"
"","16.0800","6.7810","0.4427"
"","16.3200","6.8829","0.4442"
"","16.5600","6.9846","0.4459"
"","16.8000","7.0864","0.4477"
"","17.0400","7.1880","0.4490"
"","17.2800","7.2895","0.4504"
"","17.5200","7.3910","0.4520"
"","17.7600","7.4924","0.4536"
"","18.0000","7.5938","0.4547"
"","18.2400","7.6956","0.4559"
"","18.4800","7.7969","0.4569"
"","18.7200","7.8986","0.4581"
"","18.9600","8.0004","0.4591"
"","19.2000","8.1017","0.4601"
"","19.4400","8.2033","0.4612"
"","19.6800","8.3049","0.4623"
"","19.9200","8.4062","0.4631"
"","20.1600","8.5078","0.4638"
"","20.4000","8.6094","0.4648"
"","20.6400","8.7110","0.4656"
"","20.8800","8.8128","0.4664"
"","21.1200","8.9147","0.4671"
"","21.3600","9.0167","0.4678"
"","21.6000","9.1185","0.4683"
"","21.8400","9.2200","0.4691"
"","22.0800","9.3212","0.4697"
"","22.3200","9.4230","0.4704"
"","22.5600","9.5242","0.4709"
"","22.8000","9.6261","0.4715"
"","23.0400","9.7276","0.4721"
"","23.2800","9.8290","0.4723"
"","23.5200","9.9305","0.4728"
"","23.7600","10.0323","0.4735"
"","24.0000","10.1337","0.4736"
"","24.2400","10.2354","0.4740"
"","24.4800","10.3368","0.4745"
"","24.7200","10.4382","0.4748"
"","24.9600","10.5397","0.4747"
"","25.2000","10.6416","0.4753"
"","25.4400","10.7431","0.4756"
"","25.6800","10.8449","0.4759"
"","25.9200","10.9466","0.4758"
"","26.1600","11.0485","0.4760"
"","26.4000","11.1503","0.4764"
"","26.6400","11.2519","0.4768"
"","26.8800","11.3535","0.4768"
"","27.1200","11.4552","0.4768"
"","27.3600","11.5564","0.4768"
"","27.6000","11.6578","0.4772"
"","27.8400","11.7595","0.4771"
"","28.0800","11.8611","0.4770"
"","28.3200","11.9627","0.4774"
"","28.5600","12.0644","0.4774"
"","28.8000","12.1658","0.4774"
"","29.0400","12.2671","0.4775"
"","29.2800","12.3689","0.4774"
"","29.5200","12.4702","0.4772"
"","29.7600","12.5720","0.4774"
"","30.0000","12.6737","0.4775"
"","30.2400","12.7749","0.4775"
"","30.4800","12.8768","0.4772"
"","30.7200","12.9786","0.4771"
"","30.9600","13.0803","0.4770"
"","31.2000","13.1824","0.4769"
"","31.4400","13.2840","0.4768"
"","31.6800","13.3855","0.4766"
"","31.9200","13.4869","0.4764"
"","32.1600","13.5885","0.4760"
"","32.4000","13.6899","0.4762"
"","32.6400","13.7917","0.4761"
"","32.8800","13.8931","0.4760"
"","33.1200","13.9945","0.4756"
"","33.3600","14.0965","0.4755"
"","33.6000","14.1979","0.4754"
"","33.8400","14.2995","0.4752"
"","34.0800","14.4009","0.4749"
"","34.3200","14.5022","0.4746"
"","34.5600","14.6037","0.4745"
"","34.8000","14.7056","0.4744"
"","35.0400","14.8071","0.4742"
"","35.2800","14.9090","0.4741"
"","35.5200","15.0107","0.4740"
"","35.7600","15.1124","0.4740"
"","36.0000","15.2138","0.4735"
"","36.2400","15.3161","0.4736"
"","36.4800","15.4175","0.4732"
"","36.7200","15.5192","0.4730"
"","36.9600","15.6206","0.4729"
"","37.2000","15.7219","0.4726"
"","37.4400","15.8234","0.4723"
"","37.6800","15.9250","0.4721"
"","37.9200","16.0266","0.4721"
"","38.1600","16.1283","0.4715"
"","38.4000","16.2298","0.4714"
"","38.6400","16.3314","0.4712"
"","38.8800","16.4330","0.4709"
"","39.1200","16.5343","0.4708"
"","39.3600","16.6358","0.4705"
"","39.6000","16.7374","0.4705"
"","39.8400","16.8390","0.4702"
"","40.0800","16.9407","0.4701"
"","40.3200","17.0428","0.4697"
"","40.5600","17.1443","0.4697"
"","40.8000","17.2463","0.4694"
"","41.0400","17.3480","0.4691"
"","41.2800","17.4495","0.4691"
"","41.5200","17.5511","0.4688"
"","41.7600","17.6525","0.4683"
"","42.0000","17.7539","0.4679"
"","42.2400","17.8557","0.4680"
"","42.4800","17.9568","0.4676"
"","42.7200","18.0587","0.4673"
"","42.9600","18.1604","0.4671"
"","43.2000","18.2617","0.4670"
"","43.4400","18.3634","0.4666"
"","43.6800","18.4651","0.4664"
"","43.9200","18.5664","0.4661"
"","44.1600","18.6680","0.4661"
"","44.4000","18.7695","0.4655"
"","44.6400","18.8707","0.4653"
"","44.8800","18.9727","0.4652"
"","45.1200","19.0745","0.4650"
"","45.3600","19.1765","0.4648"
"","45.6000","19.2784","0.4647"
"","45.8400","19.3800","0.4644"
"","46.0800","19.4814","0.4640"
"","46.3200","19.5830","0.4640"
"","46.5600","19.6844","0.4634"
"","46.8000","19.7861","0.4633"
"","47.0400","19.8876","0.4632"
"","47.2800","19.9891","0.4629"
"","47.5200","20.0906","0.4627"
"","47.7600","20.1923","0.4626"
"","48.0000","20.2939","0.4625"
"","48.2400","20.3954","0.4619"
"","48.4800","20.4971","0.4616"
"","48.7200","20.5985","0.4616"
"","48.9600","20.6997","0.4610"
"","49.2000","20.8016","0.4612"
"","49.4400","20.9030","0.4608"
"","49.6800","21.0048","0.4606"
"","49.9200","21.1064","0.4603"
"","50.1600","21.2082","0.4603"
"","50.4000","21.3100","0.4601"
"","50.6400","21.4120","0.4598"
"","50.8800","21.5136","0.4596"
"","51.1200","21.6152","0.4595"
"","51.3600","21.7166","0.4593"
"","51.6000","21.8177","0.4589"
"","51.8400","21.9195","0.4587"
"","52.0800","22.0211","0.4585"
"","52.3200","22.1227","0.4583"
"","52.5600","22.2245","0.4579"
"","52.8000","22.3260","0.4582"
"","53.0400","22.4273","0.4578"
"","53.2800","22.5289","0.4576"
"","53.5200","22.6303","0.4571"
"","53.7600","22.7320","0.4570"
"","54.0000","22.8335","0.4569"
"","54.2400","22.9349","0.4567"
"","54.4800","23.0367","0.4567"
"","54.7200","23.1385","0.4564"
"","54.9600","23.2401","0.4563"
"","55.2000","23.3422","0.4565"
"","55.4400","23.4439","0.4560"
"","55.6800","23.5454","0.4559"
"","55.9200","23.6471","0.4557"
"","56.1600","23.7486","0.4554"
"","56.4000","23.8501","0.4554"
"","56.6400","23.9518","0.4552"
"","56.8800","24.0530","0.4551"
"","57.1200","24.1545","0.4549"
"","57.3600","24.2563","0.4546"
"","57.6000","24.3579","0.4546"
"","57.8400","24.4596","0.4545"
"","58.0800","24.5610","0.4542"
"","58.3200","24.6626","0.4541"
"","58.5600","24.7638","0.4539"
"","58.8000","24.8655","0.4539"
"","59.0400","24.9670","0.4536"
"","59.2800","25.0688","0.4538"
"","59.5200","25.1706","0.4534"
"","59.7600","25.2722","0.4532"
"","60.0000","25.3741","0.4532"
"","60.2400","25.4759","0.4532"
"","60.4800","25.5773","0.4530"
"","60.7200","25.6791","0.4532"
"","60.9600","25.7807","0.4529"
"","61.2000","25.8820","0.4526"
"","61.4400","25.9836","0.4526"
"","61.6800","26.0852","0.4525"
"","61.9200","26.1866","0.4523"
"","62.1600","26.2882","0.4522"
"","62.4000","26.3899","0.4520"
"","62.6400","26.4914","0.4520"
"","62.8800","26.5931","0.4518"
"","63.1200","26.6944","0.4516"
"","63.3600","26.7959","0.4519"
"","63.6000","26.8975","0.4515"
"","63.8400","26.9989","0.4517"
"","64.0800","27.1006","0.4516"
"","64.3200","27.2026","0.4516"
"","64.5600","27.3039","0.4511"
"","64.8000","27.4061","0.4514"
"","65.0400","27.5077","0.4513"
"","65.2800","27.6095","0.4513"
"","65.5200","27.7112","0.4511"
"","65.7600","27.8126","0.4510"
"","66.0000","27.9139","0.4510"
"","66.2400","28.0156","0.4506"
"","66.4800","28.1171","0.4506"
"","66.7200","28.2187","0.4508"
"","66.9600","28.3204","0.4506"
"","67.2000","28.4218","0.4507"
"","67.4400","28.5234","0.4502"
"","67.6800","28.6251","0.4503"
"","67.9200","28.7265","0.4504"
"","68.1600","28.8281","0.4502"
"","68.4000","28.9296","0.4502"
"","68.6400","29.0308","0.4501"
"","68.8800","29.1326","0.4501"
"","69.1200","29.2344","0.4502"
"","69.3600","29.3361","0.4501"
"","69.6000","29.4380","0.4499"
"","69.8400","29.5398","0.4500"
"","70.0800","29.6414","0.4500"
"","70.3200","29.7431","0.4498"
"","70.5600","29.8446","0.4499"
"","70.8000","29.9462","0.4498"
"","71.0400","30.0476","0.4498"
"","71.2800","30.1490","0.4495"
"","71.5200","30.2504","0.4495"
"","71.7600","30.3524","0.4495"
"","72.0000","30.4540","0.4496"
"","72.2400","30.5556","0.4493"
"","72.4800","30.6570","0.4495"
"","72.7200","30.7584","0.4494"
"","72.9600","30.8599","0.4492"
"","73.2000","30.9615","0.4491"
"","73.4400","31.0630","0.4492"
"","73.6800","31.1647","0.4493"
"","73.9200","31.2664","0.4492"
"","74.1600","31.3680","0.4492"
"","74.4000","31.4699","0.4492"
"","74.6400","31.5718","0.4492"
"","74.8800","31.6735","0.4493"
"","75.1200","31.7753","0.4493"
"","75.3600","31.8766","0.4491"
"","75.6000","31.9780","0.4492"
"","75.8400","32.0796","0.4491"
"","76.0800","32.1809","0.4492"
"","76.3200","32.2826","0.4490"
"","76.5600","32.3844","0.4490"
"","76.8000","32.4859","0.4488"
"","77.0400","32.5875","0.4486"
"","77.2800","32.6892","0.4490"
"","77.5200","32.7906","0.4489"
"","77.7600","32.8921","0.4489"
"","78.0000","32.9933","0.4488"
"","78.2400","33.0950","0.4488"
"","78.4800","33.1967","0.4488"
"","78.7200","33.2984","0.4488"
"","78.9600","33.4000","0.4489"
"","79.2000","33.5022","0.4489"
"","79.4400","33.6037","0.4489"
"","79.6800","33.7053","0.4490"
"","79.9200","33.8072","0.4488"
"","80.1600","33.9086","0.4488"
"","80.4000","34.0101","0.4493"
"","80.6400","34.1117","0.4491"
"","80.8800","34.2133","0.4488"
"","81.1200","34.3146","0.4487"
"","81.3600","34.4161","0.4486"
"","81.6000","34.5177","0.4488"
"","81.8400","34.6195","0.4490"
"","82.0800","34.7213","0.4489"
"","82.3200","34.8226","0.4487"
"","82.5600","34.9240","0.4489"
"","82.8000","35.0256","0.4488"
"","83.0400","35.1269","0.4488"
"","83.2800","35.2286","0.4489"
"","83.5200","35.3305","0.4491"
"","83.7600","35.4319","0.4488"
"","84.0000","35.5339","0.4489"
"","84.2400","35.6358","0.4490"
"","84.4800","35.7372","0.4489"
"","84.7200","35.8392","0.4489"
"","84.9600","35.9408","0.4490"
"","85.2000","36.0421","0.4490"
"","85.4400","36.1438","0.4490"
"","85.6800","36.2452","0.4491"
"","85.9200","36.3466","0.4489"
"","86.1600","36.4483","0.4492"
"","86.4000","36.5499","0.4489"
"","86.6400","36.6513","0.4492"
"","86.8800","36.7532","0.4490"
"","87.1200","36.8545","0.4491"
"","87.3600","36.9561","0.4494"
"","87.6000","37.0577","0.4490"
"","87.8400","37.1590","0.4491"
"","88.0800","37.2605","0.4491"
"","88.3200","37.3622","0.4493"
"","88.5600","37.4638","0.4493"
"","88.8000","37.5660","0.4493"
"","89.0400","37.6677","0.4496"
"","89.2800","37.7694","0.4495"
"","89.5200","37.8710","0.4495"
"","89.7600","37.9727","0.4496"
"","90.0000","38.0741","0.4495"
"","90.2400","38.1757","0.4497"
"","90.4800","38.2772","0.4494"
"","90.7200","38.3788","0.4494"
"","90.9600","38.4804","0.4497"
"","91.2000","38.5818","0.4496"
"","91.4400","38.6834","0.4495"
"","91.6800","38.7852","0.4494"
"","91.9200","38.8867","0.4497"
"","92.1600","38.9882","0.4495"
"","92.4000","39.0897","0.4497"
"","92.6400","39.1910","0.4496"
"","92.8800","39.2926","0.4496"
"","93.1200","39.3943","0.4495"
"","93.3600","39.4960","0.4497"
"","93.6000","39.5976","0.4499"
"","93.8400","39.6997","0.4496"
"","94.0800","39.8011","0.4496"
"","94.3200","39.9033","0.4499"
"","94.5600","40.0048","0.4497"
"","94.8000","40.1062","0.4499"
"","95.0400","40.2078","0.4499"
"","95.2800","40.3090","0.4500"
"","95.5200","40.4105","0.4498"
"","95.7600","40.5124","0.4501"
"","96.0000","40.6138","0.4500"
"","96.2400","40.7156","0.4500"
"","96.4800","40.8172","0.4501"
"","96.7200","40.9185","0.4499"
"","96.9600","41.0201","0.4502"
"","97.2000","41.1217","0.4502"
"","97.4400","41.2231","0.4503"
"","97.6800","41.3247","0.4502"
"","97.9200","41.4264","0.4501"
"","98.1600","41.5279","0.4503"
"","98.4000","41.6300","0.4503"
"","98.6400","41.7315","0.4506"
"","98.8800","41.8333","0.4505"
"","99.1200","41.9351","0.4504"
"","99.3600","42.0368","0.4505"
"","99.6000","42.1382","0.4507"
"","99.8400","42.2399","0.4504"
"","100.0800","42.3410","0.4505"
"","100.3200","42.4427","0.4502"
"","100.5600","42.5441","0.4506"
"","100.8000","42.6459","0.4505"
"","101.0400","42.7474","0.4506"
"","101.2800","42.8491","0.4506"
"","101.5200","42.9506","0.4506"
"","101.7600","43.0521","0.4505"
"","102.0000","43.1536","0.4506"
"","102.2400","43.2550","0.4504"
"","102.4800","43.3565","0.4504"
"","102.7200","43.4582","0.4504"
"","102.9600","43.5599","0.4506"
"","103.2000","43.6618","0.4510"
"","103.4400","43.7637","0.4509"
"","103.6800","43.8654","0.4508"
"","103.9200","43.9670","0.4509"
"","104.1600","44.0685","0.4508"
"","104.4000","44.1702","0.4509"
"","104.6400","44.2720","0.4508"
"","104.8800","44.3733","0.4510"
"","105.1200","44.4746","0.4510"
"","105.3600","44.5764","0.4510"
"","105.6000","44.6776","0.4510"
"","105.8400","44.7793","0.4508"
"","106.0800","44.8814","0.4507"
"","106.3200","44.9828","0.4510"
"","106.5600","45.0842","0.4511"
"","106.8000","45.1856","0.4509"
"","107.0400","45.2866","0.4508"
"","107.2800","45.3886","0.4508"
"","107.5200","45.4904","0.4507"
"","107.7600","45.5919","0.4507"
"","108.0000","45.6938","0.4511"
"","108.2400","45.7955","0.4510"
"","108.4800","45.8972","0.4508"
"","108.7200","45.9993","0.4510"
"","108.9600","46.1009","0.4511"
"","109.2000","46.2021","0.4510"
"","109.4400","46.3038","0.4508"
"","109.6800","46.4052","0.4506"
"","109.9200","46.5068","0.4511"
"","110.1600","46.6086","0.4509"
"","110.4000","46.7100","0.4508"
"","110.6400","46.8113","0.4506"
"","110.8800","46.9131","0.4507"
"","111.1200","47.0145","0.4506"
"","111.3600","47.1162","0.4506"
"","111.6000","47.2178","0.4503"
"","111.8400","47.3192","0.4504"
"","112.0800","47.4206","0.4505"
"","112.3200","47.5223","0.4504"
"","112.5600","47.6238","0.4506"
"","112.8000","47.7255","0.4506"
"","113.0400","47.8275","0.4506"
"","113.2800","47.9292","0.4504"
"","113.5200","48.0308","0.4506"
"","113.7600","48.1328","0.4504"
"","114.0000","48.2342","0.4504"
"","114.2400","48.3360","0.4505"
"","114.4800","48.4372","0.4504"
"","114.7200","48.5388","0.4503"
"","114.9600","48.6402","0.4503"
"","115.2000","48.7418","0.4502"
"","115.4400","48.8434","0.4503"
"","115.6800","48.9452","0.4500"
"","115.9200","49.0467","0.4503"
"","116.1600","49.1481","0.4499"
"","116.4000","49.2499","0.4500"
"","116.6400","49.3511","0.4500"
"","116.8800","49.4526","0.4502"
"","117.1200","49.5543","0.4500"
"","117.3600","49.6559","0.4498"
"","117.6000","49.7576","0.4501"
"","117.8400","49.8595","0.4498"
"","118.0800","49.9611","0.4500"
"","118.3200","50.0631","0.4499"
"","118.5600","50.1647","0.4497"
"","118.8000","50.2663","0.4498"
"","119.0400","50.3680","0.4494"
"","119.2800","50.4692","0.4494"
"","119.5200","50.5707","0.4496"
"","119.7600","50.6725","0.4500"
"","120.0000","50.7737","0.4494"
"","120.2400","50.8755","0.4498"
"","120.4800","50.9772","0.4499"
"","120.7200","51.0786","0.4498"
"","120.9600","51.1802","0.4497"
"","121.2000","51.2817","0.4497"
"","121.4400","51.3831","0.4496"
"","121.6800","51.4847","0.4495"
"","121.9200","51.5864","0.4498"
"","122.1600","51.6878","0.4499"
"","122.4000","51.7898","0.4496"
"","122.6400","51.8913","0.4495"
"","122.8800","51.9931","0.4497"
"","123.1200","52.0949","0.4496"
"","123.3600","52.1968","0.4497"
"","123.6000","52.2984","0.4498"
"","123.8400","52.4001","0.4498"
"","124.0800","52.5012","0.4496"
"","124.3200","52.6029","0.4494"
"","124.5600","52.7043","0.4492"
"","124.8000","52.8057","0.4495"
"","125.0400","52.9073","0.4494"
"","125.2800","53.0091","0.4495"
"","125.5200","53.1106","0.4493"
"","125.7600","53.2122","0.4495"
"","126.0000","53.3139","0.4495"
"","126.2400","53.4152","0.4494"
"","126.4800","53.5167","0.4493"
"","126.7200","53.6181","0.4495"
"","126.9600","53.7198","0.4496"
"","127.2000","53.8217","0.4491"
"","127.4400","53.9236","0.4494"
"","127.6800","54.0252","0.4495"
"","127.9200","54.1270","0.4494"
"","128.1600","54.2286","0.4498"
"","128.4000","54.3301","0.4494"
"","128.6400","54.4320","0.4495"
"","128.8800","54.5336","0.4495"
"","129.1200","54.6347","0.4493"
"","129.3600","54.7364","0.4495"
"","129.6000","54.8376","0.4492"
"","129.8400","54.9394","0.4495"
"","130.0800","55.0413","0.4491"
"","130.3200","55.1426","0.4491"
"","130.5600","55.2441","0.4493"
"","130.8000","55.3458","0.4489"
"","131.0400","55.4470","0.4491"
"","131.2800","55.5486","0.4491"
"","131.5200","55.6505","0.4489"
"","131.7600","55.7518","0.4489"
"","132.0000","55.8535","0.4491"
"","132.2400","55.9553","0.4492"
"","132.4800","56.0569","0.4489"
"","132.7200","56.1591","0.4491"
"","132.9600","56.2609","0.4492"
"","133.2000","56.3622","0.4491"
"","133.4400","56.4640","0.4491"
"","133.6800","56.5653","0.4492"
"","133.9200","56.6668","0.4489"
"","134.1600","56.7685","0.4488"
"","134.4000","56.8700","0.4488"
"","134.6400","56.9713","0.4488"
"","134.8800","57.0732","0.4485"
"","135.1200","57.1746","0.4487"
"","135.3600","57.2763","0.4487"
"","135.6000","57.3778","0.4484"
"","135.8400","57.4793","0.4486"
"","136.0800","57.5804","0.4483"
"","136.3200","57.6823","0.4484"
"","136.5600","57.7837","0.4488"
"","136.8000","57.8855","0.4484"
"","137.0400","57.9873","0.4485"
"","137.2800","58.0891","0.4487"
"","137.5200","58.1909","0.4484"
"","137.7600","58.2928","0.4483"
"","138.0000","58.3942","0.4483"
"","138.2400","58.4959","0.4482"
"","138.4800","58.5974","0.4481"
"","138.7200","58.6987","0.4482"
"","138.9600","58.8003","0.4481"
"","139.2000","58.9019","0.4480"
"","139.4400","59.0035","0.4479"
"","139.6800","59.1053","0.4479"
"","139.9200","59.2067","0.4479"
"","140.1600","59.3083","0.4479"
"","140.4000","59.4098","0.4478"
"","140.6400","59.5111","0.4477"
"","140.8800","59.6127","0.4478"
"","141.1200","59.7144","0.4479"
"","141.3600","59.8159","0.4477"
"","141.6000","59.9176","0.4476"
"","141.8400","60.0193","0.4478"
"","142.0800","60.1208","0.4474"
"","142.3200","60.2229","0.4476"
"","142.5600","60.3243","0.4474"
"","142.8000","60.4264","0.4474"
"","143.0400","60.5282","0.4472"
"","143.2800","60.6296","0.4473"
"","143.5200","60.7308","0.4472"
"","143.7600","60.8325","0.4471"
"","144.0000","60.9337","0.4470"
"","144.2400","61.0353","0.4470"
"","144.4800","61.1372","0.4468"
"","144.7200","61.2386","0.4472"
"","144.9600","61.3403","0.4472"
"","145.2000","61.4419","0.4467"
"","145.4400","61.5434","0.4469"
"","145.6800","61.6449","0.4465"
"","145.9200","61.7463","0.4464"
"","146.1600","61.8476","0.4463"
"","146.4000","61.9496","0.4464"
"","146.6400","62.0513","0.4464"
"","146.8800","62.1531","0.4462"
"","147.1200","62.2549","0.4463"
"","147.3600","62.3567","0.4463"
"","147.6000","62.4581","0.4463"
"","147.8400","62.5599","0.4461"
"","148.0800","62.6615","0.4460"
"","148.3200","62.7628","0.4458"
"","148.5600","62.8646","0.4459"
"","148.8000","62.9659","0.4456"
"","149.0400","63.0672","0.4458"
"","149.2800","63.1692","0.4455"
"","149.5200","63.2706","0.4456"
"","149.7600","63.3723","0.4454"
"","150.0000","63.4740","0.4455"
"","150.2400","63.5753","0.4455"
"","150.4800","63.6767","0.4454"
"","150.7200","63.7782","0.4451"
"","150.9600","63.8796","0.4451"
"","151.2000","63.9814","0.4453"
"","151.4400","64.0835","0.4449"
"","151.6800","64.1848","0.4448"
"","151.9200","64.2869","0.4448"
"","152.1600","64.3887","0.4450"
"","152.4000","64.4903","0.4448"
"","152.6400","64.5921","0.4444"
"","152.8800","64.6935","0.4443"
"","153.1200","64.7948","0.4445"
"","153.3600","64.8965","0.4445"
"","153.6000","64.9979","0.4441"
"","153.8400","65.0994","0.4441"
"","154.0800","65.2011","0.4440"
"","154.3200","65.3026","0.4440"
"","154.5600","65.4042","0.4439"
"","154.8000","65.5058","0.4437"
"","155.0400","65.6073","0.4436"
"","155.2800","65.7088","0.4439"
"","155.5200","65.8105","0.4437"
"","155.7600","65.9117","0.4435"
"","156.0000","66.0133","0.4434"
"","156.2400","66.1152","0.4435"
"","156.4800","66.2168","0.4434"
"","156.7200","66.3187","0.4432"
"","156.9600","66.4208","0.4431"
"","157.2000","66.5222","0.4429"
"","157.4400","66.6241","0.4428"
"","157.6800","66.7254","0.4427"
"","157.9200","66.8268","0.4425"
"","158.1600","66.9284","0.4426"
"","158.4000","67.0301","0.4426"
"","158.6400","67.1314","0.4424"
"","158.8800","67.2332","0.4422"
"","159.1200","67.3346","0.4421"
"","159.3600","67.4362","0.4420"
"","159.6000","67.5380","0.4419"
"","159.8400","67.6393","0.4417"
"","160.0800","67.7407","0.4417"
"","160.3200","67.8424","0.4414"
"","160.5600","67.9436","0.4414"
"","160.8000","68.0454","0.4413"
"","161.0400","68.1473","0.4411"
"","161.2800","68.2489","0.4413"
"","161.5200","68.3506","0.4409"
"","161.7600","68.4526","0.4409"
"","162.0000","68.5541","0.4409"
"","162.2400","68.6559","0.4404"
"","162.4800","68.7577","0.4403"
"","162.7200","68.8590","0.4401"
"","162.9600","68.9606","0.4402"
"","163.2000","69.0619","0.4398"
"","163.4400","69.1632","0.4396"
"","163.6800","69.2652","0.4397"
"","163.9200","69.3667","0.4393"
"","164.1600","69.4682","0.4393"
"","164.4000","69.5700","0.4391"
"","164.6400","69.6712","0.4392"
"","164.8800","69.7728","0.4387"
"","165.1200","69.8741","0.4387"
"","165.3600","69.9760","0.4387"
"","165.6000","70.0777","0.4386"
"","165.8400","70.1792","0.4387"
"","166.0800","70.2807","0.4383"
"","166.3200","70.3826","0.4379"
"","166.5600","70.4845","0.4380"
"","166.8000","70.5863","0.4380"
"","167.0400","70.6881","0.4379"
"","167.2800","70.7896","0.4375"
"","167.5200","70.8908","0.4372"
"","167.7600","70.9926","0.4373"
"","168.0000","71.0940","0.4369"
"","168.2400","71.1955","0.4369"
"","168.4800","71.2972","0.4369"
"","168.7200","71.3986","0.4365"
"","168.9600","71.5003","0.4366"
"","169.2000","71.6021","0.4365"
"","169.4400","71.7035","0.4364"
"","169.6800","71.8048","0.4358"
"","169.9200","71.9063","0.4358"
"","170.1600","72.0077","0.4356"
"","170.4000","72.1094","0.4355"
"","170.6400","72.2112","0.4354"
"","170.8800","72.3129","0.4349"
"","171.1200","72.4147","0.4348"
"","171.3600","72.5166","0.4349"
"","171.6000","72.6177","0.4343"
"","171.8400","72.7200","0.4344"
"","172.0800","72.8216","0.4339"
"","172.3200","72.9230","0.4340"
"","172.5600","73.0247","0.4335"
"","172.8000","73.1260","0.4337"
"","173.0400","73.2273","0.4333"
"","173.2800","73.3291","0.4330"
"","173.5200","73.4305","0.4328"
"","173.7600","73.5321","0.4327"
"","174.0000","73.6340","0.4324"
"","174.2400","73.7354","0.4322"
"","174.4800","73.8370","0.4319"
"","174.7200","73.9385","0.4318"
"","174.9600","74.0398","0.4318"
"","175.2000","74.1413","0.4310"
"","175.4400","74.2431","0.4311"
"","175.6800","74.3446","0.4306"
"","175.9200","74.4467","0.4305"
"","176.1600","74.5484","0.4303"
"","176.4000","74.6501","0.4299"
"","176.6400","74.7520","0.4296"
"","176.8800","74.8535","0.4296"
"","177.1200","74.9550","0.4292"
"","177.3600","75.0565","0.4289"
"","177.6000","75.1580","0.4288"
"","177.8400","75.2595","0.4285"
"","178.0800","75.3610","0.4283"
"","178.3200","75.4628","0.4277"
"","178.5600","75.5642","0.4275"
"","178.8000","75.6659","0.4271"
"","179.0400","75.7673","0.4267"
"","179.2800","75.8690","0.4264"
"","179.5200","75.9705","0.4261"
"","179.7600","76.0719","0.4257"
"","180.0000","76.1735","0.4252"
"","180.2400","76.2750","0.4249"
"","180.4800","76.3766","0.4246"
"","180.7200","76.4784","0.4244"
"","180.9600","76.5807","0.4239"
"","181.2000","76.6822","0.4237"
"","181.4400","76.7839","0.4233"
"","181.6800","76.8856","0.4229"
"","181.9200","76.9869","0.4223"
"","182.1600","77.0886","0.4220"
"","182.4000","77.1902","0.4217"
"","182.6400","77.2913","0.4210"
"","182.8800","77.3932","0.4205"
"","183.1200","77.4947","0.4203"
"","183.3600","77.5961","0.4197"
"","183.6000","77.6981","0.4195"
"","183.8400","77.7993","0.4190"
"","184.0800","77.9009","0.4184"
"","184.3200","78.0026","0.4181"
"","184.5600","78.1037","0.4177"
"","184.8000","78.2054","0.4171"
"","185.0400","78.3072","0.4169"
"","185.2800","78.4088","0.4164"
"","185.5200","78.5105","0.4156"
"","185.7600","78.6124","0.4154"
"","186.0000","78.7139","0.4150"
"","186.2400","78.8159","0.4142"
"","186.4800","78.9177","0.4141"
"","186.7200","79.0191","0.4136"
"","186.9600","79.1207","0.4130"
"","187.2000","79.2218","0.4127"
"","187.4400","79.3234","0.4121"
"","187.6800","79.4251","0.4116"
"","187.9200","79.5267","0.4117"
"","188.1600","79.6283","0.4112"
"","188.4000","79.7300","0.4106"
"","188.6400","79.8313","0.4099"
"","188.8800","79.9329","0.4098"
"","189.1200","80.0344","0.4092"
"","189.3600","80.1359","0.4089"
"","189.6000","80.2373","0.4086"
"","189.8400","80.3391","0.4082"
"","190.0800","80.4407","0.4077"
"","190.3200","80.5424","0.4074"
"","190.5600","80.6443","0.4073"
"","190.8000","80.7462","0.4070"
"","191.0400","80.8480","0.4068"
"","191.2800","80.9495","0.4065"
"","191.5200","81.0510","0.4059"
"","191.7600","81.1527","0.4061"
"","192.0000","81.2542","0.4056"
"","192.2400","81.3556","0.4052"
"","192.4800","81.4572","0.4054"
"","192.7200","81.5585","0.4048"
"","192.9600","81.6600","0.4047"
"","193.2000","81.7620","0.4045"
"","193.4400","81.8636","0.4043"
"","193.6800","81.9650","0.4042"
"","193.9200","82.0667","0.4040"
"","194.1600","82.1676","0.4038"
"","194.4000","82.2694","0.4037"
"","194.6400","82.3711","0.4039"
"","194.8800","82.4727","0.4038"
"","195.1200","82.5746","0.4036"
"","195.3600","82.6763","0.4035"
"","195.6000","82.7780","0.4032"
"","195.8400","82.8799","0.4034"
"","196.0800","82.9815","0.4032"
"","196.3200","83.0830","0.4033"
"","196.5600","83.1847","0.4033"
"","196.8000","83.2861","0.4030"
"","197.0400","83.3875","0.4031"
"","197.2800","83.4894","0.4031"
"","197.5200","83.5907","0.4033"
"","197.7600","83.6921","0.4033"
"","198.0000","83.7940","0.4035"
"","198.2400","83.8953","0.4033"
"","198.4800","83.9970","0.4033"
"","198.7200","84.0985","0.4034"
"","198.9600","84.2000","0.4034"
"","199.2000","84.3014","0.4036"
"","199.4400","84.4030","0.4037"
"","199.6800","84.5045","0.4035"
"","199.9200","84.6065","0.4040"
"","200.1600","84.7082","0.4040"
"","200.4000","84.8100","0.4040"
"","200.6400","84.9116","0.4043"
"","200.8800","85.0137","0.4040"
"","201.1200","85.1150","0.4043"
"","201.3600","85.2166","0.4044"
"","201.6000","85.3180","0.4045"
"","201.8400","85.4194","0.4043"
"","202.0800","85.5212","0.4045"
"","202.3200","85.6227","0.4046"
"","202.5600","85.7243","0.4045"
"","202.8000","85.8259","0.4046"
"","203.0400","85.9273","0.4046"
"","203.2800","86.0289","0.4047"
"","203.5200","86.1307","0.4050"
"","203.7600","86.2320","0.4048"
"","204.0000","86.3336","0.4051"
"","204.2400","86.4350","0.4050"
"","204.4800","86.5366","0.4052"
"","204.7200","86.6383","0.4051"
"","204.9600","86.7403","0.4053"
"","205.2000","86.8419","0.4055"
"","205.4400","86.9438","0.4054"
"","205.6800","87.0456","0.4056"
"","205.9200","87.1470","0.4056"
"","206.1600","87.2488","0.4057"
"","206.4000","87.3503","0.4058"
"","206.6400","87.4516","0.4056"
"","206.8800","87.5531","0.4058"
"","207.1200","87.6544","0.4059"
"","207.3600","87.7563","0.4058"
"","207.6000","87.8581","0.4061"
"","207.8400","87.9595","0.4059"
"","208.0800","88.0610","0.4060"
"","208.3200","88.1626","0.4061"
"","208.5600","88.2639","0.4060"
"","208.8000","88.3654","0.4061"
"","209.0400","88.4673","0.4064"
"","209.2800","88.5685","0.4064"
"","209.5200","88.6703","0.4064"
"","209.7600","88.7721","0.4065"
"","210.0000","88.8738","0.4070"
"","210.2400","88.9758","0.4065"
"","210.4800","89.0776","0.4067"
"","210.7200","89.1792","0.4064"
"","210.9600","89.2808","0.4065"
"","211.2000","89.3821","0.4065"
"","211.4400","89.4835","0.4068"
"","211.6800","89.5852","0.4070"
"","211.9200","89.6867","0.4069"
"","212.1600","89.7881","0.4071"
"","212.4000","89.8900","0.4073"
"","212.6400","89.9915","0.4071"
"","212.8800","90.0929","0.4069"
"","213.1200","90.1947","0.4069"
"","213.3600","90.2960","0.4068"
"","213.6000","90.3973","0.4068"
"","213.8400","90.4992","0.4066"
"","214.0800","90.6005","0.4071"
"","214.3200","90.7023","0.4066"
"","214.5600","90.8042","0.4069"
"","214.8000","90.9061","0.4068"
"","215.0400","91.0077","0.4068"
"","215.2800","91.1095","0.4067"
"","215.5200","91.2110","0.4072"
"","215.7600","91.3126","0.4070"
"","216.0000","91.4141","0.4071"
"","216.2400","91.5157","0.4072"
"","216.4800","91.6175","0.4070"
"","216.7200","91.7187","0.4071"
"","216.9600","91.8200","0.4072"
"","217.2000","91.9219","0.4071"
"","217.4400","92.0234","0.4071"
"","217.6800","92.1251","0.4072"
"","217.9200","92.2268","0.4073"
"","218.1600","92.3280","0.4072"
"","218.4000","92.4294","0.4075"
"","218.6400","92.5310","0.4075"
"","218.8800","92.6325","0.4077"
"","219.1200","92.7344","0.4079"
"","219.3600","92.8360","0.4080"
"","219.6000","92.9377","0.4081"
"","219.8400","93.0397","0.4077"
"","220.0800","93.1415","0.4080"
"","220.3200","93.2431","0.4079"
"","220.5600","93.3448","0.4082"
"","220.8000","93.4462","0.4081"
"","221.0400","93.5477","0.4080"
"","221.2800","93.6492","0.4084"
"","221.5200","93.7506","0.4082"
"","221.7600","93.8522","0.4085"
"","222.0000","93.9541","0.4087"
"","222.2400","94.0554","0.4085"
"","222.4800","94.1570","0.4085"
"","222.7200","94.2585","0.4086"
"","222.9600","94.3601","0.4085"
"","223.2000","94.4615","0.4084"
"","223.4400","94.5632","0.4085"
"","223.6800","94.6645","0.4082"
"","223.9200","94.7662","0.4086"
"","224.1600","94.8679","0.4088"
"","224.4000","94.9699","0.4084"
"","224.6400","95.0718","0.4086"
"","224.8800","95.1736","0.4087"
"","225.1200","95.2749","0.4085"
"","225.3600","95.3767","0.4088"
"","225.6000","95.4781","0.4088"
"","225.8400","95.5796","0.4087"
"","226.0800","95.6813","0.4090"
"","226.3200","95.7828","0.4089"
"","226.5600","95.8842","0.4089"
"","226.8000","95.9858","0.4088"
"","227.0400","96.0875","0.4089"
"","227.2800","96.1890","0.4091"
"","227.5200","96.2908","0.4087"
"","227.7600","96.3921","0.4090"
"","228.0000","96.4936","0.4088"
"","228.2400","96.5951","0.4092"
"","228.4800","96.6966","0.4090"
"","228.7200","96.7984","0.4093"
"","228.9600","96.9002","0.4087"
"","229.2000","97.0016","0.4090"
"","229.4400","97.1036","0.4090"
"","229.6800","97.2052","0.4090"
"","229.9200","97.3072","0.4091"
"","230.1600","97.4089","0.4091"
"","230.4000","97.5104","0.4090"
"","230.6400","97.6116","0.4092"
"","230.8800","97.7131","0.4092"
"","231.1200","97.8146","0.4092"
"","231.3600","97.9162","0.4091"
"","231.6000","98.0180","0.4093"
"","231.8400","98.1195","0.4093"
"","232.0800","98.2210","0.4095"
"","232.3200","98.3227","0.4094"
"","232.5600","98.4241","0.4096"
"","232.8000","98.5256","0.4096"
"","233.0400","98.6273","0.4099"
"","233.2800","98.7285","0.4099"
"","233.5200","98.8303","0.4098"
"","233.7600","98.9321","0.4097"
"","234.0000","99.0338","0.4101"
"","234.2400","99.1355","0.4098"
"","234.4800","99.2375","0.4098"
"","234.7200","99.3389","0.4101"
"","234.9600","99.4408","0.4101"
"","235.2000","99.5424","0.4101"
"","235.4400","99.6437","0.4101"
"","235.6800","99.7452","0.4102"
"","235.9200","99.8468","0.4102"
"","236.1600","99.9479","0.4099"
"","236.4000","100.0500","0.4102"
"","236.6400","100.1515","0.4104"
"","236.8800","100.2530","0.4104"
"","237.1200","100.3548","0.4104"
"","237.3600","100.4562","0.4103"
"","237.6000","100.5575","0.4101"
"","237.8400","100.6591","0.4103"
"","238.0800","100.7604","0.4105"
"","238.3200","100.8621","0.4108"
"","238.5600","100.9641","0.4108"
"","238.8000","101.0657","0.4107"
"","239.0400","101.1677","0.4108"
"","239.2800","101.2695","0.4107"
"","239.5200","101.3710","0.4108"
"","239.7600","101.4726","0.4109"
"","240.0000","101.5743","0.4111"
"","240.2400","101.6758","0.4108"
"","240.4800","101.7774","0.4112"
"","240.7200","101.8786","0.4110"
"","240.9600","101.9802","0.4109"
"","241.2000","102.0818","0.4111"
"","241.4400","102.1833","0.4114"
"","241.6800","102.2852","0.4113"
"","241.9200","102.3869","0.4114"
"","242.1600","102.4883","0.4113"
"","242.4000","102.5896","0.4113"
"","242.6400","102.6909","0.4112"
"","242.8800","102.7926","0.4112"
"","243.1200","102.8943","0.4110"
"","243.3600","102.9960","0.4113"
"","243.6000","103.0976","0.4114"
"","243.8400","103.1996","0.4112"
"","244.0800","103.3014","0.4112"
"","244.3200","103.4031","0.4113"
"","244.5600","103.5049","0.4113"
"","244.8000","103.6061","0.4112"
"","245.0400","103.7076","0.4114"
"","245.2800","103.8092","0.4113"
"","245.5200","103.9109","0.4111"
"","245.7600","104.0125","0.4112"
"","246.0000","104.1141","0.4111"
"","246.2400","104.2153","0.4112"
"","246.4800","104.3169","0.4114"
"","246.7200","104.4186","0.4113"
"","246.9600","104.5201","0.4116"
"","247.2000","104.6216","0.4116"
"","247.4400","104.7233","0.4116"
"","247.6800","104.8246","0.4114"
"","247.9200","104.9262","0.4113"
"","248.1600","105.0279","0.4115"
"","248.4000","105.1294","0.4117"
"","248.6400","105.2316","0.4118"
"","248.8800","105.3335","0.4118"
"","249.1200","105.4348","0.4118"
"","249.3600","105.5368","0.4118"
"","249.6000","105.6383","0.4118"
"","249.8400","105.7398","0.4120"
"","250.0800","105.8414","0.4118"
"","250.3200","105.9428","0.4120"
"","250.5600","106.0440","0.4122"
"","250.8000","106.1458","0.4121"
"","251.0400","106.2474","0.4122"
"","251.2800","106.3490","0.4122"
"","251.5200","106.4509","0.4120"
"","251.7600","106.5521","0.4121"
"","252.0000","106.6537","0.4122"
"","252.2400","106.7551","0.4121"
"","252.4800","106.8566","0.4124"
"","252.7200","106.9583","0.4124"
"","252.9600","107.0601","0.4126"
"","253.2000","107.1615","0.4124"
"","253.4400","107.2635","0.4125"
"","253.6800","107.3652","0.4125"
"","253.9200","107.4669","0.4127"
"","254.1600","107.5687","0.4128"
"","254.4000","107.6704","0.4128"
"","254.6400","107.7718","0.4127"
"","254.8800","107.8733","0.4127"
"","255.1200","107.9747","0.4131"
"","255.3600","108.0763","0.4131"
"","255.6000","108.1780","0.4133"
"","255.8400","108.2794","0.4130"
"","256.0800","108.3810","0.4134"
"","256.3200","108.4827","0.4132"
"","256.5600","108.5843","0.4133"
"","256.8000","108.6857","0.4134"
"","257.0400","108.7873","0.4136"
"","257.2800","108.8886","0.4138"
"","257.5200","108.9904","0.4136"
"","257.7600","109.0919","0.4139"
"","258.0000","109.1937","0.4137"
"","258.2400","109.2952","0.4139"
"","258.4800","109.3974","0.4141"
"","258.7200","109.4988","0.4142"
"","258.9600","109.6008","0.4138"
"","259.2000","109.7024","0.4141"
"","259.4400","109.8038","0.4143"
"","259.6800","109.9053","0.4144"
"","259.9200","110.0068","0.4145"
"","260.1600","110.1082","0.4146"
"","260.4000","110.2099","0.4142"
"","260.6400","110.3113","0.4144"
"","260.8800","110.4129","0.4145"
"","261.1200","110.5147","0.4145"
"","261.3600","110.6162","0.4145"
"","261.6000","110.7179","0.4145"
"","261.8400","110.8194","0.4145"
"","262.0800","110.9206","0.4145"
"","262.3200","111.0219","0.4148"
"","262.5600","111.1240","0.4147"
"","262.8000","111.2256","0.4143"
"","263.0400","111.3276","0.4145"
"","263.2800","111.4292","0.4147"
"","263.5200","111.5308","0.4149"
"","263.7600","111.6327","0.4148"
"","264.0000","111.7343","0.4149"
"","264.2400","111.8358","0.4151"
"","264.4800","111.9376","0.4147"
"","264.7200","112.0388","0.4149"
"","264.9600","112.1403","0.4147"
"","265.2000","112.2416","0.4150"
"","265.4400","112.3434","0.4151"
"","265.6800","112.4452","0.4151"
"","265.9200","112.5468","0.4148"
"","266.1600","112.6481","0.4150"
"","266.4000","112.7497","0.4148"
"","266.6400","112.8512","0.4148"
"","266.8800","112.9526","0.4149"
"","267.1200","113.0544","0.4150"
"","267.3600","113.1559","0.4150"
"","267.6000","113.2574","0.4151"
"","267.8400","113.3592","0.4151"
"","268.0800","113.4612","0.4148"
"","268.3200","113.5631","0.4149"
"","268.5600","113.6650","0.4149"
"","268.8000","113.7663","0.4148"
"","269.0400","113.8678","0.4149"
"","269.2800","113.9694","0.4150"
"","269.5200","114.0708","0.4151"
"","269.7600","114.1723","0.4151"
"","270.0000","114.2741","0.4149"
"","270.2400","114.3753","0.4148"
"","270.4800","114.4769","0.4148"
"","270.7200","114.5787","0.4152"
"","270.9600","114.6802","0.4151"
"","271.2000","114.7818","0.4150"
"","271.4400","114.8835","0.4152"
"","271.6800","114.9843","0.4150"
"","271.9200","115.0863","0.4149"
"","272.1600","115.1879","0.4151"
"","272.4000","115.2894","0.4150"
"","272.6400","115.3913","0.4153"
"","272.8800","115.4932","0.4153"
"","273.1200","115.5948","0.4151"
"","273.3600","115.6968","0.4152"
"","273.6000","115.7983","0.4152"
"","273.8400","115.8997","0.4155"
"","274.0800","116.0016","0.4151"
"","274.3200","116.1027","0.4152"
"","274.5600","116.2043","0.4154"
"","274.8000","116.3060","0.4150"
"","275.0400","116.4075","0.4154"
"","275.2800","116.5090","0.4153"
"","275.5200","116.6109","0.4153"
"","275.7600","116.7123","0.4154"
"","276.0000","116.8137","0.4151"
"","276.2400","116.9152","0.4153"
"","276.4800","117.0167","0.4152"
"","276.7200","117.1183","0.4153"
"","276.9600","117.2200","0.4150"
"","277.2000","117.3215","0.4152"
"","277.4400","117.4232","0.4154"
"","277.6800","117.5250","0.4151"
"","277.9200","117.6268","0.4152"
"","278.1600","117.7284","0.4150"
"","278.4000","117.8306","0.4153"
"","278.6400","117.9319","0.4153"
"","278.8800","118.0335","0.4153"
"","279.1200","118.1349","0.4151"
"","279.3600","118.2363","0.4153"
"","279.6000","118.3379","0.4152"
"","279.8400","118.4393","0.4151"
"","280.0800","118.5410","0.4153"
"","280.3200","118.6427","0.4150"
"","280.5600","118.7443","0.4149"
"","280.8000","118.8457","0.4152"
"","281.0400","118.9475","0.4151"
"","281.2800","119.0488","0.4150"
"","281.5200","119.1502","0.4151"
"","281.7600","119.2518","0.4152"
"","282.0000","119.3535","0.4151"
"","282.2400","119.4552","0.4153"
"","282.4800","119.5571","0.4153"
"","282.7200","119.6588","0.4153"
"","282.9600","119.7607","0.4151"
"","283.2000","119.8622","0.4152"
"","283.4400","119.9638","0.4152"
"","283.6800","120.0656","0.4156"
"","283.9200","120.1669","0.4155"
"","284.1600","120.2683","0.4156"
"","284.4000","120.3700","0.4154"
"","284.6400","120.4713","0.4154"
"","284.8800","120.5730","0.4153"
"","285.1200","120.6747","0.4154"
"","285.3600","120.7762","0.4155"
"","285.6000","120.8779","0.4154"
"","285.8400","120.9795","0.4155"
"","286.0800","121.0807","0.4155"
"","286.3200","121.1821","0.4156"
"","286.5600","121.2838","0.4158"
"","286.8000","121.3853","0.4158"
"","287.0400","121.4874","0.4156"
"","287.2800","121.5890","0.4154"
"","287.5200","121.6909","0.4157"
"","287.7600","121.7926","0.4158"
"","288.0000","121.8944","0.4160"
"","288.2400","121.9959","0.4159"
"","288.4800","122.0976","0.4159"
"","288.7200","122.1988","0.4159"
"","288.9600","122.3003","0.4160"
"","289.2000","122.4021","0.4160"
"","289.4400","122.5035","0.4162"
"","289.6800","122.6049","0.4160"
"","289.9200","122.7068","0.4160"
"","290.1600","122.8081","0.4161"
"","290.4000","122.9096","0.4161"
"","290.6400","123.0114","0.4162"
[...]
"","13.1000","110.4864","0.4236"
"","13.1200","110.6556","0.4237"
"","13.1400","110.8248","0.4237"
"","13.1600","110.9941","0.4237"
"","13.1800","111.1635","0.4239"
"","13.2000","111.3332","0.4239"
"","13.2200","111.5026","0.4237"
"","13.2400","111.6719","0.4237"
"","13.2600","111.8413","0.4237"
"","13.2800","112.0106","0.4240"
"","13.3000","112.1798","0.4241"
"","13.3200","112.3490","0.4241"
"","13.3400","112.5183","0.4242"
"","13.3600","112.6877","0.4243"
"","13.3800","112.8571","0.4242"
"","13.4000","113.0264","0.4242"
"","13.4200","113.1957","0.4242"
"","13.4400","113.3650","0.4242"
"","13.4600","113.5342","0.4244"
"","13.4800","113.7035","0.4245"
"","13.5000","113.8730","0.4245"
"","13.5200","114.0424","0.4248"
"","13.5400","114.2118","0.4246"
"","13.5600","114.3812","0.4246"
"","13.5800","114.5504","0.4247"
"","13.6000","114.7196","0.4247"
"","13.6200","114.8889","0.4247"
"","13.6400","115.0582","0.4251"
"","13.6600","115.2275","0.4250"
"","13.6800","115.3970","0.4252"
"","13.7000","115.5665","0.4252"
"","13.7200","115.7359","0.4250"
"","13.7400","115.9051","0.4250"
"","13.7600","116.0744","0.4250"
"","13.7800","116.2438","0.4252"
"","13.8000","116.4130","0.4254"
"","13.8200","116.5823","0.4253"
"","13.8400","116.7517","0.4251"
"","13.8600","116.9211","0.4252"
"","13.8800","117.0904","0.4254"
"","13.9000","117.2597","0.4254"
"","13.9200","117.4291","0.4256"
"","13.9400","117.5984","0.4256"
"","13.9600","117.7676","0.4257"
"","13.9800","117.9369","0.4258"
"","14.0000","118.1062","0.4256"
"","14.0200","118.2756","0.4257"
"","14.0400","118.4450","0.4257"
"","14.0600","118.6144","0.4257"
"","14.0800","118.7836","0.4259"
"","14.1000","118.9529","0.4259"
"","14.1200","119.1223","0.4259"
"","14.1400","119.2917","0.4260"
"","14.1600","119.4611","0.4259"
"","14.1800","119.6306","0.4259"
"","14.2000","119.8000","0.4261"
"","14.2200","119.9693","0.4262"
"","14.2400","120.1385","0.4261"
"","14.2600","120.3077","0.4263"
"","14.2800","120.4769","0.4264"
"","14.3000","120.6461","0.4264"
"","14.3200","120.8155","0.4264"
"","14.3400","120.9851","0.4264"
"","14.3600","121.1545","0.4266"
"","14.3800","121.3238","0.4267"
"","14.4000","121.4930","0.4265"
"","14.4200","121.6623","0.4265"
"","14.4400","121.8315","0.4267"
"","14.4600","122.0009","0.4267"
"","14.4800","122.1704","0.4268"
"","14.5000","122.3398","0.4269"
"","14.5200","122.5092","0.4269"
"","14.5400","122.6786","0.4269"
"","14.5600","122.8479","0.4269"
"","14.5800","123.0171","0.4270"
"","14.6000","123.1863","0.4272"
"","14.6200","123.3557","0.4274"
"","14.6400","123.5250","0.4274"
"","14.6600","123.6944","0.4274"
"","14.6800","123.8638","0.4274"
"","14.7000","124.0331","0.4272"
"","14.7200","124.2022","0.4272"
"","14.7400","124.3715","0.4272"
"","14.7600","124.5409","0.4274"
"","14.7800","124.7103","0.4275"
"","14.8000","124.8797","0.4273"
"","14.8200","125.0491","0.4275"
"","14.8400","125.2184","0.4275"
"","14.8600","125.3877","0.4276"
"","14.8800","125.5570","0.4277"
"","14.9000","125.7263","0.4277"
"","14.9200","125.8956","0.4277"
"","14.9400","126.0648","0.4278"
"","14.9600","126.2343","0.4279"
"","14.9800","126.4038","0.4280"
"","15.0000","126.5731","0.4279"
"","15.0200","126.7424","0.4277"
"","15.0400","126.9117","0.4278"
"","15.0600","127.0811","0.4280"
"","15.0800","127.2505","0.4280"
"","15.1000","127.4198","0.4280"
"","15.1200","127.5891","0.4281"
"","15.1400","127.7584","0.4280"
"","15.1600","127.9277","0.4281"
"","15.1800","128.0971","0.4283"
"","15.2000","128.2665","0.4281"
"","15.2200","128.4357","0.4282"
"","15.2400","128.6049","0.4282"
"","15.2600","128.7741","0.4281"
"","15.2800","128.9433","0.4283"
"","15.3000","129.1127","0.4284"
"","15.3200","129.2823","0.4284"
"","15.3400","129.4516","0.4284"
"","15.3600","129.6209","0.4286"
"","15.3800","129.7903","0.4286"
"","15.4000","129.9598","0.4287"
"","15.4200","130.1292","0.4287"
"","15.4400","130.2985","0.4287"
"","15.4600","130.4680","0.4288"
"","15.4800","130.6374","0.4288"
"","15.5000","130.8067","0.4287"
"","15.5200","130.9759","0.4288"
"","15.5400","131.1451","0.4287"
"","15.5600","131.3143","0.4289"
"","15.5800","131.4835","0.4291"
"","15.6000","131.6529","0.4288"
"","15.6200","131.8223","0.4288"
"","15.6400","131.9918","0.4290"
"","15.6600","132.1611","0.4291"
"","15.6800","132.3304","0.4291"
"","15.7000","132.4996","0.4292"
"","15.7200","132.6689","0.4293"
"","15.7400","132.8383","0.4292"
"","15.7600","133.0076","0.4291"
"","15.7800","133.1770","0.4290"
"","15.8000","133.3465","0.4291"
"","15.8200","133.5160","0.4293"
"","15.8400","133.6852","0.4294"
"","15.8600","133.8543","0.4296"
"","15.8800","134.0236","0.4294"
"","15.9000","134.1930","0.4292"
"","15.9200","134.3623","0.4292"
"","15.9400","134.5317","0.4294"
"","15.9600","134.7012","0.4296"
"","15.9800","134.8704","0.4296"
"","16.0000","135.0396","0.4295"
"","16.0200","135.2089","0.4294"
"","16.0400","135.3783","0.4295"
"","16.0600","135.5477","0.4296"
"","16.0800","135.7170","0.4296"
"","16.1000","135.8864","0.4296"
"","16.1200","136.0557","0.4296"
"","16.1400","136.2250","0.4297"
"","16.1600","136.3943","0.4297"
"","16.1800","136.5636","0.4298"
"","16.2000","136.7328","0.4297"
"","16.2200","136.9022","0.4298"
"","16.2400","137.0717","0.4299"
"","16.2600","137.2411","0.4300"
"","16.2800","137.4104","0.4299"
"","16.3000","137.5798","0.4300"
"","16.3200","137.7491","0.4299"
"","16.3400","137.9185","0.4298"
"","16.3600","138.0878","0.4299"
"","16.3800","138.2571","0.4299"
"","16.4000","138.4263","0.4299"
"","16.4200","138.5956","0.4301"
"","16.4400","138.7650","0.4301"
"","16.4600","138.9345","0.4301"
"","16.4800","139.1038","0.4303"
"","16.5000","139.2730","0.4303"
"","16.5200","139.4423","0.4301"
"","16.5400","139.6115","0.4301"
"","16.5600","139.7808","0.4302"
"","16.5800","139.9502","0.4302"
"","16.6000","140.1196","0.4302"
"","16.6200","140.2890","0.4302"
"","16.6400","140.4584","0.4301"
"","16.6600","140.6278","0.4302"
"","16.6800","140.7972","0.4303"
"","16.7000","140.9665","0.4304"
"","16.7200","141.1358","0.4304"
"","16.7400","141.3051","0.4305"
"","16.7600","141.4745","0.4305"
"","16.7800","141.6440","0.4305"
"","16.8000","141.8133","0.4305"
"","16.8200","141.9825","0.4305"
"","16.8400","142.1517","0.4305"
"","16.8600","142.3209","0.4305"
"","16.8800","142.4902","0.4307"
"","16.9000","142.6596","0.4306"
"","16.9200","142.8289","0.4303"
"","16.9400","142.9983","0.4307"
"","16.9600","143.1676","0.4308"
"","16.9800","143.3369","0.4306"
"","17.0000","143.5063","0.4306"
"","17.0200","143.6757","0.4307"
"","17.0400","143.8449","0.4307"
"","17.0600","144.0143","0.4306"
"","17.0800","144.1838","0.4306"
"","17.1000","144.3533","0.4308"
"","17.1200","144.5225","0.4309"
"","17.1400","144.6917","0.4308"
"","17.1600","144.8610","0.4308"
"","17.1800","145.0303","0.4308"
"","17.2000","145.1996","0.4308"
"","17.2200","145.3690","0.4309"
"","17.2400","145.5384","0.4312"
"","17.2600","145.7077","0.4311"
"","17.2800","145.8771","0.4312"
"","17.3000","146.0465","0.4312"
"","17.3200","146.2159","0.4311"
"","17.3400","146.3851","0.4311"
"","17.3600","146.5543","0.4313"
"","17.3800","146.7236","0.4313"
"","17.4000","146.8929","0.4314"
"","17.4200","147.0624","0.4312"
"","17.4400","147.2317","0.4311"
"","17.4600","147.4010","0.4313"
"","17.4800","147.5702","0.4313"
"","17.5000","147.7396","0.4313"
"","17.5200","147.9089","0.4314"
"","17.5400","148.0782","0.4314"
"","17.5600","148.2476","0.4315"
"","17.5800","148.4171","0.4316"
"","17.6000","148.5865","0.4315"
"","17.6200","148.7558","0.4313"
"","17.6400","148.9251","0.4314"
"","17.6600","149.0944","0.4315"
"","17.6800","149.2636","0.4316"
"","17.7000","149.4329","0.4316"
"","17.7200","149.6024","0.4316"
"","17.7400","149.7719","0.4314"
"","17.7600","149.9412","0.4314"
"","17.7800","150.1104","0.4315"
"","17.8000","150.2797","0.4316"
"","17.8200","150.4489","0.4318"
"","17.8400","150.6182","0.4318"
"","17.8600","150.7875","0.4319"
"","17.8800","150.9569","0.4317"
"","17.9000","151.1263","0.4318"
"","17.9200","151.2958","0.4321"
"","17.9400","151.4653","0.4319"
"","17.9600","151.6346","0.4318"
"","17.9800","151.8038","0.4319"
"","18.0000","151.9731","0.4320"
"","18.0200","152.1424","0.4320"
"","18.0400","152.3118","0.4319"
"","18.0600","152.4812","0.4320"
"","18.0800","152.6505","0.4320"
"","18.1000","152.8197","0.4318"
"","18.1200","152.9890","0.4318"
"","18.1400","153.1583","0.4320"
"","18.1600","153.3276","0.4321"
"","18.1800","153.4969","0.4320"
"","18.2000","153.6663","0.4320"
"","18.2200","153.8357","0.4317"
"","18.2400","154.0051","0.4320"
"","18.2600","154.1744","0.4321"
"","18.2800","154.3438","0.4321"
"","18.3000","154.5130","0.4321"
"","18.3200","154.6822","0.4322"
"","18.3400","154.8516","0.4321"
"","18.3600","155.0211","0.4323"
"","18.3800","155.1905","0.4324"
"","18.4000","155.3598","0.4323"
"","18.4200","155.5291","0.4324"
"","18.4400","155.6984","0.4323"
"","18.4600","155.8677","0.4322"
"","18.4800","156.0370","0.4322"
"","18.5000","156.2063","0.4324"
"","18.5200","156.3756","0.4323"
"","18.5400","156.5450","0.4324"
"","18.5600","156.7144","0.4325"
"","18.5800","156.8839","0.4325"
"","18.6000","157.0532","0.4325"
"","18.6200","157.2224","0.4324"
"","18.6400","157.3916","0.4322"
"","18.6600","157.5609","0.4324"
"","18.6800","157.7302","0.4325"
"","18.7000","157.8996","0.4325"
"","18.7200","158.0690","0.4326"
"","18.7400","158.2383","0.4325"
"","18.7600","158.4076","0.4327"
"","18.7800","158.5770","0.4328"
"","18.8000","158.7463","0.4327"
"","18.8200","158.9155","0.4328"
"","18.8400","159.0849","0.4327"
"","18.8600","159.2544","0.4327"
"","18.8800","159.4239","0.4328"
"","18.9000","159.5933","0.4328"
"","18.9200","159.7625","0.4327"
"","18.9400","159.9318","0.4328"
"","18.9600","160.1009","0.4328"
"","18.9800","160.2702","0.4326"
"","19.0000","160.4397","0.4327"
"","19.0200","160.6091","0.4331"
"","19.0400","160.7785","0.4329"
"","19.0600","160.9478","0.4329"
"","19.0800","161.1171","0.4329"
"","19.1000","161.2863","0.4328"
"","19.1200","161.4556","0.4327"
"","19.1400","161.6249","0.4327"
"","19.1600","161.7942","0.4328"
"","19.1800","161.9636","0.4330"
"","19.2000","162.1332","0.4328"
"","19.2200","162.3026","0.4328"
"","19.2400","162.4719","0.4329"
"","19.2600","162.6411","0.4328"
"","19.2800","162.8104","0.4329"
"","19.3000","162.9796","0.4332"
"","19.3200","163.1489","0.4331"
"","19.3400","163.3183","0.4331"
"","19.3600","163.4877","0.4331"
"","19.3800","163.6571","0.4330"
"","19.4000","163.8263","0.4329"
"","19.4200","163.9956","0.4330"
"","19.4400","164.1649","0.4330"
"","19.4600","164.3342","0.4330"
"","19.4800","164.5035","0.4332"
"","19.5000","164.6730","0.4333"
"","19.5200","164.8425","0.4333"
"","19.5400","165.0119","0.4333"
"","19.5600","165.1812","0.4332"
"","19.5800","165.3504","0.4332"
"","19.6000","165.5195","0.4332"
"","19.6200","165.6889","0.4332"
"","19.6400","165.8584","0.4331"
"","19.6600","166.0278","0.4330"
"","19.6800","166.1972","0.4333"
"","19.7000","166.3665","0.4337"
"","19.7200","166.5358","0.4337"
"","19.7400","166.7050","0.4334"
"","19.7600","166.8742","0.4334"
"","19.7800","167.0435","0.4333"
"","19.8000","167.2128","0.4334"
"","19.8200","167.3822","0.4335"
"","19.8400","167.5518","0.4335"
"","19.8600","167.7212","0.4337"
"","19.8800","167.8905","0.4337"
"","19.9000","168.0597","0.4335"
"","19.9200","168.2290","0.4337"
"","19.9400","168.3983","0.4337"
"","19.9600","168.5676","0.4335"
"","19.9800","168.7370","0.4336"
"","20.0000","168.9064","0.4336"
"","20.0200","169.0757","0.4335"
"","20.0400","169.2451","0.4337"
"","20.0600","169.4144","0.4337"
"","20.0800","169.5837","0.4336"
"","20.1000","169.7529","0.4337"
"","20.1200","169.9223","0.4338"
"","20.1400","170.0918","0.4337"
"","20.1600","170.2613","0.4336"
"","20.1800","170.4306","0.4335"
"","20.2000","170.5999","0.4337"
"","20.2200","170.7691","0.4337"
"","20.2400","170.9383","0.4336"
"","20.2600","171.1076","0.4337"
"","20.2800","171.2770","0.4338"
"","20.3000","171.4463","0.4337"
"","20.3200","171.6157","0.4337"
"","20.3400","171.7851","0.4336"
"","20.3600","171.9543","0.4338"
"","20.3800","172.1236","0.4340"
"","20.4000","172.2930","0.4339"
"","20.4200","172.4622","0.4338"
"","20.4400","172.6315","0.4338"
"","20.4600","172.8010","0.4338"
"","20.4800","172.9705","0.4338"
"","20.5000","173.1399","0.4339"
"","20.5200","173.3092","0.4339"
"","20.5400","173.4786","0.4338"
"","20.5600","173.6479","0.4340"
"","20.5800","173.8171","0.4340"
"","20.6000","173.9863","0.4340"
"","20.6200","174.1556","0.4338"
"","20.6400","174.3250","0.4340"
"","20.6600","174.4943","0.4339"
"","20.6800","174.6637","0.4339"
"","20.7000","174.8330","0.4338"
"","20.7200","175.0023","0.4340"
"","20.7400","175.1715","0.4340"
"","20.7600","175.3409","0.4340"
"","20.7800","175.5102","0.4341"
"","20.8000","175.6797","0.4342"
"","20.8200","175.8492","0.4344"
"","20.8400","176.0186","0.4343"
"","20.8600","176.1878","0.4341"
"","20.8800","176.3571","0.4340"
"","20.9000","176.5264","0.4342"
"","20.9200","176.6956","0.4342"
"","20.9400","176.8649","0.4342"
"","20.9600","177.0343","0.4342"
"","20.9800","177.2038","0.4342"
"","21.0000","177.3732","0.4341"
"","21.0200","177.5424","0.4341"
"","21.0400","177.7116","0.4341"
"","21.0600","177.8808","0.4341"
"","21.0800","178.0501","0.4342"
"","21.1000","178.2196","0.4342"
"","21.1200","178.3891","0.4342"
"","21.1400","178.5586","0.4343"
"","21.1600","178.7278","0.4344"
"","21.1800","178.8970","0.4345"
"","21.2000","179.0663","0.4343"
"","21.2200","179.2355","0.4345"
"","21.2400","179.4048","0.4345"
"","21.2600","179.5742","0.4343"
"","21.2800","179.7436","0.4344"
"","21.3000","179.9132","0.4345"
"","21.3200","180.0827","0.4342"
"","21.3400","180.2520","0.4344"
"","21.3600","180.4211","0.4345"
"","21.3800","180.5903","0.4345"
"","21.4000","180.7597","0.4347"
"","21.4200","180.9291","0.4347"
"","21.4400","181.0986","0.4347"
"","21.4600","181.2680","0.4347"
"","21.4800","181.4372","0.4347"
"","21.5000","181.6064","0.4347"
"","21.5200","181.7756","0.4348"
"","21.5400","181.9449","0.4346"
"","21.5600","182.1143","0.4345"
"","21.5800","182.2836","0.4347"
"","21.6000","182.4530","0.4347"
"","21.6200","182.6223","0.4348"
"","21.6400","182.7916","0.4349"
"","21.6600","182.9609","0.4348"
"","21.6800","183.1302","0.4347"
"","21.7000","183.2996","0.4347"
"","21.7200","183.4689","0.4346"
"","21.7400","183.6384","0.4347"
"","21.7600","183.8079","0.4348"
"","21.7800","183.9773","0.4347"
"","21.8000","184.1466","0.4349"
"","21.8200","184.3159","0.4349"
"","21.8400","184.4852","0.4346"
"","21.8600","184.6544","0.4347"
"","21.8800","184.8236","0.4348"
"","21.9000","184.9929","0.4349"
"","21.9200","185.1623","0.4348"
"","21.9400","185.3317","0.4349"
"","21.9600","185.5011","0.4349"
"","21.9800","185.6704","0.4348"
"","22.0000","185.8396","0.4350"
"","22.0200","186.0089","0.4352"
"","22.0400","186.1781","0.4351"
"","22.0600","186.3474","0.4350"
"","22.0800","186.5169","0.4351"
"","22.1000","186.6864","0.4351"
"","22.1200","186.8558","0.4349"
"","22.1400","187.0251","0.4351"
"","22.1600","187.1945","0.4352"
"","22.1800","187.3638","0.4351"
"","22.2000","187.5331","0.4350"
"","22.2200","187.7023","0.4349"
"","22.2400","187.8717","0.4349"
"","22.2600","188.0412","0.4351"
"","22.2800","188.2105","0.4351"
"","22.3000","188.3797","0.4350"
"","22.3200","188.5490","0.4351"
"","22.3400","188.7182","0.4350"
"","22.3600","188.8875","0.4351"
"","22.3800","189.0570","0.4351"
"","22.4000","189.2265","0.4351"
"","22.4200","189.3959","0.4351"
"","22.4400","189.5652","0.4353"
"","22.4600","189.7345","0.4352"
"","22.4800","189.9037","0.4352"
"","22.5000","190.0730","0.4352"
"","22.5200","190.2422","0.4352"
"","22.5400","190.4115","0.4352"
"","22.5600","190.5809","0.4351"
"","22.5800","190.7504","0.4352"
"","22.6000","190.9199","0.4354"
"","22.6200","191.0891","0.4355"
"","22.6400","191.2583","0.4354"
"","22.6600","191.4277","0.4355"
"","22.6800","191.5971","0.4355"
"","22.7000","191.7665","0.4355"
"","22.7200","191.9359","0.4354"
"","22.7400","192.1052","0.4353"
"","22.7600","192.2745","0.4353"
"","22.7800","192.4437","0.4353"
"","22.8000","192.6130","0.4354"
"","22.8200","192.7823","0.4355"
"","22.8400","192.9516","0.4355"
"","22.8600","193.1208","0.4355"
"","22.8800","193.2902","0.4355"
"","22.9000","193.4596","0.4357"
"","22.9200","193.6290","0.4355"
"","22.9400","193.7984","0.4356"
"","22.9600","193.9677","0.4357"
"","22.9800","194.1370","0.4356"
"","23.0000","194.3063","0.4356"
"","23.0200","194.4758","0.4357"
"","23.0400","194.6451","0.4356"
"","23.0600","194.8145","0.4358"
"","23.0800","194.9839","0.4358"
"","23.1000","195.1533","0.4357"
"","23.1200","195.3226","0.4357"
"","23.1400","195.4918","0.4357"
"","23.1600","195.6610","0.4355"
"","23.1800","195.8302","0.4355"
"","23.2000","195.9995","0.4356"
"","23.2200","196.1690","0.4356"
"","23.2400","196.3385","0.4358"
"","23.2600","196.5078","0.4358"
"","23.2800","196.6770","0.4359"
"","23.3000","196.8463","0.4359"
"","23.3200","197.0155","0.4359"
"","23.3400","197.1848","0.4359"
"","23.3600","197.3543","0.4357"
"","23.3800","197.5238","0.4357"
"","23.4000","197.6931","0.4357"
"","23.4200","197.8624","0.4357"
"","23.4400","198.0318","0.4358"
"","23.4600","198.2011","0.4358"
"","23.4800","198.3703","0.4356"
"","23.5000","198.5396","0.4355"
"","23.5200","198.7090","0.4355"
"","23.5400","198.8784","0.4356"
"","23.5600","199.0479","0.4357"
"","23.5800","199.2172","0.4357"
"","23.6000","199.3864","0.4357"
"","23.6200","199.5556","0.4357"
"","23.6400","199.7250","0.4357"
"","23.6600","199.8943","0.4357"
"","23.6800","200.0637","0.4358"
"","23.7000","200.2331","0.4358"
"","23.7200","200.4025","0.4358"
"","23.7400","200.5718","0.4358"
"","23.7600","200.7410","0.4358"
"","23.7800","200.9102","0.4358"
"","23.8000","201.0795","0.4357"
"","23.8200","201.2488","0.4356"
"","23.8400","201.4182","0.4356"
"","23.8600","201.5878","0.4357"
"","23.8800","201.7573","0.4357"
"","23.9000","201.9265","0.4357"
"","23.9200","202.0958","0.4355"
"","23.9400","202.2652","0.4356"
"","23.9600","202.4345","0.4358"
"","23.9800","202.6038","0.4360"
"","24.0000","202.7731","0.4360"
"","24.0200","202.9425","0.4357"
"","24.0400","203.1118","0.4356"
"","24.0600","203.2811","0.4356"
"","24.0800","203.4504","0.4356"
"","24.1000","203.6197","0.4357"
"","24.1200","203.7890","0.4357"
"","24.1400","203.9582","0.4356"
"","24.1600","204.1275","0.4358"
"","24.1800","204.2969","0.4356"
"","24.2000","204.4663","0.4355"
"","24.2200","204.6357","0.4356"
"","24.2400","204.8051","0.4356"
"","24.2600","204.9744","0.4356"
"","24.2800","205.1438","0.4357"
"","24.3000","205.3130","0.4355"
"","24.3200","205.4823","0.4356"
"","24.3400","205.6517","0.4355"
"","24.3600","205.8212","0.4353"
"","24.3800","205.9906","0.4354"
"","24.4000","206.1598","0.4355"
"","24.4200","206.3290","0.4354"
"","24.4400","206.4983","0.4352"
"","24.4600","206.6675","0.4351"
"","24.4800","206.8368","0.4349"
"","24.5000","207.0062","0.4349"
"","24.5200","207.1757","0.4347"
"","24.5400","207.3450","0.4345"
"","24.5600","207.5143","0.4343"
"","24.5800","207.6837","0.4335"
"","24.6000","207.8530","0.4320"
"","24.6200","208.0223","0.4221"
"","24.6400","208.1917","0.2258"
"","24.6600","208.3610","0.0452"
"","24.6800","208.5305","-0.0151"
"","24.7000","208.7000","-0.0160"
"","24.7200","208.8694","-0.0062"
"","24.7400","209.0386","-0.0009"
"","24.7600","209.2077","0.0000"
"","24.7800","209.3769","-0.0003"
"","24.8000","209.5463","-0.0007"
"","24.8200","209.7157","-0.0009"
"","24.8400","209.8851","-0.0009"
"","24.8600","210.0545","-0.0006"
"","24.8800","210.2238","-0.0007"
"","24.9000","210.3931","-0.0007"
"","24.9200","210.5624","-0.0007"
"","24.9400","210.7318","-0.0007"
"","24.9600","210.9010","-0.0006"
"","24.9800","211.0703","-0.0005"
"","25.0000","211.2398","-0.0005"
"","25.0200","211.4091","-0.0006"
"","25.0400","211.5784","-0.0008"
"","25.0600","211.7477","-0.0008"
"","25.0800","211.9169","-0.0006"
"","25.1000","212.0861","-0.0005"
"","25.1200","212.2555","-0.0004"
"","25.1400","212.4250","-0.0004"
"","25.1600","212.5945","-0.0009"
"","25.1660","212.6453","-0.0009"