File: Lab10/PC_S6_1.csv
Results Table 1
,Specimen label,Thickness,Width,Length,Rate 1
,,(mm),(mm),(mm),(mm/min)
"1","PC 1INPM","3.05","12.95","87.12","25.40"
"2","PC 5INPM","3.05","12.95","87.53","127.00"
"3","PC 20INPM","3.05","12.95","90.91","508.00"

Results Table 2


1,Time,Displacement,Force
,(s),(mm),(kN)
"","0.0000","0.0000","0.0468"
"","0.1400","0.0217","0.0673"
"","0.2800","0.0902","0.1322"
"","0.4200","0.1487","0.1861"
"","0.5600","0.2085","0.2401"
"","0.7000","0.2666","0.2919"
"","0.8400","0.3261","0.3441"
"","0.9800","0.3856","0.3950"
"","1.1200","0.4448","0.4443"
"","1.2600","0.5044","0.4929"
"","1.4000","0.5628","0.5405"
"","1.5400","0.6224","0.5889"
"","1.6800","0.6821","0.6371"
"","1.8200","0.7411","0.6838"
"","1.9600","0.8004","0.7302"
"","2.1000","0.8590","0.7754"
"","2.2400","0.9189","0.8214"
"","2.3800","0.9788","0.8662"
"","2.5200","1.0372","0.9095"
"","2.6600","1.0968","0.9529"
"","2.8000","1.1558","0.9953"
"","2.9400","1.2151","1.0374"
"","3.0800","1.2751","1.0797"
"","3.2200","1.3333","1.1197"
"","3.3600","1.3928","1.1599"
"","3.5000","1.4522","1.2001"
"","3.6400","1.5115","1.2390"
"","3.7800","1.5712","1.2780"
"","3.9200","1.6299","1.3153"
"","4.0600","1.6893","1.3529"
"","4.2000","1.7490","1.3900"
"","4.3400","1.8076","1.4251"
"","4.4800","1.8673","1.4605"
"","4.6200","1.9260","1.4951"
"","4.7600","1.9857","1.5293"
"","4.9000","2.0452","1.5631"
"","5.0400","2.1038","1.5953"
"","5.1800","2.1637","1.6279"
"","5.3200","2.2227","1.6593"
"","5.4600","2.2820","1.6901"
"","5.6000","2.3418","1.7204"
"","5.7400","2.4001","1.7495"
"","5.8800","2.4598","1.7788"
"","6.0200","2.5195","1.8075"
"","6.1600","2.5782","1.8348"
"","6.3000","2.6378","1.8621"
"","6.4400","2.6964","1.8881"
"","6.5800","2.7561","1.9144"
"","6.7200","2.8158","1.9401"
"","6.8600","2.8745","1.9643"
"","7.0000","2.9340","1.9886"
"","7.1400","2.9930","2.0120"
"","7.2800","3.0526","2.0354"
"","7.4200","3.1122","2.0577"
"","7.5600","3.1705","2.0792"
"","7.7000","3.2302","2.1007"
"","7.8400","3.2895","2.1216"
"","7.9800","3.3489","2.1424"
"","8.1200","3.4085","2.1623"
"","8.2600","3.4669","2.1810"
"","8.4000","3.5266","2.2005"
"","8.5400","3.5862","2.2189"
"","8.6800","3.6450","2.2368"
"","8.8200","3.7047","2.2543"
"","8.9600","3.7631","2.2709"
"","9.1000","3.8228","2.2879"
"","9.2400","3.8827","2.3044"
"","9.3800","3.9414","2.3200"
"","9.5200","4.0010","2.3352"
"","9.6600","4.0597","2.3500"
"","9.8000","4.1192","2.3645"
"","9.9400","4.1790","2.3786"
"","10.0800","4.2375","2.3918"
"","10.2200","4.2971","2.4050"
"","10.3600","4.3562","2.4179"
"","10.5000","4.4155","2.4301"
"","10.6400","4.4754","2.4427"
"","10.7800","4.5337","2.4534"
"","10.9200","4.5935","2.4647"
"","11.0600","4.6530","2.4754"
"","11.2000","4.7118","2.4853"
"","11.3400","4.7715","2.4955"
"","11.4800","4.8302","2.5045"
"","11.6200","4.8896","2.5134"
"","11.7600","4.9494","2.5222"
"","11.9000","5.0079","2.5300"
"","12.0400","5.0678","2.5380"
"","12.1800","5.1267","2.5453"
"","12.3200","5.1860","2.5520"
"","12.4600","5.2457","2.5588"
"","12.6000","5.3043","2.5646"
"","12.7400","5.3642","2.5703"
"","12.8800","5.4232","2.5759"
"","13.0200","5.4822","2.5805"
"","13.1600","5.5418","2.5854"
"","13.3000","5.6005","2.5894"
"","13.4400","5.6604","2.5933"
"","13.5800","5.7199","2.5969"
"","13.7200","5.7785","2.5996"
"","13.8600","5.8382","2.6022"
"","14.0000","5.8971","2.6043"
"","14.1400","5.9567","2.6063"
"","14.2800","6.0163","2.6078"
"","14.4200","6.0745","2.6086"
"","14.5600","6.1342","2.6096"
"","14.7000","6.1936","2.6105"
"","14.8400","6.2529","2.6101"
"","14.9800","6.3125","2.6101"
"","15.1200","6.3710","2.6093"
"","15.2600","6.4307","2.6086"
"","15.4000","6.4904","2.6073"
"","15.5400","6.5490","2.6053"
"","15.6800","6.6086","2.6037"
"","15.8200","6.6673","2.6012"
"","15.9600","6.7270","2.5989"
"","16.1000","6.7866","2.5964"
"","16.2400","6.8453","2.5927"
"","16.3800","6.9050","2.5896"
"","16.5200","6.9638","2.5857"
"","16.6600","7.0234","2.5817"
"","16.8000","7.0834","2.5779"
"","16.9400","7.1416","2.5728"
"","17.0800","7.2011","2.5681"
"","17.2200","7.2605","2.5629"
"","17.3600","7.3195","2.5573"
"","17.5000","7.3794","2.5519"
"","17.6400","7.4379","2.5452"
"","17.7800","7.4973","2.5384"
"","17.9200","7.5569","2.5318"
"","18.0600","7.6159","2.5234"
"","18.2000","7.6756","2.5150"
"","18.3400","7.7344","2.5045"
"","18.4800","7.7938","2.4921"
"","18.6200","7.8535","2.4766"
"","18.7600","7.9119","2.4517"
"","18.9000","7.9718","2.4051"
"","19.0400","8.0309","2.2959"
"","19.1800","8.0902","2.1643"
"","19.3200","8.1495","2.0944"
"","19.4600","8.2083","2.0579"
"","19.6000","8.2682","2.0376"
"","19.7400","8.3276","2.0250"
"","19.8800","8.3862","2.0166"
"","20.0200","8.4460","2.0117"
"","20.1600","8.5046","2.0080"
"","20.3000","8.5643","2.0055"
"","20.4400","8.6240","2.0035"
"","20.5800","8.6826","2.0015"
"","20.7200","8.7421","2.0007"
"","20.8600","8.8013","1.9993"
"","21.0000","8.8608","1.9981"
"","21.1400","8.9203","1.9972"
"","21.2800","8.9787","1.9956"
"","21.4200","9.0384","1.9947"
"","21.5600","9.0976","1.9936"
"","21.7000","9.1571","1.9927"
"","21.8400","9.2166","1.9916"
"","21.9800","9.2747","1.9896"
"","22.1200","9.3347","1.9893"
"","22.2600","9.3945","1.9886"
"","22.4000","9.4533","1.9873"
"","22.5400","9.5126","1.9864"
"","22.6800","9.5714","1.9851"
"","22.8200","9.6311","1.9845"
"","22.9600","9.6909","1.9840"
"","23.1000","9.7495","1.9830"
"","23.2400","9.8088","1.9823"
"","23.3800","9.8679","1.9817"
"","23.5200","9.9274","1.9815"
"","23.6600","9.9872","1.9816"
"","23.8000","10.0457","1.9809"
"","23.9400","10.1052","1.9808"
"","24.0800","10.1645","1.9812"
"","24.2200","10.2237","1.9808"
"","24.3600","10.2833","1.9814"
"","24.5000","10.3419","1.9812"
"","24.6400","10.4015","1.9815"
"","24.7800","10.4611","1.9824"
"","24.9200","10.5198","1.9824"
"","25.0600","10.5797","1.9830"
"","25.2000","10.6384","1.9833"
"","25.3400","10.6979","1.9836"
"","25.4800","10.7577","1.9845"
"","25.6200","10.8160","1.9842"
"","25.7600","10.8756","1.9849"
"","25.9000","10.9349","1.9855"
"","26.0400","10.9942","1.9856"
"","26.1800","11.0537","1.9863"
"","26.3200","11.1124","1.9860"
"","26.4600","11.1723","1.9867"
"","26.6000","11.2316","1.9868"
"","26.7400","11.2904","1.9864"
"","26.8800","11.3501","1.9871"
"","27.0200","11.4086","1.9864"
"","27.1600","11.4685","1.9872"
"","27.3000","11.5280","1.9874"
"","27.4400","11.5864","1.9870"
"","27.5800","11.6462","1.9875"
"","27.7200","11.7052","1.9877"
"","27.8600","11.7648","1.9879"
"","28.0000","11.8246","1.9882"
"","28.1400","11.8829","1.9875"
"","28.2800","11.9425","1.9882"
"","28.4200","12.0017","1.9882"
"","28.5600","12.0610","1.9880"
"","28.7000","12.1207","1.9887"
"","28.8400","12.1791","1.9878"
"","28.9800","12.2384","1.9879"
"","29.1200","12.2985","1.9885"
"","29.2600","12.3574","1.9883"
"","29.4000","12.4169","1.9888"
"","29.5400","12.4755","1.9882"
"","29.6800","12.5352","1.9887"
"","29.8200","12.5949","1.9888"
"","29.9600","12.6534","1.9889"
"","30.1000","12.7130","1.9891"
"","30.2400","12.7720","1.9890"
"","30.3800","12.8315","1.9892"
"","30.5200","12.8913","1.9900"
"","30.6600","12.9497","1.9893"
"","30.8000","13.0093","1.9896"
"","30.9400","13.0687","1.9898"
"","31.0800","13.1278","1.9895"
"","31.2200","13.1876","1.9900"
"","31.3600","13.2459","1.9891"
"","31.5000","13.3056","1.9891"
"","31.6400","13.3652","1.9895"
"","31.7800","13.4239","1.9892"
"","31.9200","13.4837","1.9895"
"","32.0600","13.5426","1.9892"
"","32.2000","13.6017","1.9889"
"","32.3400","13.6617","1.9893"
"","32.4800","13.7202","1.9890"
"","32.6200","13.7799","1.9893"
"","32.7600","13.8389","1.9892"
"","32.9000","13.8983","1.9891"
"","33.0400","13.9580","1.9894"
"","33.1800","14.0163","1.9887"
"","33.3200","14.0763","1.9894"
"","33.4600","14.1357","1.9891"
"","33.6000","14.1945","1.9890"
"","33.7400","14.2542","1.9894"
"","33.8800","14.3130","1.9892"
"","34.0200","14.3724","1.9890"
"","34.1600","14.4323","1.9898"
"","34.3000","14.4907","1.9891"
"","34.4400","14.5502","1.9895"
"","34.5800","14.6092","1.9891"
"","34.7200","14.6689","1.9893"
"","34.8600","14.7284","1.9894"
"","35.0000","14.7870","1.9889"
"","35.1400","14.8467","1.9892"
"","35.2800","14.9060","1.9890"
"","35.4200","14.9648","1.9884"
"","35.5600","15.0248","1.9889"
"","35.7000","15.0831","1.9879"
"","35.8400","15.1427","1.9882"
"","35.9800","15.2025","1.9886"
"","36.1200","15.2613","1.9879"
"","36.2600","15.3210","1.9882"
"","36.4000","15.3795","1.9876"
"","36.5400","15.4392","1.9876"
"","36.6800","15.4992","1.9882"
"","36.8200","15.5575","1.9872"
"","36.9600","15.6171","1.9874"
"","37.1000","15.6760","1.9873"
"","37.2400","15.7355","1.9875"
"","37.3800","15.7953","1.9877"
"","37.5200","15.8538","1.9873"
"","37.6600","15.9134","1.9875"
"","37.8000","15.9727","1.9878"
"","37.9400","16.0319","1.9876"
"","38.0800","16.0916","1.9882"
"","38.2200","16.1500","1.9880"
"","38.3600","16.2098","1.9883"
"","38.5000","16.2693","1.9890"
"","38.6400","16.3276","1.9883"
"","38.7800","16.3878","1.9893"
"","38.9200","16.4466","1.9893"
"","39.0600","16.5059","1.9894"
"","39.2000","16.5658","1.9901"
"","39.3400","16.6243","1.9895"
"","39.4800","16.6840","1.9903"
"","39.6200","16.7431","1.9902"
"","39.7600","16.8024","1.9903"
"","39.9000","16.8620","1.9906"
"","40.0400","16.9204","1.9902"
"","40.1800","16.9802","1.9912"
"","40.3200","17.0396","1.9911"
"","40.4600","17.0985","1.9912"
"","40.6000","17.1582","1.9916"
"","40.7400","17.2169","1.9917"
"","40.8800","17.2766","1.9921"
"","41.0200","17.3363","1.9928"
"","41.1600","17.3947","1.9924"
"","41.3000","17.4543","1.9930"
"","41.4400","17.5134","1.9931"
"","41.5800","17.5729","1.9932"
"","41.7200","17.6327","1.9939"
"","41.8600","17.6907","1.9931"
"","42.0000","17.7506","1.9939"
"","42.1400","17.8102","1.9943"
"","42.2800","17.8692","1.9942"
"","42.4200","17.9288","1.9948"
"","42.5600","17.9870","1.9944"
"","42.7000","18.0470","1.9951"
"","42.8400","18.1064","1.9957"
"","42.9800","18.1655","1.9957"
"","43.1200","18.2250","1.9961"
"","43.2600","18.2836","1.9957"
"","43.4000","18.3433","1.9962"
"","43.5400","18.4032","1.9968"
"","43.6800","18.4615","1.9961"
"","43.8200","18.5213","1.9964"
"","43.9600","18.5801","1.9968"
"","44.1000","18.6395","1.9970"
"","44.2400","18.6993","1.9975"
"","44.3800","18.7579","1.9973"
"","44.5200","18.8174","1.9977"
"","44.6600","18.8767","1.9984"
"","44.8000","18.9360","1.9982"
"","44.9400","18.9957","1.9991"
"","45.0800","19.0540","1.9986"
"","45.2200","19.1138","1.9992"
"","45.3600","19.1733","1.9994"
"","45.5000","19.2320","1.9994"
"","45.6400","19.2918","1.9997"
"","45.7800","19.3506","1.9997"
"","45.9200","19.4101","1.9999"
"","46.0600","19.4697","2.0003"
"","46.2000","19.5283","2.0002"
"","46.3400","19.5882","2.0009"
"","46.4800","19.6472","2.0009"
"","46.6200","19.7063","2.0011"
"","46.7600","19.7661","2.0017"
"","46.9000","19.8244","2.0011"
"","47.0400","19.8843","2.0018"
"","47.1800","19.9437","2.0022"
"","47.3200","20.0025","2.0022"
"","47.4600","20.0622","2.0024"
"","47.6000","20.1210","2.0029"
"","47.7400","20.1807","2.0032"
"","47.8800","20.2404","2.0039"
"","48.0200","20.2990","2.0034"
"","48.1600","20.3585","2.0035"
"","48.3000","20.4172","2.0031"
"","48.4400","20.4771","2.0040"
"","48.5800","20.5368","2.0046"
"","48.7200","20.5948","2.0039"
"","48.8600","20.6547","2.0044"
"","49.0000","20.7140","2.0048"
"","49.1400","20.7734","2.0050"
"","49.2800","20.8330","2.0054"
"","49.4200","20.8912","2.0049"
"","49.5600","20.9510","2.0056"
"","49.7000","21.0105","2.0060"
"","49.8400","21.0694","2.0059"
"","49.9800","21.1291","2.0066"
"","50.1200","21.1876","2.0060"
"","50.2600","21.2473","2.0067"
"","50.4000","21.3070","2.0073"
"","50.5400","21.3657","2.0067"
"","50.6800","21.4254","2.0070"
"","50.8200","21.4844","2.0070"
"","50.9600","21.5436","2.0069"
"","51.1000","21.6035","2.0074"
"","51.2400","21.6619","2.0069"
"","51.3800","21.7216","2.0072"
"","51.5200","21.7806","2.0073"
"","51.6600","21.8399","2.0074"
"","51.8000","21.8999","2.0080"
"","51.9400","21.9580","2.0072"
"","52.0800","22.0180","2.0078"
"","52.2200","22.0775","2.0082"
"","52.3600","22.1361","2.0075"
"","52.5000","22.1958","2.0084"
"","52.6400","22.2547","2.0083"
"","52.7800","22.3140","2.0086"
"","52.9200","22.3738","2.0092"
"","53.0600","22.4322","2.0088"
"","53.2000","22.4921","2.0092"
"","53.3400","22.5512","2.0094"
"","53.4800","22.6106","2.0094"
"","53.6200","22.6701","2.0096"
"","53.7600","22.7285","2.0085"
"","53.9000","22.7885","2.0095"
"","54.0400","22.8478","2.0091"
"","54.1800","22.9067","2.0088"
"","54.3200","22.9662","2.0097"
"","54.4600","23.0250","2.0094"
"","54.6000","23.0849","2.0100"
"","54.7400","23.1445","2.0100"
"","54.8800","23.2028","2.0099"
"","55.0200","23.2626","2.0101"
"","55.1600","23.3213","2.0101"
"","55.3000","23.3811","2.0105"
"","55.4400","23.4407","2.0112"
"","55.5800","23.4991","2.0105"
"","55.7200","23.5584","2.0110"
"","55.8600","23.6182","2.0116"
"","56.0000","23.6774","2.0116"
"","56.1400","23.7370","2.0116"
"","56.2800","23.7953","2.0112"
"","56.4200","23.8551","2.0120"
"","56.5600","23.9146","2.0117"
"","56.7000","23.9737","2.0123"
"","56.8400","24.0331","2.0120"
"","56.9800","24.0915","2.0116"
"","57.1200","24.1514","2.0125"
"","57.2600","24.2112","2.0130"
"","57.4000","24.2697","2.0122"
"","57.5400","24.3293","2.0128"
"","57.6800","24.3884","2.0123"
"","57.8200","24.4478","2.0125"
"","57.9600","24.5076","2.0128"
"","58.1000","24.5660","2.0124"
"","58.2400","24.6255","2.0126"
"","58.3800","24.6848","2.0128"
"","58.5200","24.7440","2.0129"
"","58.6600","24.8036","2.0129"
"","58.8000","24.8624","2.0128"
"","58.9400","24.9218","2.0130"
"","59.0800","24.9816","2.0132"
"","59.2200","25.0403","2.0128"
"","59.3600","25.1000","2.0131"
"","59.5000","25.1584","2.0126"
"","59.6400","25.2183","2.0132"
"","59.7800","25.2778","2.0133"
"","59.9200","25.3363","2.0130"
"","60.0600","25.3961","2.0138"
"","60.2000","25.4552","2.0136"
"","60.3400","25.5146","2.0135"
"","60.4800","25.5743","2.0142"
"","60.6200","25.6326","2.0136"
"","60.7600","25.6924","2.0141"
"","60.9000","25.7520","2.0143"
"","61.0400","25.8108","2.0141"
"","61.1800","25.8703","2.0145"
"","61.3200","25.9289","2.0144"
"","61.4600","25.9889","2.0146"
"","61.6000","26.0482","2.0152"
"","61.7400","26.1070","2.0147"
"","61.8800","26.1666","2.0152"
"","62.0200","26.2256","2.0151"
"","62.1600","26.2852","2.0153"
"","62.3000","26.3448","2.0154"
"","62.4400","26.4030","2.0147"
"","62.5800","26.4628","2.0152"
"","62.7200","26.5220","2.0151"
"","62.8600","26.5815","2.0153"
"","63.0000","26.6410","2.0156"
"","63.1400","26.6993","2.0153"
"","63.2800","26.7592","2.0153"
"","63.4200","26.8189","2.0159"
"","63.5600","26.8777","2.0158"
"","63.7000","26.9372","2.0158"
"","63.8400","26.9958","2.0156"
"","63.9800","27.0552","2.0158"
"","64.1200","27.1153","2.0167"
"","64.2600","27.1739","2.0162"
"","64.4000","27.2334","2.0163"
"","64.5400","27.2922","2.0160"
"","64.6800","27.3520","2.0164"
"","64.8200","27.4116","2.0165"
"","64.9600","27.4701","2.0160"
"","65.1000","27.5297","2.0164"
"","65.2400","27.5889","2.0164"
"","65.3800","27.6480","2.0162"
"","65.5200","27.7080","2.0168"
"","65.6600","27.7662","2.0161"
"","65.8000","27.8259","2.0164"
"","65.9400","27.8855","2.0170"
"","66.0800","27.9443","2.0166"
"","66.2200","28.0041","2.0173"
"","66.3600","28.0628","2.0167"
"","66.5000","28.1222","2.0171"
"","66.6400","28.1818","2.0175"
"","66.7800","28.2405","2.0172"
"","66.9200","28.3003","2.0176"
"","67.0600","28.3593","2.0175"
"","67.2000","28.4185","2.0173"
"","67.3400","28.4781","2.0177"
"","67.4800","28.5367","2.0174"
"","67.6200","28.5969","2.0181"
"","67.7600","28.6558","2.0180"
"","67.9000","28.7148","2.0180"
"","68.0400","28.7744","2.0185"
"","68.1800","28.8330","2.0183"
"","68.3200","28.8929","2.0186"
"","68.4600","28.9525","2.0188"
"","68.6000","29.0107","2.0186"
"","68.7400","29.0707","2.0194"
"","68.8800","29.1297","2.0195"
"","69.0200","29.1892","2.0196"
"","69.1600","29.2489","2.0201"
"","69.3000","29.3072","2.0194"
"","69.4400","29.3667","2.0199"
"","69.5800","29.4261","2.0202"
"","69.7200","29.4855","2.0205"
"","69.8600","29.5449","2.0205"
"","70.0000","29.6034","2.0204"
"","70.1400","29.6632","2.0209"
"","70.2800","29.7228","2.0212"
"","70.4200","29.7817","2.0206"
"","70.5600","29.8414","2.0212"
"","70.7000","29.8997","2.0208"
"","70.8400","29.9597","2.0212"
"","70.9800","30.0191","2.0215"
"","71.1200","30.0778","2.0211"
"","71.2600","30.1373","2.0214"
"","71.4000","30.1964","2.0218"
"","71.5400","30.2559","2.0217"
"","71.6800","30.3159","2.0223"
"","71.8200","30.3741","2.0216"
"","71.9600","30.4336","2.0221"
"","72.1000","30.4931","2.0224"
"","72.2400","30.5521","2.0223"
"","72.3800","30.6118","2.0226"
"","72.5200","30.6704","2.0226"
"","72.6600","30.7299","2.0230"
"","72.8000","30.7895","2.0231"
"","72.9400","30.8483","2.0231"
"","73.0800","30.9081","2.0233"
"","73.2200","30.9669","2.0231"
"","73.3600","31.0265","2.0231"
"","73.5000","31.0860","2.0231"
"","73.6400","31.1444","2.0228"
"","73.7800","31.2043","2.0231"
"","73.9200","31.2634","2.0232"
"","74.0600","31.3227","2.0231"
"","74.2000","31.3820","2.0235"
"","74.3400","31.4408","2.0232"
"","74.4800","31.5006","2.0235"
"","74.6200","31.5603","2.0237"
"","74.7600","31.6189","2.0236"
"","74.9000","31.6785","2.0236"
"","75.0400","31.7371","2.0231"
"","75.1800","31.7970","2.0235"
"","75.3200","31.8566","2.0238"
"","75.4600","31.9150","2.0235"
"","75.6000","31.9745","2.0237"
"","75.7400","32.0338","2.0239"
"","75.8800","32.0934","2.0243"
"","76.0200","32.1530","2.0243"
"","76.1600","32.2112","2.0235"
"","76.3000","32.2710","2.0243"
"","76.4400","32.3301","2.0240"
"","76.5800","32.3897","2.0242"
"","76.7200","32.4491","2.0243"
"","76.8600","32.5074","2.0237"
"","77.0000","32.5672","2.0241"
"","77.1400","32.6270","2.0245"
"","77.2800","32.6859","2.0242"
"","77.4200","32.7451","2.0240"
"","77.5600","32.8039","2.0235"
"","77.7000","32.8637","2.0236"
"","77.8400","32.9233","2.0238"
"","77.9800","32.9820","2.0233"
"","78.1200","33.0414","2.0237"
"","78.2600","33.1004","2.0234"
"","78.4000","33.1600","2.0234"
"","78.5400","33.2198","2.0238"
"","78.6800","33.2782","2.0232"
"","78.8200","33.3378","2.0232"
"","78.9600","33.3971","2.0230"
"","79.1000","33.4563","2.0230"
"","79.2400","33.5158","2.0233"
"","79.3800","33.5744","2.0226"
"","79.5200","33.6341","2.0230"
"","79.6600","33.6936","2.0232"
"","79.8000","33.7524","2.0230"
"","79.9400","33.8122","2.0235"
"","80.0800","33.8708","2.0231"
"","80.2200","33.9305","2.0231"
"","80.3600","33.9902","2.0235"
"","80.5000","34.0487","2.0230"
"","80.6400","34.1080","2.0230"
"","80.7800","34.1675","2.0233"
"","80.9200","34.2267","2.0231"
"","81.0600","34.2864","2.0234"
"","81.2000","34.3448","2.0227"
"","81.3400","34.4047","2.0233"
"","81.4800","34.4641","2.0231"
"","81.6200","34.5230","2.0230"
"","81.7600","34.5827","2.0234"
"","81.9000","34.6413","2.0229"
"","82.0400","34.7010","2.0233"
"","82.1800","34.7606","2.0233"
"","82.3200","34.8191","2.0230"
"","82.4600","34.8788","2.0230"
"","82.6000","34.9377","2.0229"
"","82.7400","34.9973","2.0229"
"","82.8800","35.0569","2.0231"
"","83.0200","35.1154","2.0226"
"","83.1600","35.1751","2.0227"
"","83.3000","35.2343","2.0229"
"","83.4400","35.2937","2.0230"
"","83.5800","35.3532","2.0232"
"","83.7200","35.4116","2.0227"
"","83.8600","35.4711","2.0232"
"","84.0000","35.5309","2.0239"
"","84.1400","35.5899","2.0238"
"","84.2800","35.6493","2.0240"
"","84.4200","35.7079","2.0239"
"","84.5600","35.7680","2.0245"
"","84.7000","35.8276","2.0249"
"","84.8400","35.8859","2.0247"
"","84.9800","35.9456","2.0250"
"","85.1200","36.0046","2.0250"
"","85.2600","36.0638","2.0248"
"","85.4000","36.1238","2.0259"
"","85.5400","36.1822","2.0251"
"","85.6800","36.2417","2.0254"
"","85.8200","36.3012","2.0253"
"","85.9600","36.3604","2.0253"
"","86.1000","36.4200","2.0253"
"","86.2400","36.4785","2.0248"
"","86.3800","36.5382","2.0249"
"","86.5200","36.5975","2.0250"
"","86.6600","36.6564","2.0246"
"","86.8000","36.7162","2.0250"
"","86.9400","36.7750","2.0247"
"","87.0800","36.8341","2.0248"
"","87.2200","36.8943","2.0255"
"","87.3600","36.9527","2.0249"
"","87.5000","37.0126","2.0252"
"","87.6400","37.0715","2.0251"
"","87.7800","37.1309","2.0251"
"","87.9200","37.1904","2.0254"
"","88.0600","37.2490","2.0249"
"","88.2000","37.3087","2.0253"
"","88.3400","37.3683","2.0257"
"","88.4800","37.4270","2.0251"
"","88.6200","37.4866","2.0253"
"","88.7600","37.5453","2.0251"
"","88.9000","37.6051","2.0256"
"","89.0400","37.6646","2.0254"
"","89.1800","37.7232","2.0250"
"","89.3200","37.7828","2.0254"
"","89.4600","37.8416","2.0250"
"","89.6000","37.9014","2.0255"
"","89.7400","37.9610","2.0257"
"","89.8800","38.0194","2.0251"
"","90.0200","38.0793","2.0255"
"","90.1600","38.1385","2.0254"
"","90.3000","38.1974","2.0250"
"","90.4400","38.2574","2.0254"
"","90.5800","38.3158","2.0248"
"","90.7200","38.3752","2.0250"
"","90.8600","38.4350","2.0253"
"","91.0000","38.4939","2.0251"
"","91.1400","38.5533","2.0255"
"","91.2800","38.6121","2.0254"
"","91.4200","38.6718","2.0259"
"","91.5600","38.7317","2.0263"
"","91.7000","38.7902","2.0262"
"","91.8400","38.8496","2.0262"
"","91.9800","38.9085","2.0264"
"","92.1200","38.9680","2.0265"
"","92.2600","39.0279","2.0271"
"","92.4000","39.0862","2.0260"
"","92.5400","39.1458","2.0264"
"","92.6800","39.2053","2.0269"
"","92.8200","39.2644","2.0268"
"","92.9600","39.3242","2.0271"
"","93.1000","39.3826","2.0266"
"","93.2400","39.4423","2.0269"
"","93.3800","39.5018","2.0272"
"","93.5200","39.5603","2.0270"
"","93.6600","39.6202","2.0275"
"","93.8000","39.6792","2.0276"
"","93.9400","39.7384","2.0275"
"","94.0800","39.7982","2.0280"
"","94.2200","39.8568","2.0277"
"","94.3600","39.9166","2.0282"
"","94.5000","39.9756","2.0277"
"","94.6400","40.0349","2.0281"
"","94.7800","40.0946","2.0283"
"","94.9200","40.1529","2.0279"
"","95.0600","40.2128","2.0286"
"","95.2000","40.2722","2.0287"
"","95.3400","40.3310","2.0287"
"","95.4800","40.3907","2.0288"
"","95.6200","40.4494","2.0284"
"","95.7600","40.5092","2.0289"
"","95.9000","40.5688","2.0292"
"","96.0400","40.6273","2.0286"
"","96.1800","40.6868","2.0291"
"","96.3200","40.7459","2.0291"
"","96.4600","40.8055","2.0291"
"","96.6000","40.8652","2.0298"
"","96.7400","40.9232","2.0291"
"","96.8800","40.9832","2.0296"
"","97.0200","41.0426","2.0300"
"","97.1600","41.1018","2.0300"
"","97.3000","41.1614","2.0303"
"","97.4400","41.2197","2.0300"
"","97.5800","41.2794","2.0303"
"","97.7200","41.3390","2.0310"
"","97.8600","41.3980","2.0308"
"","98.0000","41.4576","2.0312"
"","98.1400","41.5160","2.0308"
"","98.2800","41.5758","2.0311"
"","98.4200","41.6357","2.0318"
"","98.5600","41.6942","2.0312"
"","98.7000","41.7538","2.0314"
"","98.8400","41.8127","2.0309"
"","98.9800","41.8721","2.0309"
"","99.1200","41.9319","2.0313"
"","99.2600","41.9905","2.0308"
"","99.4000","42.0499","2.0309"
"","99.5400","42.1092","2.0311"
"","99.6800","42.1685","2.0314"
"","99.8200","42.2282","2.0314"
"","99.9600","42.2865","2.0313"
"","100.1000","42.3465","2.0316"
"","100.2400","42.4058","2.0316"
"","100.3800","42.4646","2.0316"
"","100.5200","42.5244","2.0319"
"","100.6600","42.5830","2.0315"
"","100.8000","42.6427","2.0317"
"","100.9400","42.7023","2.0325"
"","101.0800","42.7608","2.0320"
"","101.2200","42.8206","2.0323"
"","101.3600","42.8797","2.0323"
"","101.5000","42.9390","2.0324"
"","101.6400","42.9986","2.0326"
"","101.7800","43.0571","2.0319"
"","101.9200","43.1167","2.0322"
"","102.0600","43.1763","2.0324"
"","102.2000","43.2350","2.0321"
"","102.3400","43.2947","2.0325"
"","102.4800","43.3534","2.0317"
"","102.6200","43.4133","2.0322"
"","102.7600","43.4729","2.0325"
"","102.9000","43.5315","2.0322"
"","103.0400","43.5911","2.0323"
"","103.1800","43.6497","2.0323"
"","103.3200","43.7096","2.0325"
"","103.4600","43.7693","2.0327"
"","103.6000","43.8273","2.0320"
"","103.7400","43.8871","2.0325"
"","103.8800","43.9465","2.0327"
"","104.0200","44.0058","2.0328"
"","104.1600","44.0655","2.0331"
"","104.3000","44.1239","2.0324"
"","104.4400","44.1836","2.0324"
"","104.5800","44.2431","2.0325"
"","104.7200","44.3021","2.0325"
"","104.8600","44.3614","2.0326"
"","105.0000","44.4202","2.0321"
"","105.1400","44.4798","2.0324"
"","105.2800","44.5396","2.0329"
"","105.4200","44.5982","2.0323"
"","105.5600","44.6579","2.0325"
"","105.7000","44.7167","2.0322"
"","105.8400","44.7762","2.0327"
"","105.9800","44.8361","2.0328"
"","106.1200","44.8944","2.0322"
"","106.2600","44.9541","2.0325"
"","106.4000","45.0132","2.0326"
"","106.5400","45.0723","2.0330"
"","106.6800","45.1324","2.0334"
"","106.8200","45.1907","2.0326"
"","106.9600","45.2503","2.0328"
"","107.1000","45.3100","2.0331"
"","107.2400","45.3688","2.0327"
"","107.3800","45.4284","2.0328"
"","107.5200","45.4873","2.0326"
"","107.6600","45.5466","2.0324"
"","107.8000","45.6062","2.0328"
"","107.9400","45.6648","2.0324"
"","108.0800","45.7247","2.0328"
"","108.2200","45.7836","2.0329"
"","108.3600","45.8430","2.0326"
"","108.5000","45.9028","2.0330"
"","108.6400","45.9611","2.0324"
"","108.7800","46.0210","2.0326"
"","108.9200","46.0804","2.0325"
"","109.0600","46.1391","2.0323"
"","109.2000","46.1988","2.0326"
"","109.3400","46.2575","2.0322"
"","109.4800","46.3172","2.0327"
"","109.6200","46.3770","2.0331"
"","109.7600","46.4354","2.0326"
"","109.9000","46.4951","2.0332"
"","110.0400","46.5540","2.0330"
"","110.1800","46.6138","2.0334"
"","110.3200","46.6732","2.0338"
"","110.4600","46.7316","2.0335"
"","110.6000","46.7911","2.0337"
"","110.7400","46.8508","2.0340"
"","110.8800","46.9099","2.0339"
"","111.0200","46.9694","2.0342"
"","111.1600","47.0277","2.0336"
"","111.3000","47.0878","2.0341"
"","111.4400","47.1471","2.0341"
"","111.5800","47.2061","2.0339"
"","111.7200","47.2657","2.0339"
"","111.8600","47.3242","2.0338"
"","112.0000","47.3839","2.0339"
"","112.1400","47.4439","2.0344"
"","112.2800","47.5023","2.0338"
"","112.4200","47.5616","2.0340"
"","112.5600","47.6209","2.0338"
"","112.7000","47.6803","2.0341"
"","112.8400","47.7402","2.0344"
"","112.9800","47.7986","2.0334"
"","113.1200","47.8580","2.0337"
"","113.2600","47.9173","2.0338"
"","113.4000","47.9766","2.0336"
"","113.5400","48.0362","2.0337"
"","113.6800","48.0948","2.0333"
"","113.8200","48.1544","2.0334"
"","113.9600","48.2141","2.0336"
"","114.1000","48.2728","2.0332"
"","114.2400","48.3325","2.0336"
"","114.3800","48.3912","2.0328"
"","114.5200","48.4507","2.0331"
"","114.6600","48.5104","2.0331"
"","114.8000","48.5688","2.0327"
"","114.9400","48.6287","2.0331"
"","115.0800","48.6878","2.0329"
"","115.2200","48.7470","2.0329"
"","115.3600","48.8068","2.0333"
"","115.5000","48.8653","2.0327"
"","115.6400","48.9249","2.0326"
"","115.7800","48.9846","2.0331"
"","115.9200","49.0433","2.0327"
"","116.0600","49.1029","2.0329"
"","116.2000","49.1615","2.0323"
"","116.3400","49.2214","2.0329"
"","116.4800","49.2807","2.0331"
"","116.6200","49.3395","2.0326"
"","116.7600","49.3991","2.0327"
"","116.9000","49.4580","2.0326"
"","117.0400","49.5178","2.0325"
"","117.1800","49.5774","2.0326"
"","117.3200","49.6356","2.0319"
"","117.4600","49.6953","2.0322"
"","117.6000","49.7545","2.0320"
"","117.7400","49.8140","2.0322"
"","117.8800","49.8734","2.0323"
"","118.0200","49.9319","2.0317"
"","118.1600","49.9915","2.0321"
"","118.3000","50.0512","2.0326"
"","118.4400","50.1104","2.0324"
"","118.5800","50.1697","2.0324"
"","118.7200","50.2284","2.0320"
"","118.8600","50.2878","2.0321"
"","119.0000","50.3478","2.0326"
"","119.1400","50.4063","2.0321"
"","119.2800","50.4659","2.0320"
"","119.4200","50.5245","2.0317"
"","119.5600","50.5844","2.0318"
"","119.7000","50.6442","2.0320"
"","119.8400","50.7027","2.0315"
"","119.9800","50.7622","2.0317"
"","120.1200","50.8215","2.0315"
"","120.2600","50.8805","2.0313"
"","120.4000","50.9404","2.0319"
"","120.5400","50.9988","2.0311"
"","120.6800","51.0583","2.0311"
"","120.8200","51.1180","2.0316"
"","120.9600","51.1768","2.0315"
"","121.1000","51.2365","2.0315"
"","121.2400","51.2954","2.0313"
"","121.3800","51.3549","2.0313"
"","121.5200","51.4144","2.0313"
"","121.6600","51.4731","2.0310"
"","121.8000","51.5328","2.0312"
"","121.9400","51.5918","2.0312"
"","122.0800","51.6509","2.0312"
"","122.2200","51.7108","2.0313"
"","122.3600","51.7692","2.0312"
"","122.5000","51.8293","2.0317"
"","122.6400","51.8884","2.0315"
"","122.7800","51.9473","2.0314"
"","122.9200","52.0069","2.0315"
"","123.0600","52.0657","2.0315"
"","123.2000","52.1254","2.0316"
"","123.3400","52.1850","2.0320"
"","123.4800","52.2434","2.0318"
"","123.6200","52.3032","2.0320"
"","123.7600","52.3622","2.0321"
"","123.9000","52.4217","2.0320"
"","124.0400","52.4814","2.0322"
"","124.1800","52.5398","2.0318"
"","124.3200","52.5994","2.0319"
"","124.4600","52.6586","2.0320"
"","124.6000","52.7180","2.0319"
"","124.7400","52.7775","2.0320"
"","124.8800","52.8360","2.0317"
"","125.0200","52.8957","2.0320"
"","125.1600","52.9553","2.0321"
"","125.3000","53.0141","2.0320"
"","125.4400","53.0739","2.0322"
"","125.5800","53.1325","2.0315"
"","125.7200","53.1922","2.0316"
"","125.8600","53.2516","2.0319"
"","126.0000","53.3104","2.0313"
"","126.1400","53.3699","2.0312"
"","126.2800","53.4290","2.0311"
"","126.4200","53.4883","2.0310"
"","126.5600","53.5484","2.0315"
"","126.7000","53.6066","2.0310"
"","126.8400","53.6663","2.0308"
"","126.9800","53.7256","2.0309"
"","127.1200","53.7848","2.0307"
"","127.2600","53.8443","2.0306"
"","127.4000","53.9029","2.0301"
"","127.5400","53.9625","2.0305"
"","127.6800","54.0221","2.0308"
"","127.8200","54.0809","2.0304"
"","127.9600","54.1406","2.0311"
"","128.1000","54.1994","2.0306"
"","128.2400","54.2589","2.0307"
"","128.3800","54.3186","2.0311"
"","128.5200","54.3770","2.0304"
"","128.6600","54.4368","2.0306"
"","128.8000","54.4961","2.0306"
"","128.9400","54.5552","2.0305"
"","129.0800","54.6146","2.0308"
"","129.2200","54.6734","2.0303"
"","129.3600","54.7330","2.0303"
"","129.5000","54.7927","2.0306"
"","129.6400","54.8515","2.0302"
"","129.7800","54.9111","2.0305"
"","129.9200","54.9697","2.0298"
"","130.0600","55.0295","2.0301"
"","130.2000","55.0891","2.0302"
"","130.3400","55.1475","2.0296"
"","130.4800","55.2072","2.0300"
"","130.6200","55.2661","2.0298"
"","130.7600","55.3258","2.0300"
"","130.9000","55.3854","2.0299"
"","131.0400","55.4438","2.0299"
"","131.1800","55.5035","2.0299"
"","131.3200","55.5629","2.0301"
"","131.4600","55.6220","2.0299"
"","131.6000","55.6817","2.0299"
"","131.7400","55.7399","2.0295"
"","131.8800","55.7997","2.0299"
"","132.0200","55.8594","2.0302"
"","132.1600","55.9184","2.0300"
"","132.3000","55.9775","2.0296"
"","132.4400","56.0366","2.0297"
"","132.5800","56.0963","2.0295"
"","132.7200","56.1560","2.0298"
"","132.8600","56.2145","2.0291"
"","133.0000","56.2741","2.0293"
"","133.1400","56.3329","2.0290"
"","133.2800","56.3925","2.0288"
"","133.4200","56.4523","2.0291"
"","133.5600","56.5106","2.0283"
"","133.7000","56.5702","2.0285"
"","133.8400","56.6296","2.0285"
"","133.9800","56.6889","2.0285"
"","134.1200","56.7484","2.0284"
"","134.2600","56.8071","2.0280"
"","134.4000","56.8665","2.0276"
"","134.5400","56.9261","2.0278"
"","134.6800","56.9850","2.0273"
"","134.8200","57.0446","2.0276"
"","134.9600","57.1033","2.0270"
"","135.1000","57.1630","2.0271"
"","135.2400","57.2226","2.0272"
"","135.3800","57.2815","2.0268"
"","135.5200","57.3407","2.0268"
"","135.6600","57.4000","2.0267"
"","135.8000","57.4592","2.0266"
"","135.9400","57.5190","2.0268"
"","136.0800","57.5772","2.0262"
"","136.2200","57.6372","2.0265"
"","136.3600","57.6966","2.0268"
"","136.5000","57.7554","2.0263"
"","136.6400","57.8153","2.0267"
"","136.7800","57.8739","2.0260"
"","136.9200","57.9335","2.0261"
"","137.0600","57.9932","2.0263"
"","137.2000","58.0517","2.0260"
"","137.3400","58.1111","2.0261"
"","137.4800","58.1702","2.0262"
"","137.6200","58.2299","2.0261"
"","137.7600","58.2895","2.0261"
"","137.9000","58.3478","2.0255"
"","138.0400","58.4076","2.0255"
"","138.1800","58.4668","2.0253"
"","138.3200","58.5263","2.0251"
"","138.4600","58.5859","2.0252"
"","138.6000","58.6441","2.0244"
"","138.7400","58.7034","2.0243"
"","138.8800","58.7636","2.0248"
"","139.0200","58.8223","2.0244"
"","139.1600","58.8819","2.0242"
"","139.3000","58.9406","2.0241"
"","139.4400","59.0002","2.0244"
"","139.5800","59.0601","2.0244"
"","139.7200","59.1186","2.0239"
"","139.8600","59.1780","2.0239"
"","140.0000","59.2372","2.0241"
"","140.1400","59.2965","2.0239"
"","140.2800","59.3562","2.0241"
"","140.4200","59.4147","2.0236"
"","140.5600","59.4744","2.0238"
"","140.7000","59.5336","2.0234"
"","140.8400","59.5928","2.0237"
"","140.9800","59.6527","2.0238"
"","141.1200","59.7111","2.0231"
"","141.2600","59.7707","2.0233"
"","141.4000","59.8302","2.0236"
"","141.5400","59.8889","2.0234"
"","141.6800","59.9488","2.0238"
"","141.8200","60.0076","2.0234"
"","141.9600","60.0666","2.0236"
"","142.1000","60.1267","2.0239"
"","142.2400","60.1853","2.0237"
"","142.3800","60.2451","2.0239"
"","142.5200","60.3042","2.0239"
"","142.6600","60.3633","2.0237"
"","142.8000","60.4229","2.0241"
"","142.9400","60.4815","2.0238"
"","143.0800","60.5412","2.0242"
"","143.2200","60.6008","2.0246"
"","143.3600","60.6595","2.0240"
"","143.5000","60.7193","2.0245"
"","143.6400","60.7777","2.0243"
"","143.7800","60.8377","2.0250"
"","143.9200","60.8973","2.0250"
"","144.0600","60.9558","2.0247"
"","144.2000","61.0153","2.0249"
"","144.3400","61.0743","2.0251"
"","144.4800","61.1339","2.0252"
"","144.6200","61.1936","2.0257"
"","144.7600","61.2519","2.0255"
"","144.9000","61.3115","2.0260"
"","145.0400","61.3711","2.0264"
"","145.1800","61.4299","2.0264"
"","145.3200","61.4899","2.0269"
"","145.4600","61.5484","2.0270"
"","145.6000","61.6078","2.0272"
"","145.7400","61.6675","2.0278"
"","145.8800","61.7265","2.0278"
"","146.0200","61.7860","2.0281"
"","146.1600","61.8445","2.0283"
"","146.3000","61.9042","2.0287"
"","146.4400","61.9642","2.0297"
"","146.5800","62.0227","2.0296"
"","146.7200","62.0822","2.0297"
"","146.8600","62.1411","2.0300"
"","147.0000","62.2005","2.0300"
"","147.1400","62.2604","2.0311"
"","147.2800","62.3188","2.0309"
"","147.4200","62.3783","2.0318"
"","147.5600","62.4377","2.0320"
"","147.7000","62.4970","2.0324"
"","147.8400","62.5566","2.0328"
"","147.9800","62.6153","2.0330"
"","148.1200","62.6748","2.0335"
"","148.2600","62.7345","2.0343"
"","148.4000","62.7928","2.0342"
"","148.5400","62.8528","2.0351"
"","148.6800","62.9116","2.0351"
"","148.8200","62.9711","2.0355"
"","148.9600","63.0307","2.0362"
"","149.1000","63.0893","2.0362"
"","149.2400","63.1491","2.0371"
"","149.3800","63.2082","2.0375"
"","149.5200","63.2674","2.0377"
"","149.6600","63.3273","2.0385"
"","149.8000","63.3854","2.0383"
"","149.9400","63.4454","2.0390"
"","150.0800","63.5048","2.0394"
"","150.2200","63.5635","2.0395"
"","150.3600","63.6231","2.0402"
"","150.5000","63.6819","2.0403"
"","150.6400","63.7416","2.0409"
"","150.7800","63.8013","2.0417"
"","150.9200","63.8600","2.0417"
"","151.0600","63.9193","2.0422"
"","151.2000","63.9785","2.0425"
"","151.3400","64.0381","2.0433"
"","151.4800","64.0976","2.0436"
"","151.6200","64.1557","2.0436"
"","151.7600","64.2157","2.0442"
"","151.9000","64.2750","2.0446"
"","152.0400","64.3343","2.0453"
"","152.1800","64.3939","2.0460"
"","152.3200","64.4524","2.0454"
"","152.4600","64.5121","2.0460"
"","152.6000","64.5716","2.0468"
"","152.7400","64.6304","2.0466"
"","152.8800","64.6902","2.0471"
"","153.0200","64.7486","2.0470"
"","153.1600","64.8081","2.0477"
"","153.3000","64.8681","2.0483"
"","153.4400","64.9268","2.0483"
"","153.5800","64.9863","2.0488"
"","153.7200","65.0453","2.0490"
"","153.8600","65.1046","2.0492"
"","154.0000","65.1644","2.0500"
"","154.1400","65.2230","2.0498"
"","154.2800","65.2824","2.0503"
"","154.4200","65.3416","2.0505"
"","154.5600","65.4010","2.0511"
"","154.7000","65.4608","2.0514"
"","154.8400","65.5189","2.0510"
"","154.9800","65.5790","2.0522"
"","155.1200","65.6385","2.0528"
"","155.2600","65.6971","2.0526"
"","155.4000","65.7570","2.0532"
"","155.5400","65.8157","2.0532"
"","155.6800","65.8750","2.0536"
"","155.8200","65.9348","2.0545"
"","155.9600","65.9933","2.0544"
"","156.1000","66.0531","2.0551"
"","156.2400","66.1124","2.0552"
"","156.3800","66.1714","2.0553"
"","156.5200","66.2311","2.0558"
"","156.6600","66.2897","2.0556"
"","156.8000","66.3494","2.0559"
"","156.9400","66.4088","2.0565"
"","157.0800","66.4676","2.0559"
"","157.2200","66.5272","2.0562"
"","157.3600","66.5859","2.0563"
"","157.5000","66.6458","2.0565"
"","157.6400","66.7053","2.0568"
"","157.7800","66.7639","2.0562"
"","157.9200","66.8237","2.0565"
"","158.0600","66.8824","2.0564"
"","158.2000","66.9422","2.0567"
"","158.3400","67.0019","2.0568"
"","158.4800","67.0598","2.0564"
"","158.6200","67.1197","2.0572"
"","158.7600","67.1792","2.0574"
"","158.9000","67.2383","2.0578"
"","159.0400","67.2979","2.0589"
"","159.1800","67.3565","2.0591"
"","159.3200","67.4162","2.0599"
"","159.4600","67.4757","2.0609"
"","159.6000","67.5346","2.0615"
"","159.7400","67.5940","2.0625"
"","159.8800","67.6526","2.0634"
"","160.0200","67.7124","2.0645"
"","160.1600","67.7722","2.0661"
"","160.3000","67.8306","2.0668"
"","160.4400","67.8904","2.0685"
"","160.5800","67.9492","2.0698"
"","160.7200","68.0088","2.0714"
"","160.8600","68.0687","2.0729"
"","161.0000","68.1271","2.0741"
"","161.1400","68.1865","2.0757"
"","161.2800","68.2459","2.0774"
"","161.4200","68.3049","2.0790"
"","161.5600","68.3649","2.0813"
"","161.7000","68.4232","2.0823"
"","161.8400","68.4827","2.0844"
"","161.9800","68.5425","2.0865"
"","162.1200","68.6013","2.0881"
"","162.2600","68.6609","2.0900"
"","162.4000","68.7199","2.0918"
"","162.5400","68.7792","2.0936"
"","162.6800","68.8388","2.0955"
"","162.8200","68.8974","2.0972"
"","162.9600","68.9571","2.0991"
"","163.1000","69.0162","2.1007"
"","163.2400","69.0754","2.1026"
"","163.3800","69.1353","2.1050"
"","163.5200","69.1936","2.1065"
"","163.6600","69.2536","2.1081"
"","163.8000","69.3131","2.1100"
"","163.9400","69.3715","2.1115"
"","164.0800","69.4314","2.1135"
"","164.2200","69.4901","2.1153"
"","164.3600","69.5499","2.1174"
"","164.5000","69.6094","2.1198"
"","164.6400","69.6680","2.1213"
"","164.7800","69.7275","2.1236"
"","164.9200","69.7865","2.1255"
"","165.0600","69.8462","2.1276"
"","165.2000","69.9058","2.1297"
"","165.3400","69.9641","2.1316"
"","165.4800","70.0237","2.1340"
"","165.6200","70.0831","2.1359"
"","165.7600","70.1424","2.1382"
"","165.9000","70.2020","2.1402"
"","166.0400","70.2602","2.1418"
"","166.1800","70.3201","2.1446"
"","166.3200","70.3798","2.1465"
"","166.4600","70.4387","2.1484"
"","166.6000","70.4982","2.1503"
"","166.7400","70.5567","2.1521"
"","166.8800","70.6165","2.1547"
"","167.0200","70.6764","2.1568"
"","167.1600","70.7348","2.1582"
"","167.3000","70.7942","2.1605"
"","167.4400","70.8534","2.1628"
"","167.5800","70.9128","2.1650"
"","167.7200","70.9726","2.1674"
"","167.8600","71.0311","2.1692"
"","168.0000","71.0907","2.1715"
"","168.1400","71.1499","2.1740"
"","168.2800","71.2091","2.1758"
"","168.4200","71.2687","2.1783"
"","168.5600","71.3273","2.1803"
"","168.7000","71.3868","2.1827"
"","168.8400","71.4465","2.1852"
"","168.9800","71.5052","2.1872"
"","169.1200","71.5650","2.1899"
"","169.2600","71.6239","2.1921"
"","169.4000","71.6832","2.1939"
"","169.5400","71.7429","2.1965"
"","169.6800","71.8013","2.1981"
"","169.8200","71.8613","2.2007"
"","169.9600","71.9202","2.2025"
"","170.1000","71.9796","2.2048"
"","170.2400","72.0392","2.2074"
"","170.3800","72.0978","2.2096"
"","170.5200","72.1576","2.2119"
"","170.6600","72.2172","2.2144"
"","170.8000","72.2757","2.2162"
"","170.9400","72.3356","2.2187"
"","171.0800","72.3940","2.2205"
"","171.2200","72.4539","2.2233"
"","171.3600","72.5133","2.2257"
"","171.5000","72.5719","2.2279"
"","171.6400","72.6317","2.2303"
"","171.7800","72.6906","2.2327"
"","171.9200","72.7502","2.2351"
"","172.0600","72.8100","2.2374"
"","172.2000","72.8683","2.2390"
"","172.3400","72.9278","2.2413"
[...]
"","192.6400","81.5221","2.4273"
"","192.7800","81.5803","2.4283"
"","192.9200","81.6401","2.4297"
"","193.0600","81.6993","2.4307"
"","193.2000","81.7588","2.4321"
"","193.3400","81.8185","2.4338"
"","193.4800","81.8767","2.4340"
"","193.6200","81.9360","2.4355"
"","193.7600","81.9959","2.4373"
"","193.9000","82.0549","2.4380"
"","194.0400","82.1145","2.4395"
"","194.1800","82.1731","2.4406"
"","194.3200","82.2327","2.4418"
"","194.4600","82.2924","2.4432"
"","194.6000","82.3511","2.4443"
"","194.7400","82.4108","2.4459"
"","194.8800","82.4698","2.4469"
"","195.0200","82.5291","2.4482"
"","195.1600","82.5888","2.4496"
"","195.3000","82.6473","2.4504"
"","195.4400","82.7069","2.4517"
"","195.5800","82.7661","2.4529"
"","195.7200","82.8252","2.4538"
"","195.8600","82.8852","2.4556"
"","196.0000","82.9436","2.4560"
"","196.1400","83.0033","2.4575"
"","196.2800","83.0628","2.4585"
"","196.4200","83.1215","2.4595"
"","196.5600","83.1813","2.4607"
"","196.7000","83.2401","2.4617"
"","196.8400","83.2991","2.4628"
"","196.9800","83.3592","2.4642"
"","197.1200","83.4178","2.4650"
"","197.2600","83.4775","2.4664"
"","197.4000","83.5367","2.4676"
"","197.5400","83.5959","2.4687"
"","197.6800","83.6555","2.4697"
"","197.8200","83.7139","2.4705"
"","197.9600","83.7739","2.4718"
"","198.1000","83.8332","2.4732"
"","198.2400","83.8921","2.4739"
"","198.3800","83.9517","2.4751"
"","198.5200","84.0103","2.4761"
"","198.6600","84.0702","2.4774"
"","198.8000","84.1299","2.4787"
"","198.9400","84.1882","2.4793"
"","199.0800","84.2479","2.4806"
"","199.2200","84.3068","2.4813"
"","199.3600","84.3665","2.4827"
"","199.5000","84.4261","2.4837"
"","199.6400","84.4845","2.4846"
"","199.7800","84.5440","2.4856"
"","199.9200","84.6036","2.4868"
"","200.0600","84.6625","2.4873"
"","200.2000","84.7224","2.4888"
"","200.3400","84.7808","2.4894"
"","200.4800","84.8405","2.4904"
"","200.6200","84.9000","2.4918"
"","200.7600","84.9591","2.4925"
"","200.9000","85.0185","2.4934"
"","201.0400","85.0769","2.4939"
"","201.1800","85.1369","2.4952"
"","201.3200","85.1967","2.4964"
"","201.4600","85.2551","2.4968"
"","201.6000","85.3147","2.4980"
"","201.7400","85.3739","2.4987"
"","201.8800","85.4331","2.4994"
"","202.0200","85.4930","2.5005"
"","202.1600","85.5514","2.5008"
"","202.3000","85.6108","2.5020"
"","202.4400","85.6703","2.5027"
"","202.5800","85.7294","2.5034"
"","202.7200","85.7889","2.5041"
"","202.8600","85.8478","2.5047"
"","203.0000","85.9075","2.5057"
"","203.1400","85.9670","2.5063"
"","203.2800","86.0254","2.5054"
"","203.4200","86.0855","2.5038"
"","203.4640","86.1040","1.4711"
2,Time,Displacement,Force
,(s),(mm),(kN)
"","0.0000","0.0000","0.0414"
"","0.0200","0.0001","0.0417"
"","0.0400","0.0033","0.0446"
"","0.0600","0.0199","0.0611"
"","0.0800","0.0546","0.0956"
"","0.1000","0.0938","0.1340"
"","0.1200","0.1309","0.1700"
"","0.1400","0.1695","0.2070"
"","0.1600","0.2127","0.2476"
"","0.1800","0.2597","0.2915"
"","0.2000","0.3075","0.3352"
"","0.2200","0.3534","0.3767"
"","0.2400","0.3970","0.4158"
"","0.2600","0.4387","0.4529"
"","0.2800","0.4798","0.4895"
"","0.3000","0.5211","0.5255"
"","0.3200","0.5629","0.5617"
"","0.3400","0.6052","0.5982"
"","0.3600","0.6478","0.6342"
"","0.3800","0.6905","0.6700"
"","0.4000","0.7331","0.7050"
"","0.4200","0.7754","0.7389"
"","0.4400","0.8175","0.7723"
"","0.4600","0.8596","0.8056"
"","0.4800","0.9021","0.8391"
"","0.5000","0.9448","0.8722"
"","0.5200","0.9876","0.9052"
"","0.5400","1.0300","0.9379"
"","0.5600","1.0721","0.9698"
"","0.5800","1.1140","1.0016"
"","0.6000","1.1561","1.0332"
"","0.6200","1.1983","1.0645"
"","0.6400","1.2407","1.0956"
"","0.6600","1.2832","1.1265"
"","0.6800","1.3256","1.1569"
"","0.7000","1.3679","1.1869"
"","0.7200","1.4101","1.2164"
"","0.7400","1.4523","1.2459"
"","0.7600","1.4949","1.2751"
"","0.7800","1.5376","1.3040"
"","0.8000","1.5802","1.3324"
"","0.8200","1.6225","1.3604"
"","0.8400","1.6646","1.3884"
"","0.8600","1.7067","1.4156"
"","0.8800","1.7489","1.4425"
"","0.9000","1.7913","1.4692"
"","0.9200","1.8338","1.4957"
"","0.9400","1.8763","1.5220"
"","0.9600","1.9185","1.5477"
"","0.9800","1.9606","1.5728"
"","1.0000","2.0028","1.5976"
"","1.0200","2.0452","1.6224"
"","1.0400","2.0878","1.6470"
"","1.0600","2.1305","1.6710"
"","1.0800","2.1728","1.6948"
"","1.1000","2.2149","1.7180"
"","1.1200","2.2569","1.7408"
"","1.1400","2.2991","1.7634"
"","1.1600","2.3415","1.7855"
"","1.1800","2.3840","1.8076"
"","1.2000","2.4264","1.8295"
"","1.2200","2.4688","1.8507"
"","1.2400","2.5110","1.8716"
"","1.2600","2.5531","1.8921"
"","1.2800","2.5953","1.9125"
"","1.3000","2.6379","1.9326"
"","1.3200","2.6806","1.9524"
"","1.3400","2.7233","1.9721"
"","1.3600","2.7657","1.9909"
"","1.3800","2.8078","2.0094"
"","1.4000","2.8498","2.0276"
"","1.4200","2.8919","2.0455"
"","1.4400","2.9342","2.0635"
"","1.4600","2.9766","2.0809"
"","1.4800","3.0191","2.0982"
"","1.5000","3.0614","2.1152"
"","1.5200","3.1035","2.1316"
"","1.5400","3.1457","2.1480"
"","1.5600","3.1881","2.1640"
"","1.5800","3.2307","2.1799"
"","1.6000","3.2734","2.1954"
"","1.6200","3.3159","2.2106"
"","1.6400","3.3583","2.2255"
"","1.6600","3.4004","2.2398"
"","1.6800","3.4426","2.2541"
"","1.7000","3.4847","2.2683"
"","1.7200","3.5269","2.2820"
"","1.7400","3.5690","2.2955"
"","1.7600","3.6112","2.3088"
"","1.7800","3.6534","2.3220"
"","1.8000","3.6957","2.3347"
"","1.8200","3.7381","2.3474"
"","1.8400","3.7807","2.3599"
"","1.8600","3.8235","2.3721"
"","1.8800","3.8662","2.3841"
"","1.9000","3.9088","2.3957"
"","1.9200","3.9511","2.4069"
"","1.9400","3.9932","2.4181"
"","1.9600","4.0353","2.4290"
"","1.9800","4.0776","2.4396"
"","2.0000","4.1198","2.4503"
"","2.0200","4.1621","2.4602"
"","2.0400","4.2043","2.4702"
"","2.0600","4.2465","2.4798"
"","2.0800","4.2887","2.4893"
"","2.1000","4.3310","2.4987"
"","2.1200","4.3734","2.5078"
"","2.1400","4.4161","2.5172"
"","2.1600","4.4587","2.5262"
"","2.1800","4.5012","2.5345"
"","2.2000","4.5436","2.5425"
"","2.2200","4.5858","2.5502"
"","2.2400","4.6280","2.5580"
"","2.2600","4.6702","2.5657"
"","2.2800","4.7125","2.5730"
"","2.3000","4.7548","2.5802"
"","2.3200","4.7971","2.5869"
"","2.3400","4.8393","2.5938"
"","2.3600","4.8814","2.6003"
"","2.3800","4.9235","2.6065"
"","2.4000","4.9657","2.6126"
"","2.4200","5.0083","2.6183"
"","2.4400","5.0510","2.6242"
"","2.4600","5.0936","2.6301"
"","2.4800","5.1360","2.6354"
"","2.5000","5.1783","2.6404"
"","2.5200","5.2206","2.6451"
"","2.5400","5.2629","2.6498"
"","2.5600","5.3053","2.6544"
"","2.5800","5.3476","2.6587"
"","2.6000","5.3899","2.6629"
"","2.6200","5.4321","2.6666"
"","2.6400","5.4742","2.6703"
"","2.6600","5.5164","2.6736"
"","2.6800","5.5588","2.6769"
"","2.7000","5.6012","2.6803"
"","2.7200","5.6438","2.6832"
"","2.7400","5.6862","2.6861"
"","2.7600","5.7286","2.6885"
"","2.7800","5.7709","2.6908"
"","2.8000","5.8132","2.6931"
"","2.8200","5.8556","2.6950"
"","2.8400","5.8980","2.6968"
"","2.8600","5.9403","2.6983"
"","2.8800","5.9825","2.6994"
"","2.9000","6.0246","2.7008"
"","2.9200","6.0666","2.7016"
"","2.9400","6.1089","2.7026"
"","2.9600","6.1513","2.7034"
"","2.9800","6.1940","2.7040"
"","3.0000","6.2365","2.7045"
"","3.0200","6.2788","2.7045"
"","3.0400","6.3210","2.7044"
"","3.0600","6.3632","2.7041"
"","3.0800","6.4056","2.7038"
"","3.1000","6.4482","2.7036"
"","3.1200","6.4907","2.7028"
"","3.1400","6.5330","2.7018"
"","3.1600","6.5752","2.7006"
"","3.1800","6.6173","2.6993"
"","3.2000","6.6594","2.6979"
"","3.2200","6.7018","2.6963"
"","3.2400","6.7443","2.6945"
"","3.2600","6.7869","2.6927"
"","3.2800","6.8294","2.6901"
"","3.3000","6.8717","2.6876"
"","3.3200","6.9139","2.6848"
"","3.3400","6.9561","2.6819"
"","3.3600","6.9985","2.6788"
"","3.3800","7.0409","2.6754"
"","3.4000","7.0833","2.6717"
"","3.4200","7.1255","2.6673"
"","3.4400","7.1677","2.6626"
"","3.4600","7.2098","2.6576"
"","3.4800","7.2520","2.6518"
"","3.5000","7.2945","2.6454"
"","3.5200","7.3371","2.6379"
"","3.5400","7.3797","2.6283"
"","3.5600","7.4221","2.6156"
"","3.5800","7.4643","2.5983"
"","3.6000","7.5066","2.5722"
"","3.6200","7.5489","2.5283"
"","3.6400","7.5914","2.4568"
"","3.6600","7.6337","2.3656"
"","3.6800","7.6759","2.2816"
"","3.7000","7.7180","2.2219"
"","3.7200","7.7602","2.1838"
"","3.7400","7.8024","2.1599"
"","3.7600","7.8449","2.1438"
"","3.7800","7.8874","2.1318"
"","3.8000","7.9300","2.1226"
"","3.8200","7.9725","2.1155"
"","3.8400","8.0147","2.1097"
"","3.8600","8.0569","2.1050"
"","3.8800","8.0992","2.1014"
"","3.9000","8.1417","2.0985"
"","3.9200","8.1842","2.0961"
"","3.9400","8.2266","2.0940"
"","3.9600","8.2688","2.0923"
"","3.9800","8.3108","2.0906"
"","4.0000","8.3529","2.0891"
"","4.0200","8.3950","2.0876"
"","4.0400","8.4373","2.0867"
"","4.0600","8.4798","2.0860"
"","4.0800","8.5223","2.0851"
"","4.1000","8.5647","2.0843"
"","4.1200","8.6070","2.0834"
"","4.1400","8.6493","2.0822"
"","4.1600","8.6917","2.0814"
"","4.1800","8.7343","2.0807"
"","4.2000","8.7767","2.0801"
"","4.2200","8.8191","2.0790"
"","4.2400","8.8613","2.0781"
"","4.2600","8.9035","2.0773"
"","4.2800","8.9456","2.0763"
"","4.3000","8.9877","2.0754"
"","4.3200","9.0299","2.0746"
"","4.3400","9.0723","2.0741"
"","4.3600","9.1149","2.0736"
"","4.3800","9.1574","2.0730"
"","4.4000","9.1998","2.0727"
"","4.4200","9.2421","2.0719"
"","4.4400","9.2845","2.0713"
"","4.4600","9.3270","2.0708"
"","4.4800","9.3696","2.0705"
"","4.5000","9.4120","2.0702"
"","4.5200","9.4542","2.0696"
"","4.5400","9.4962","2.0689"
"","4.5600","9.5383","2.0682"
"","4.5800","9.5805","2.0678"
"","4.6000","9.6228","2.0677"
"","4.6200","9.6652","2.0678"
"","4.6400","9.7076","2.0680"
"","4.6600","9.7499","2.0681"
"","4.6800","9.7922","2.0678"
"","4.7000","9.8345","2.0676"
"","4.7200","9.8769","2.0676"
"","4.7400","9.9195","2.0678"
"","4.7600","9.9620","2.0681"
"","4.7800","10.0045","2.0684"
"","4.8000","10.0467","2.0685"
"","4.8200","10.0888","2.0686"
"","4.8400","10.1310","2.0686"
"","4.8600","10.1732","2.0689"
"","4.8800","10.2155","2.0693"
"","4.9000","10.2580","2.0700"
"","4.9200","10.3005","2.0704"
"","4.9400","10.3427","2.0707"
"","4.9600","10.3848","2.0710"
"","4.9800","10.4270","2.0713"
"","5.0000","10.4695","2.0719"
"","5.0200","10.5122","2.0725"
"","5.0400","10.5550","2.0730"
"","5.0600","10.5974","2.0736"
"","5.0800","10.6396","2.0737"
"","5.1000","10.6816","2.0740"
"","5.1200","10.7236","2.0742"
"","5.1400","10.7658","2.0745"
"","5.1600","10.8081","2.0751"
"","5.1800","10.8507","2.0756"
"","5.2000","10.8932","2.0761"
"","5.2200","10.9356","2.0767"
"","5.2400","10.9778","2.0768"
"","5.2600","11.0201","2.0770"
"","5.2800","11.0625","2.0774"
"","5.3000","11.1049","2.0780"
"","5.3200","11.1474","2.0786"
"","5.3400","11.1897","2.0786"
"","5.3600","11.2318","2.0788"
"","5.3800","11.2739","2.0789"
"","5.4000","11.3161","2.0792"
"","5.4200","11.3584","2.0797"
"","5.4400","11.4009","2.0798"
"","5.4600","11.4435","2.0804"
"","5.4800","11.4858","2.0808"
"","5.5000","11.5281","2.0809"
"","5.5200","11.5702","2.0810"
"","5.5400","11.6125","2.0814"
"","5.5600","11.6551","2.0819"
"","5.5800","11.6978","2.0824"
"","5.6000","11.7402","2.0826"
"","5.6200","11.7824","2.0827"
"","5.6400","11.8245","2.0827"
"","5.6600","11.8666","2.0830"
"","5.6800","11.9089","2.0834"
"","5.7000","11.9513","2.0838"
"","5.7200","11.9938","2.0843"
"","5.7400","12.0363","2.0846"
"","5.7600","12.0786","2.0847"
"","5.7800","12.1207","2.0849"
"","5.8000","12.1628","2.0853"
"","5.8200","12.2052","2.0858"
"","5.8400","12.2478","2.0860"
"","5.8600","12.2905","2.0862"
"","5.8800","12.3330","2.0864"
"","5.9000","12.3751","2.0865"
"","5.9200","12.4171","2.0866"
"","5.9400","12.4591","2.0865"
"","5.9600","12.5013","2.0868"
"","5.9800","12.5437","2.0871"
"","6.0000","12.5863","2.0875"
"","6.0200","12.6288","2.0876"
"","6.0400","12.6711","2.0877"
"","6.0600","12.7133","2.0879"
"","6.0800","12.7555","2.0882"
"","6.1000","12.7980","2.0886"
"","6.1200","12.8405","2.0890"
"","6.1400","12.8831","2.0893"
"","6.1600","12.9256","2.0896"
"","6.1800","12.9679","2.0895"
"","6.2000","13.0101","2.0893"
"","6.2200","13.0522","2.0894"
"","6.2400","13.0943","2.0896"
"","6.2600","13.1364","2.0898"
"","6.2800","13.1788","2.0900"
"","6.3000","13.2212","2.0901"
"","6.3200","13.2636","2.0905"
"","6.3400","13.3058","2.0906"
"","6.3600","13.3481","2.0908"
"","6.3800","13.3906","2.0914"
"","6.4000","13.4333","2.0917"
"","6.4200","13.4759","2.0922"
"","6.4400","13.5183","2.0920"
"","6.4600","13.5605","2.0922"
"","6.4800","13.6026","2.0924"
"","6.5000","13.6448","2.0925"
"","6.5200","13.6870","2.0927"
"","6.5400","13.7293","2.0928"
"","6.5600","13.7716","2.0933"
"","6.5800","13.8138","2.0937"
"","6.6000","13.8560","2.0938"
"","6.6200","13.8982","2.0940"
"","6.6400","13.9406","2.0943"
"","6.6600","13.9832","2.0946"
"","6.6800","14.0258","2.0954"
"","6.7000","14.0685","2.0957"
"","6.7200","14.1109","2.0960"
"","6.7400","14.1531","2.0961"
"","6.7600","14.1953","2.0962"
"","6.7800","14.2375","2.0964"
"","6.8000","14.2797","2.0965"
"","6.8200","14.3221","2.0968"
"","6.8400","14.3644","2.0970"
"","6.8600","14.4067","2.0971"
"","6.8800","14.4488","2.0973"
"","6.9000","14.4909","2.0975"
"","6.9200","14.5332","2.0978"
"","6.9400","14.5759","2.0984"
"","6.9600","14.6187","2.0988"
"","6.9800","14.6613","2.0993"
"","7.0000","14.7037","2.0994"
"","7.0200","14.7458","2.0995"
"","7.0400","14.7879","2.0993"
"","7.0600","14.8300","2.0995"
"","7.0800","14.8723","2.0999"
"","7.1000","14.9147","2.1001"
"","7.1200","14.9571","2.1002"
"","7.1400","14.9994","2.1002"
"","7.1600","15.0416","2.1003"
"","7.1800","15.0838","2.1005"
"","7.2000","15.1262","2.1007"
"","7.2200","15.1687","2.1010"
"","7.2400","15.2113","2.1015"
"","7.2600","15.2537","2.1015"
"","7.2800","15.2960","2.1014"
"","7.3000","15.3382","2.1012"
"","7.3200","15.3805","2.1012"
"","7.3400","15.4229","2.1012"
"","7.3600","15.4653","2.1012"
"","7.3800","15.5078","2.1011"
"","7.4000","15.5500","2.1006"
"","7.4200","15.5922","2.1002"
"","7.4400","15.6342","2.0999"
"","7.4600","15.6764","2.0994"
"","7.4800","15.7188","2.0991"
"","7.5000","15.7614","2.0987"
"","7.5200","15.8039","2.0978"
"","7.5400","15.8463","2.0965"
"","7.5600","15.8885","2.0945"
"","7.5800","15.9307","2.0921"
"","7.6000","15.9730","2.0886"
"","7.6200","16.0155","2.0823"
"","7.6330","16.0431","1.8123"
"","7.6380","16.0537","1.5401"
"","7.6430","16.0643","1.2436"
3,Time,Displacement,Force
,(s),(mm),(kN)
"","0.0000","0.0000","0.0482"
"","0.0200","0.0005","0.0487"
"","0.0400","0.0173","0.0656"
"","0.0600","0.0972","0.1440"
"","0.0800","0.2474","0.2883"
"","0.1000","0.4146","0.4451"
"","0.1200","0.5744","0.5896"
"","0.1400","0.7336","0.7281"
"","0.1600","0.9015","0.8695"
"","0.1800","1.0785","1.0128"
"","0.2000","1.2586","1.1513"
"","0.2200","1.4359","1.2800"
"","0.2400","1.6082","1.3990"
"","0.2600","1.7766","1.5103"
"","0.2800","1.9437","1.6162"
"","0.3000","2.1114","1.7170"
"","0.3200","2.2803","1.8132"
"","0.3400","2.4502","1.9043"
"","0.3600","2.6204","1.9900"
"","0.3800","2.7903","2.0702"
"","0.4000","2.9598","2.1452"
"","0.4200","3.1290","2.2152"
"","0.4400","3.2981","2.2802"
"","0.4600","3.4673","2.3406"
"","0.4800","3.6367","2.3964"
"","0.5000","3.8059","2.4481"
"","0.5200","3.9752","2.4961"
"","0.5400","4.1447","2.5399"
"","0.5600","4.3144","2.5801"
"","0.5800","4.4838","2.6170"
"","0.6000","4.6531","2.6501"
"","0.6200","4.8224","2.6796"
"","0.6400","4.9917","2.7059"
"","0.6600","5.1609","2.7289"
"","0.6800","5.3302","2.7487"
"","0.7000","5.4996","2.7656"
"","0.7200","5.6689","2.7790"
"","0.7400","5.8381","2.7893"
"","0.7600","6.0074","2.7968"
"","0.7800","6.1767","2.8015"
"","0.8000","6.3461","2.8034"
"","0.8200","6.5154","2.8023"
"","0.8400","6.6848","2.7985"
"","0.8600","6.8542","2.7917"
"","0.8800","7.0236","2.7815"
"","0.9000","7.1929","2.7665"
"","0.9200","7.3622","2.7437"
"","0.9400","7.5314","2.6977"
"","0.9600","7.7008","2.5638"
"","0.9800","7.8703","2.3743"
"","1.0000","8.0399","2.2491"
"","1.0200","8.2093","2.1989"
"","1.0400","8.3786","2.1865"
"","1.0600","8.5479","2.1849"
"","1.0800","8.7170","2.1836"
"","1.1000","8.8862","2.1815"
"","1.1200","9.0556","2.1792"
"","1.1400","9.2250","2.1768"
"","1.1600","9.3944","2.1747"
"","1.1800","9.5638","2.1732"
"","1.2000","9.7332","2.1716"
"","1.2200","9.9024","2.1704"
"","1.2400","10.0715","2.1696"
"","1.2600","10.2408","2.1699"
"","1.2800","10.4102","2.1709"
"","1.3000","10.5796","2.1720"
"","1.3200","10.7490","2.1733"
"","1.3400","10.9183","2.1748"
"","1.3600","11.0875","2.1761"
"","1.3800","11.2567","2.1772"
"","1.4000","11.4261","2.1786"
"","1.4200","11.5956","2.1799"
"","1.4400","11.7650","2.1809"
"","1.4600","11.9344","2.1820"
"","1.4800","12.1039","2.1832"
"","1.5000","12.2733","2.1843"
"","1.5200","12.4426","2.1850"
"","1.5400","12.6117","2.1860"
"","1.5600","12.7809","2.1869"
"","1.5800","12.9502","2.1879"
"","1.6000","13.1196","2.1889"
"","1.6200","13.2890","2.1897"
"","1.6400","13.4584","2.1907"
"","1.6600","13.6276","2.1914"
"","1.6800","13.7969","2.1924"
"","1.7000","13.9661","2.1934"
"","1.7200","14.1353","2.1947"
"","1.7400","14.3047","2.1959"
"","1.7600","14.4742","2.1972"
"","1.7800","14.6436","2.1984"
"","1.8000","14.8129","2.1995"
"","1.8200","14.9823","2.2006"
"","1.8400","15.1517","2.2022"
"","1.8600","15.3209","2.2033"
"","1.8800","15.4902","2.2043"
"","1.9000","15.6597","2.2056"
"","1.9200","15.8292","2.2066"
"","1.9400","15.9985","2.2076"
"","1.9600","16.1678","2.2086"
"","1.9800","16.3370","2.2095"
"","2.0000","16.5062","2.2105"
"","2.0200","16.6754","2.2117"
"","2.0400","16.8447","2.2127"
"","2.0600","17.0142","2.2138"
"","2.0800","17.1836","2.2148"
"","2.1000","17.3530","2.2155"
"","2.1200","17.5223","2.2164"
"","2.1400","17.6916","2.2173"
"","2.1600","17.8609","2.2183"
"","2.1800","18.0303","2.2192"
"","2.2000","18.1995","2.2201"
"","2.2200","18.3689","2.2208"
"","2.2400","18.5384","2.2217"
"","2.2600","18.7078","2.2226"
"","2.2800","18.8770","2.2234"
"","2.3000","19.0462","2.2242"
"","2.3200","19.2155","2.2248"
"","2.3400","19.3849","2.2255"
"","2.3600","19.5542","2.2264"
"","2.3800","19.7236","2.2273"
"","2.4000","19.8931","2.2279"
"","2.4200","20.0624","2.2287"
"","2.4400","20.2317","2.2292"
"","2.4600","20.4010","2.2299"
"","2.4800","20.5704","2.2306"
"","2.5000","20.7397","2.2311"
"","2.5200","20.9089","2.2317"
"","2.5400","21.0783","2.2328"
"","2.5600","21.2476","2.2336"
"","2.5800","21.4169","2.2341"
"","2.6000","21.5862","2.2347"
"","2.6200","21.7555","2.2352"
"","2.6400","21.9248","2.2356"
"","2.6600","22.0942","2.2361"
"","2.6800","22.2636","2.2367"
"","2.7000","22.4329","2.2373"
"","2.7200","22.6022","2.2383"
"","2.7400","22.7717","2.2390"
"","2.7600","22.9411","2.2395"
"","2.7800","23.1105","2.2402"
"","2.8000","23.2798","2.2407"
"","2.8200","23.4491","2.2410"
"","2.8400","23.6183","2.2416"
"","2.8600","23.7875","2.2421"
"","2.8800","23.9569","2.2426"
"","2.9000","24.1263","2.2432"
"","2.9200","24.2957","2.2437"
"","2.9400","24.4650","2.2442"
"","2.9600","24.6343","2.2447"
"","2.9800","24.8036","2.2454"
"","3.0000","24.9728","2.2459"
"","3.0200","25.1421","2.2464"
"","3.0400","25.3115","2.2467"
"","3.0600","25.4809","2.2469"
"","3.0800","25.6503","2.2477"
"","3.1000","25.8198","2.2483"
"","3.1200","25.9892","2.2489"
"","3.1400","26.1584","2.2494"
"","3.1600","26.3276","2.2500"
"","3.1800","26.4969","2.2507"
"","3.2000","26.6663","2.2512"
"","3.2200","26.8356","2.2516"
"","3.2400","27.0050","2.2520"
"","3.2600","27.1743","2.2524"
"","3.2800","27.3436","2.2525"
"","3.3000","27.5129","2.2527"
"","3.3200","27.6822","2.2530"
"","3.3400","27.8515","2.2530"
"","3.3600","28.0209","2.2532"
"","3.3800","28.1904","2.2532"
"","3.4000","28.3598","2.2532"
"","3.4200","28.5291","2.2533"
"","3.4400","28.6983","2.2534"
"","3.4600","28.8676","2.2530"
"","3.4800","29.0367","2.2524"
"","3.5000","29.2060","2.2513"
"","3.5200","29.3756","2.2493"
"","3.5400","29.5451","2.2456"
"","3.5600","29.7144","2.2384"
"","3.5790","29.8752","1.9638"
"","3.5840","29.9175","1.6758"
"","3.5880","29.9514","1.4225"
"","3.5900","29.9684","1.2951"