File: Lab10/PMMA_S6_1 (2).csv
Results Table 1
,Specimen label,Thickness,Width,Length,Rate 1
,,(mm),(mm),(mm),(mm/min)
"1","PMMA_rt_.1","3.07","13.21","89.18","2.54"
"2","PMMA_rt_1","3.20","13.16","92.38","25.40"
"3","PMMA_50_.1","3.25","12.57","90.65","2.54"
"4","PMMA_50_1","3.20","13.03","91.26","25.40"

Results Table 2


1,Time,Displacement,Force
,(s),(mm),(kN)
"","0.0000","0.0000","0.1226"
"","0.1000","0.0003","0.1229"
"","0.2000","0.0013","0.1249"
"","0.3000","0.0026","0.1265"
"","0.4000","0.0121","0.1416"
"","0.5000","0.0164","0.1473"
"","0.6000","0.0204","0.1528"
"","0.7000","0.0249","0.1589"
"","0.8000","0.0290","0.1644"
"","0.9000","0.0332","0.1705"
"","1.0000","0.0374","0.1759"
"","1.1000","0.0414","0.1815"
"","1.2000","0.0459","0.1876"
"","1.3000","0.0500","0.1928"
"","1.4000","0.0543","0.1987"
"","1.5000","0.0583","0.2035"
"","1.6000","0.0631","0.2101"
"","1.7000","0.0669","0.2152"
"","1.8000","0.0718","0.2213"
"","1.9000","0.0754","0.2260"
"","2.0000","0.0801","0.2321"
"","2.1000","0.0839","0.2369"
"","2.2000","0.0884","0.2426"
"","2.3000","0.0922","0.2473"
"","2.4000","0.0970","0.2535"
"","2.5000","0.1007","0.2580"
"","2.6000","0.1052","0.2640"
"","2.7000","0.1093","0.2692"
"","2.8000","0.1138","0.2745"
"","2.9000","0.1180","0.2798"
"","3.0000","0.1222","0.2849"
"","3.1000","0.1263","0.2898"
"","3.2000","0.1307","0.2953"
"","3.3000","0.1348","0.3002"
"","3.4000","0.1389","0.3047"
"","3.5000","0.1433","0.3102"
"","3.6000","0.1473","0.3147"
"","3.7000","0.1517","0.3206"
"","3.8000","0.1558","0.3249"
"","3.9000","0.1603","0.3305"
"","4.0000","0.1645","0.3353"
"","4.1000","0.1690","0.3405"
"","4.2000","0.1729","0.3447"
"","4.3000","0.1773","0.3503"
"","4.4000","0.1813","0.3547"
"","4.5000","0.1855","0.3597"
"","4.6000","0.1898","0.3646"
"","4.7000","0.1941","0.3697"
"","4.8000","0.1982","0.3744"
"","4.9000","0.2024","0.3794"
"","5.0000","0.2068","0.3845"
"","5.1000","0.2111","0.3894"
"","5.2000","0.2155","0.3945"
"","5.3000","0.2194","0.3989"
"","5.4000","0.2239","0.4043"
"","5.5000","0.2278","0.4085"
"","5.6000","0.2322","0.4135"
"","5.7000","0.2361","0.4180"
"","5.8000","0.2408","0.4238"
"","5.9000","0.2445","0.4278"
"","6.0000","0.2491","0.4335"
"","6.1000","0.2530","0.4374"
"","6.2000","0.2578","0.4434"
"","6.3000","0.2616","0.4474"
"","6.4000","0.2663","0.4528"
"","6.5000","0.2701","0.4572"
"","6.6000","0.2748","0.4628"
"","6.7000","0.2786","0.4669"
"","6.8000","0.2831","0.4718"
"","6.9000","0.2871","0.4764"
"","7.0000","0.2915","0.4818"
"","7.1000","0.2955","0.4858"
"","7.2000","0.2998","0.4908"
"","7.3000","0.3042","0.4958"
"","7.4000","0.3085","0.5005"
"","7.5000","0.3126","0.5051"
"","7.6000","0.3168","0.5095"
"","7.7000","0.3211","0.5145"
"","7.8000","0.3252","0.5192"
"","7.9000","0.3295","0.5238"
"","8.0000","0.3336","0.5283"
"","8.1000","0.3381","0.5336"
"","8.2000","0.3419","0.5375"
"","8.3000","0.3465","0.5429"
"","8.4000","0.3506","0.5473"
"","8.5000","0.3551","0.5524"
"","8.6000","0.3592","0.5568"
"","8.7000","0.3635","0.5616"
"","8.8000","0.3676","0.5662"
"","8.9000","0.3721","0.5709"
"","9.0000","0.3762","0.5758"
"","9.1000","0.3802","0.5800"
"","9.2000","0.3846","0.5844"
"","9.3000","0.3887","0.5891"
"","9.4000","0.3930","0.5938"
"","9.5000","0.3972","0.5983"
"","9.6000","0.4017","0.6034"
"","9.7000","0.4058","0.6078"
"","9.8000","0.4102","0.6127"
"","9.9000","0.4140","0.6165"
"","10.0000","0.4186","0.6217"
"","10.1000","0.4226","0.6261"
"","10.2000","0.4270","0.6309"
"","10.3000","0.4310","0.6351"
"","10.4000","0.4354","0.6399"
"","10.5000","0.4394","0.6441"
"","10.6000","0.4439","0.6491"
"","10.7000","0.4481","0.6535"
"","10.8000","0.4524","0.6582"
"","10.9000","0.4566","0.6629"
"","11.0000","0.4608","0.6668"
"","11.1000","0.4652","0.6721"
"","11.2000","0.4694","0.6763"
"","11.3000","0.4735","0.6808"
"","11.4000","0.4775","0.6847"
"","11.5000","0.4820","0.6899"
"","11.6000","0.4859","0.6937"
"","11.7000","0.4904","0.6985"
"","11.8000","0.4943","0.7027"
"","11.9000","0.4993","0.7083"
"","12.0000","0.5029","0.7118"
"","12.1000","0.5076","0.7174"
"","12.2000","0.5112","0.7205"
"","12.3000","0.5162","0.7261"
"","12.4000","0.5198","0.7300"
"","12.5000","0.5245","0.7349"
"","12.6000","0.5280","0.7384"
"","12.7000","0.5330","0.7439"
"","12.8000","0.5365","0.7475"
"","12.9000","0.5414","0.7526"
"","13.0000","0.5451","0.7564"
"","13.1000","0.5500","0.7618"
"","13.2000","0.5537","0.7656"
"","13.3000","0.5584","0.7705"
"","13.4000","0.5622","0.7746"
"","13.5000","0.5671","0.7797"
"","13.6000","0.5708","0.7835"
"","13.7000","0.5752","0.7879"
"","13.8000","0.5790","0.7920"
"","13.9000","0.5836","0.7969"
"","14.0000","0.5874","0.8004"
"","14.1000","0.5922","0.8058"
"","14.2000","0.5961","0.8097"
"","14.3000","0.6006","0.8144"
"","14.4000","0.6045","0.8187"
"","14.5000","0.6091","0.8234"
"","14.6000","0.6131","0.8272"
"","14.7000","0.6176","0.8325"
"","14.8000","0.6213","0.8357"
"","14.9000","0.6260","0.8408"
"","15.0000","0.6297","0.8443"
"","15.1000","0.6344","0.8496"
"","15.2000","0.6383","0.8534"
"","15.3000","0.6431","0.8585"
"","15.4000","0.6470","0.8625"
"","15.5000","0.6516","0.8672"
"","15.6000","0.6550","0.8704"
"","15.7000","0.6604","0.8766"
"","15.8000","0.6639","0.8795"
"","15.9000","0.6687","0.8846"
"","16.0000","0.6720","0.8875"
"","16.1000","0.6770","0.8932"
"","16.2000","0.6804","0.8960"
"","16.3000","0.6855","0.9017"
"","16.4000","0.6889","0.9047"
"","16.5000","0.6941","0.9109"
"","16.6000","0.6976","0.9136"
"","16.7000","0.7024","0.9190"
"","16.8000","0.7059","0.9219"
"","16.9000","0.7110","0.9278"
"","17.0000","0.7144","0.9305"
"","17.1000","0.7192","0.9357"
"","17.2000","0.7228","0.9392"
"","17.3000","0.7275","0.9440"
"","17.4000","0.7314","0.9477"
"","17.5000","0.7360","0.9526"
"","17.6000","0.7401","0.9566"
"","17.7000","0.7447","0.9616"
"","17.8000","0.7485","0.9652"
"","17.9000","0.7530","0.9697"
"","18.0000","0.7574","0.9741"
"","18.1000","0.7615","0.9781"
"","18.2000","0.7656","0.9823"
"","18.3000","0.7698","0.9866"
"","18.4000","0.7739","0.9901"
"","18.5000","0.7782","0.9949"
"","18.6000","0.7823","0.9988"
"","18.7000","0.7867","1.0031"
"","18.8000","0.7911","1.0077"
"","18.9000","0.7953","1.0116"
"","19.0000","0.7993","1.0157"
"","19.1000","0.8038","1.0205"
"","19.2000","0.8078","1.0240"
"","19.3000","0.8122","1.0289"
"","19.4000","0.8161","1.0325"
"","19.5000","0.8206","1.0369"
"","19.6000","0.8245","1.0406"
"","19.7000","0.8292","1.0454"
"","19.8000","0.8330","1.0490"
"","19.9000","0.8378","1.0539"
"","20.0000","0.8416","1.0571"
"","20.1000","0.8463","1.0624"
"","20.2000","0.8501","1.0658"
"","20.3000","0.8549","1.0705"
"","20.4000","0.8585","1.0738"
"","20.5000","0.8631","1.0787"
"","20.6000","0.8669","1.0821"
"","20.7000","0.8714","1.0866"
"","20.8000","0.8754","1.0904"
"","20.9000","0.8798","1.0949"
"","21.0000","0.8841","1.0989"
"","21.1000","0.8884","1.1036"
"","21.2000","0.8926","1.1075"
"","21.3000","0.8968","1.1114"
"","21.4000","0.9012","1.1155"
"","21.5000","0.9052","1.1199"
"","21.6000","0.9095","1.1237"
"","21.7000","0.9135","1.1273"
"","21.8000","0.9181","1.1321"
"","21.9000","0.9220","1.1356"
"","22.0000","0.9266","1.1402"
"","22.1000","0.9303","1.1439"
"","22.2000","0.9352","1.1487"
"","22.3000","0.9390","1.1521"
"","22.4000","0.9436","1.1566"
"","22.5000","0.9475","1.1603"
"","22.6000","0.9523","1.1650"
"","22.7000","0.9560","1.1682"
"","22.8000","0.9604","1.1727"
"","22.9000","0.9642","1.1762"
"","23.0000","0.9688","1.1807"
"","23.1000","0.9729","1.1844"
"","23.2000","0.9773","1.1886"
"","23.3000","0.9812","1.1922"
"","23.4000","0.9860","1.1969"
"","23.5000","0.9898","1.2003"
"","23.6000","0.9942","1.2050"
"","23.7000","0.9984","1.2088"
"","23.8000","1.0027","1.2126"
"","23.9000","1.0068","1.2164"
"","24.0000","1.0111","1.2208"
"","24.1000","1.0152","1.2244"
"","24.2000","1.0196","1.2287"
"","24.3000","1.0237","1.2325"
"","24.4000","1.0280","1.2365"
"","24.5000","1.0322","1.2405"
"","24.6000","1.0366","1.2446"
"","24.7000","1.0407","1.2484"
"","24.8000","1.0453","1.2530"
"","24.9000","1.0492","1.2562"
"","25.0000","1.0537","1.2607"
"","25.1000","1.0575","1.2640"
"","25.2000","1.0621","1.2686"
"","25.3000","1.0659","1.2718"
"","25.4000","1.0705","1.2761"
"","25.5000","1.0741","1.2792"
"","25.6000","1.0792","1.2845"
"","25.7000","1.0829","1.2878"
"","25.8000","1.0877","1.2927"
"","25.9000","1.0913","1.2951"
"","26.0000","1.0962","1.3004"
"","26.1000","1.0996","1.3029"
"","26.2000","1.1046","1.3078"
"","26.3000","1.1079","1.3106"
"","26.4000","1.1131","1.3158"
"","26.5000","1.1166","1.3189"
"","26.6000","1.1214","1.3232"
"","26.7000","1.1249","1.3263"
"","26.8000","1.1301","1.3315"
"","26.9000","1.1336","1.3342"
"","27.0000","1.1385","1.3391"
"","27.1000","1.1422","1.3422"
"","27.2000","1.1470","1.3470"
"","27.3000","1.1506","1.3501"
"","27.4000","1.1552","1.3543"
"","27.5000","1.1590","1.3577"
"","27.6000","1.1637","1.3620"
"","27.7000","1.1674","1.3655"
"","27.8000","1.1719","1.3697"
"","27.9000","1.1761","1.3732"
"","28.0000","1.1806","1.3776"
"","28.1000","1.1847","1.3810"
"","28.2000","1.1890","1.3851"
"","28.3000","1.1931","1.3887"
"","28.4000","1.1974","1.3929"
"","28.5000","1.2014","1.3959"
"","28.6000","1.2058","1.4003"
"","28.7000","1.2100","1.4042"
"","28.8000","1.2143","1.4080"
"","28.9000","1.2182","1.4112"
"","29.0000","1.2228","1.4157"
"","29.1000","1.2269","1.4189"
"","29.2000","1.2315","1.4233"
"","29.3000","1.2354","1.4266"
"","29.4000","1.2400","1.4310"
"","29.5000","1.2439","1.4343"
"","29.6000","1.2484","1.4386"
"","29.7000","1.2520","1.4414"
"","29.8000","1.2568","1.4459"
"","29.9000","1.2606","1.4491"
"","30.0000","1.2652","1.4534"
"","30.1000","1.2689","1.4563"
"","30.2000","1.2739","1.4611"
"","30.3000","1.2777","1.4645"
"","30.4000","1.2824","1.4687"
"","30.5000","1.2860","1.4718"
"","30.6000","1.2908","1.4760"
"","30.7000","1.2945","1.4790"
"","30.8000","1.2991","1.4833"
"","30.9000","1.3030","1.4864"
"","31.0000","1.3075","1.4907"
"","31.1000","1.3114","1.4940"
"","31.2000","1.3159","1.4980"
"","31.3000","1.3201","1.5018"
"","31.4000","1.3244","1.5055"
"","31.5000","1.3287","1.5091"
"","31.6000","1.3329","1.5130"
"","31.7000","1.3373","1.5167"
"","31.8000","1.3413","1.5203"
"","31.9000","1.3456","1.5238"
"","32.0000","1.3496","1.5272"
"","32.1000","1.3542","1.5315"
"","32.2000","1.3580","1.5347"
"","32.3000","1.3624","1.5386"
"","32.4000","1.3664","1.5420"
"","32.5000","1.3712","1.5461"
"","32.6000","1.3751","1.5496"
"","32.7000","1.3796","1.5534"
"","32.8000","1.3835","1.5569"
"","32.9000","1.3880","1.5605"
"","33.0000","1.3919","1.5638"
"","33.1000","1.3962","1.5678"
"","33.2000","1.4003","1.5710"
"","33.3000","1.4049","1.5753"
"","33.4000","1.4088","1.5783"
"","33.5000","1.4132","1.5821"
"","33.6000","1.4175","1.5859"
"","33.7000","1.4217","1.5892"
"","33.8000","1.4262","1.5934"
"","33.9000","1.4303","1.5970"
"","34.0000","1.4345","1.6007"
"","34.1000","1.4388","1.6041"
"","34.2000","1.4429","1.6075"
"","34.3000","1.4470","1.6112"
"","34.4000","1.4514","1.6148"
"","34.5000","1.4555","1.6179"
"","34.6000","1.4597","1.6217"
"","34.7000","1.4641","1.6253"
"","34.8000","1.4684","1.6290"
"","34.9000","1.4727","1.6328"
"","35.0000","1.4768","1.6363"
"","35.1000","1.4811","1.6398"
"","35.2000","1.4852","1.6429"
"","35.3000","1.4895","1.6466"
"","35.4000","1.4933","1.6497"
"","35.5000","1.4982","1.6541"
"","35.6000","1.5019","1.6569"
"","35.7000","1.5065","1.6610"
"","35.8000","1.5102","1.6640"
"","35.9000","1.5152","1.6686"
"","36.0000","1.5189","1.6709"
"","36.1000","1.5239","1.6758"
"","36.2000","1.5272","1.6778"
"","36.3000","1.5324","1.6826"
"","36.4000","1.5358","1.6853"
"","36.5000","1.5407","1.6895"
"","36.6000","1.5442","1.6917"
"","36.7000","1.5491","1.6963"
"","36.8000","1.5525","1.6987"
"","36.9000","1.5575","1.7031"
"","37.0000","1.5611","1.7056"
"","37.1000","1.5661","1.7104"
"","37.2000","1.5698","1.7131"
"","37.3000","1.5744","1.7167"
"","37.4000","1.5781","1.7199"
"","37.5000","1.5828","1.7238"
"","37.6000","1.5866","1.7269"
"","37.7000","1.5912","1.7305"
"","37.8000","1.5951","1.7335"
"","37.9000","1.5996","1.7376"
"","38.0000","1.6035","1.7405"
"","38.1000","1.6080","1.7442"
"","38.2000","1.6122","1.7476"
"","38.3000","1.6167","1.7512"
"","38.4000","1.6208","1.7545"
"","38.5000","1.6250","1.7580"
"","38.6000","1.6293","1.7613"
"","38.7000","1.6335","1.7647"
"","38.8000","1.6376","1.7677"
"","38.9000","1.6419","1.7715"
"","39.0000","1.6459","1.7745"
"","39.1000","1.6503","1.7781"
"","39.2000","1.6543","1.7812"
"","39.3000","1.6589","1.7850"
"","39.4000","1.6632","1.7884"
"","39.5000","1.6675","1.7918"
"","39.6000","1.6712","1.7945"
"","39.7000","1.6760","1.7987"
"","39.8000","1.6797","1.8011"
"","39.9000","1.6845","1.8055"
"","40.0000","1.6880","1.8077"
"","40.1000","1.6929","1.8119"
"","40.2000","1.6965","1.8143"
"","40.3000","1.7013","1.8184"
"","40.4000","1.7050","1.8214"
"","40.5000","1.7099","1.8257"
"","40.6000","1.7137","1.8279"
"","40.7000","1.7184","1.8322"
"","40.8000","1.7221","1.8344"
"","40.9000","1.7269","1.8389"
"","41.0000","1.7308","1.8414"
"","41.1000","1.7352","1.8449"
"","41.2000","1.7390","1.8479"
"","41.3000","1.7435","1.8512"
"","41.4000","1.7474","1.8543"
"","41.5000","1.7518","1.8578"
"","41.6000","1.7562","1.8615"
"","41.7000","1.7605","1.8647"
"","41.8000","1.7647","1.8678"
"","41.9000","1.7688","1.8710"
"","42.0000","1.7732","1.8745"
"","42.1000","1.7773","1.8773"
"","42.2000","1.7816","1.8808"
"","42.3000","1.7856","1.8838"
"","42.4000","1.7901","1.8876"
"","42.5000","1.7940","1.8899"
"","42.6000","1.7985","1.8937"
"","42.7000","1.8026","1.8969"
"","42.8000","1.8071","1.9002"
"","42.9000","1.8113","1.9038"
"","43.0000","1.8154","1.9065"
"","43.1000","1.8197","1.9102"
"","43.2000","1.8242","1.9134"
"","43.3000","1.8283","1.9163"
"","43.4000","1.8323","1.9194"
"","43.5000","1.8365","1.9224"
"","43.6000","1.8406","1.9254"
"","43.7000","1.8450","1.9291"
"","43.8000","1.8490","1.9316"
"","43.9000","1.8537","1.9355"
"","44.0000","1.8578","1.9385"
"","44.1000","1.8622","1.9420"
"","44.2000","1.8660","1.9445"
"","44.3000","1.8706","1.9483"
"","44.4000","1.8745","1.9511"
"","44.5000","1.8791","1.9546"
"","44.6000","1.8830","1.9571"
"","44.7000","1.8873","1.9605"
"","44.8000","1.8915","1.9636"
"","44.9000","1.8958","1.9669"
"","45.0000","1.9000","1.9701"
"","45.1000","1.9045","1.9733"
"","45.2000","1.9086","1.9768"
"","45.3000","1.9128","1.9794"
"","45.4000","1.9174","1.9832"
"","45.5000","1.9213","1.9856"
"","45.6000","1.9257","1.9886"
"","45.7000","1.9296","1.9917"
"","45.8000","1.9340","1.9950"
"","45.9000","1.9379","1.9974"
"","46.0000","1.9426","2.0012"
"","46.1000","1.9462","2.0036"
"","46.2000","1.9514","2.0081"
"","46.3000","1.9549","2.0099"
"","46.4000","1.9597","2.0139"
"","46.5000","1.9633","2.0162"
"","46.6000","1.9681","2.0200"
"","46.7000","1.9716","2.0221"
"","46.8000","1.9766","2.0260"
"","46.9000","1.9800","2.0280"
"","47.0000","1.9851","2.0322"
"","47.1000","1.9886","2.0343"
"","47.2000","1.9933","2.0380"
"","47.3000","1.9971","2.0404"
"","47.4000","2.0020","2.0441"
"","47.5000","2.0058","2.0466"
"","47.6000","2.0105","2.0502"
"","47.7000","2.0146","2.0533"
"","47.8000","2.0187","2.0559"
"","47.9000","2.0228","2.0587"
"","48.0000","2.0272","2.0621"
"","48.1000","2.0311","2.0646"
"","48.2000","2.0356","2.0680"
"","48.3000","2.0395","2.0704"
"","48.4000","2.0441","2.0741"
"","48.5000","2.0483","2.0770"
"","48.6000","2.0527","2.0800"
"","48.7000","2.0567","2.0828"
"","48.8000","2.0611","2.0858"
"","48.9000","2.0651","2.0885"
"","49.0000","2.0696","2.0918"
"","49.1000","2.0734","2.0945"
"","49.2000","2.0780","2.0978"
"","49.3000","2.0819","2.1004"
"","49.4000","2.0865","2.1037"
"","49.5000","2.0901","2.1057"
"","49.6000","2.0953","2.1098"
"","49.7000","2.0989","2.1120"
"","49.8000","2.1038","2.1161"
"","49.9000","2.1073","2.1177"
"","50.0000","2.1124","2.1216"
"","50.1000","2.1158","2.1234"
"","50.2000","2.1208","2.1277"
"","50.3000","2.1240","2.1288"
"","50.4000","2.1291","2.1332"
"","50.5000","2.1324","2.1348"
"","50.6000","2.1375","2.1391"
"","50.7000","2.1410","2.1408"
"","50.8000","2.1462","2.1451"
"","50.9000","2.1496","2.1468"
"","51.0000","2.1545","2.1502"
"","51.1000","2.1579","2.1522"
"","51.2000","2.1630","2.1564"
"","51.3000","2.1665","2.1578"
"","51.4000","2.1713","2.1617"
"","51.5000","2.1749","2.1635"
"","51.6000","2.1797","2.1670"
"","51.7000","2.1834","2.1693"
"","51.8000","2.1881","2.1726"
"","51.9000","2.1921","2.1753"
"","52.0000","2.1967","2.1785"
"","52.1000","2.2006","2.1810"
"","52.2000","2.2050","2.1840"
"","52.3000","2.2093","2.1870"
"","52.4000","2.2135","2.1897"
"","52.5000","2.2175","2.1919"
"","52.6000","2.2218","2.1951"
"","52.7000","2.2259","2.1979"
"","52.8000","2.2301","2.2005"
"","52.9000","2.2344","2.2033"
"","53.0000","2.2387","2.2064"
"","53.1000","2.2431","2.2091"
"","53.2000","2.2473","2.2120"
"","53.3000","2.2514","2.2143"
"","53.4000","2.2558","2.2175"
"","53.5000","2.2599","2.2200"
"","53.6000","2.2643","2.2228"
"","53.7000","2.2681","2.2249"
"","53.8000","2.2727","2.2285"
"","53.9000","2.2766","2.2306"
"","54.0000","2.2811","2.2342"
"","54.1000","2.2851","2.2361"
"","54.2000","2.2899","2.2397"
"","54.3000","2.2936","2.2416"
"","54.4000","2.2983","2.2449"
"","54.5000","2.3021","2.2472"
"","54.6000","2.3069","2.2507"
"","54.7000","2.3107","2.2527"
"","54.8000","2.3151","2.2557"
"","54.9000","2.3190","2.2579"
"","55.0000","2.3235","2.2612"
"","55.1000","2.3274","2.2633"
"","55.2000","2.3318","2.2661"
"","55.3000","2.3362","2.2688"
"","55.4000","2.3405","2.2717"
"","55.5000","2.3447","2.2744"
"","55.6000","2.3488","2.2770"
"","55.7000","2.3532","2.2795"
"","55.8000","2.3572","2.2822"
"","55.9000","2.3615","2.2849"
"","56.0000","2.3655","2.2873"
"","56.1000","2.3702","2.2904"
"","56.2000","2.3739","2.2925"
"","56.3000","2.3786","2.2956"
"","56.4000","2.3824","2.2975"
"","56.5000","2.3872","2.3011"
"","56.6000","2.3911","2.3031"
"","56.7000","2.3957","2.3066"
"","56.8000","2.3994","2.3082"
"","56.9000","2.4043","2.3117"
"","57.0000","2.4079","2.3135"
"","57.1000","2.4125","2.3164"
"","57.2000","2.4164","2.3185"
"","57.3000","2.4209","2.3216"
"","57.4000","2.4248","2.3238"
"","57.5000","2.4294","2.3267"
"","57.6000","2.4332","2.3290"
"","57.7000","2.4381","2.3321"
"","57.8000","2.4420","2.3344"
"","57.9000","2.4463","2.3369"
"","58.0000","2.4505","2.3393"
"","58.1000","2.4547","2.3420"
"","58.2000","2.4588","2.3445"
"","58.3000","2.4631","2.3470"
"","58.4000","2.4672","2.3493"
"","58.5000","2.4715","2.3519"
"","58.6000","2.4757","2.3548"
"","58.7000","2.4799","2.3570"
"","58.8000","2.4844","2.3597"
"","58.9000","2.4888","2.3625"
"","59.0000","2.4927","2.3646"
"","59.1000","2.4973","2.3675"
"","59.2000","2.5012","2.3698"
"","59.3000","2.5055","2.3723"
"","59.4000","2.5096","2.3748"
"","59.5000","2.5141","2.3775"
"","59.6000","2.5179","2.3794"
"","59.7000","2.5226","2.3826"
"","59.8000","2.5261","2.3838"
"","59.9000","2.5312","2.3876"
"","60.0000","2.5351","2.3895"
"","60.1000","2.5397","2.3924"
"","60.2000","2.5433","2.3940"
"","60.3000","2.5482","2.3977"
"","60.4000","2.5515","2.3988"
"","60.5000","2.5566","2.4022"
"","60.6000","2.5601","2.4037"
"","60.7000","2.5651","2.4073"
"","60.8000","2.5686","2.4089"
"","60.9000","2.5733","2.4118"
"","61.0000","2.5769","2.4134"
"","61.1000","2.5822","2.4173"
"","61.2000","2.5857","2.4185"
"","61.3000","2.5906","2.4217"
"","61.4000","2.5942","2.4234"
"","61.5000","2.5988","2.4265"
"","61.6000","2.6027","2.4283"
"","61.7000","2.6073","2.4311"
"","61.8000","2.6110","2.4326"
"","61.9000","2.6157","2.4357"
"","62.0000","2.6195","2.4375"
"","62.1000","2.6239","2.4399"
"","62.2000","2.6284","2.4428"
"","62.3000","2.6327","2.4452"
"","62.4000","2.6367","2.4472"
"","62.5000","2.6411","2.4497"
"","62.6000","2.6450","2.4519"
"","62.7000","2.6493","2.4541"
"","62.8000","2.6535","2.4567"
"","62.9000","2.6579","2.4590"
"","63.0000","2.6620","2.4613"
"","63.1000","2.6664","2.4638"
"","63.2000","2.6702","2.4654"
"","63.3000","2.6749","2.4684"
"","63.4000","2.6791","2.4708"
"","63.5000","2.6836","2.4735"
"","63.6000","2.6873","2.4752"
"","63.7000","2.6921","2.4780"
"","63.8000","2.6958","2.4796"
"","63.9000","2.7006","2.4828"
"","64.0000","2.7041","2.4838"
"","64.1000","2.7090","2.4873"
"","64.2000","2.7126","2.4885"
"","64.3000","2.7173","2.4918"
"","64.4000","2.7209","2.4928"
"","64.5000","2.7260","2.4964"
"","64.6000","2.7297","2.4977"
"","64.7000","2.7344","2.5009"
"","64.8000","2.7380","2.5023"
"","64.9000","2.7428","2.5051"
"","65.0000","2.7465","2.5068"
"","65.1000","2.7513","2.5095"
"","65.2000","2.7550","2.5110"
"","65.3000","2.7595","2.5138"
"","65.4000","2.7634","2.5156"
"","65.5000","2.7679","2.5184"
"","65.6000","2.7721","2.5205"
"","65.7000","2.7766","2.5230"
"","65.8000","2.7806","2.5251"
"","65.9000","2.7849","2.5272"
"","66.0000","2.7892","2.5294"
"","66.1000","2.7934","2.5315"
"","66.2000","2.7978","2.5336"
"","66.3000","2.8017","2.5357"
"","66.4000","2.8061","2.5379"
"","66.5000","2.8101","2.5399"
"","66.6000","2.8144","2.5422"
"","66.7000","2.8184","2.5440"
"","66.8000","2.8234","2.5472"
"","66.9000","2.8271","2.5484"
"","67.0000","2.8315","2.5512"
"","67.1000","2.8355","2.5530"
"","67.2000","2.8399","2.5551"
"","67.3000","2.8441","2.5573"
"","67.4000","2.8484","2.5597"
"","67.5000","2.8523","2.5614"
"","67.6000","2.8569","2.5637"
"","67.7000","2.8608","2.5654"
"","67.8000","2.8652","2.5678"
"","67.9000","2.8696","2.5702"
"","68.0000","2.8738","2.5723"
"","68.1000","2.8781","2.5743"
"","68.2000","2.8823","2.5762"
"","68.3000","2.8866","2.5785"
"","68.4000","2.8909","2.5805"
"","68.5000","2.8951","2.5827"
"","68.6000","2.8991","2.5843"
"","68.7000","2.9033","2.5867"
"","68.8000","2.9075","2.5885"
"","68.9000","2.9117","2.5904"
"","69.0000","2.9162","2.5931"
"","69.1000","2.9204","2.5949"
"","69.2000","2.9247","2.5970"
"","69.3000","2.9287","2.5990"
"","69.4000","2.9331","2.6010"
"","69.5000","2.9371","2.6030"
"","69.6000","2.9417","2.6054"
"","69.7000","2.9454","2.6068"
"","69.8000","2.9501","2.6095"
"","69.9000","2.9539","2.6109"
"","70.0000","2.9586","2.6133"
"","70.1000","2.9623","2.6148"
"","70.2000","2.9673","2.6178"
"","70.3000","2.9709","2.6189"
"","70.4000","2.9758","2.6214"
"","70.5000","2.9793","2.6230"
"","70.6000","2.9844","2.6258"
"","70.7000","2.9879","2.6271"
"","70.8000","2.9926","2.6294"
"","70.9000","2.9961","2.6305"
"","71.0000","3.0010","2.6334"
"","71.1000","3.0046","2.6344"
"","71.2000","3.0095","2.6376"
"","71.3000","3.0132","2.6386"
"","71.4000","3.0181","2.6414"
"","71.5000","3.0218","2.6430"
"","71.6000","3.0264","2.6449"
"","71.7000","3.0303","2.6464"
"","71.8000","3.0348","2.6487"
"","71.9000","3.0387","2.6503"
"","72.0000","3.0431","2.6524"
"","72.1000","3.0471","2.6540"
"","72.2000","3.0515","2.6564"
"","72.3000","3.0556","2.6581"
"","72.4000","3.0601","2.6602"
"","72.5000","3.0644","2.6623"
"","72.6000","3.0686","2.6640"
"","72.7000","3.0728","2.6658"
"","72.8000","3.0770","2.6676"
"","72.9000","3.0815","2.6700"
"","73.0000","3.0856","2.6717"
"","73.1000","3.0896","2.6731"
"","73.2000","3.0938","2.6752"
"","73.3000","3.0980","2.6769"
"","73.4000","3.1022","2.6787"
"","73.5000","3.1064","2.6807"
"","73.6000","3.1110","2.6827"
"","73.7000","3.1151","2.6843"
"","73.8000","3.1195","2.6866"
"","73.9000","3.1233","2.6878"
"","74.0000","3.1280","2.6905"
"","74.1000","3.1318","2.6916"
"","74.2000","3.1364","2.6938"
"","74.3000","3.1400","2.6950"
"","74.4000","3.1448","2.6977"
"","74.5000","3.1487","2.6988"
"","74.6000","3.1533","2.7012"
"","74.7000","3.1571","2.7024"
"","74.8000","3.1620","2.7052"
"","74.9000","3.1657","2.7061"
"","75.0000","3.1705","2.7088"
"","75.1000","3.1741","2.7097"
"","75.2000","3.1790","2.7122"
"","75.3000","3.1827","2.7134"
"","75.4000","3.1872","2.7156"
"","75.5000","3.1910","2.7169"
"","75.6000","3.1955","2.7189"
"","75.7000","3.1995","2.7201"
"","75.8000","3.2040","2.7225"
"","75.9000","3.2082","2.7241"
"","76.0000","3.2124","2.7259"
"","76.1000","3.2165","2.7276"
"","76.2000","3.2210","2.7296"
"","76.3000","3.2250","2.7310"
"","76.4000","3.2295","2.7333"
"","76.5000","3.2334","2.7344"
"","76.6000","3.2377","2.7364"
"","76.7000","3.2420","2.7378"
"","76.8000","3.2462","2.7395"
"","76.9000","3.2504","2.7411"
"","77.0000","3.2548","2.7431"
"","77.1000","3.2591","2.7447"
"","77.2000","3.2633","2.7466"
"","77.3000","3.2674","2.7481"
"","77.4000","3.2718","2.7501"
"","77.5000","3.2762","2.7518"
"","77.6000","3.2803","2.7536"
"","77.7000","3.2842","2.7547"
"","77.8000","3.2886","2.7567"
"","77.9000","3.2927","2.7582"
"","78.0000","3.2971","2.7602"
"","78.1000","3.3012","2.7613"
"","78.2000","3.3057","2.7636"
"","78.3000","3.3098","2.7651"
"","78.4000","3.3142","2.7670"
"","78.5000","3.3181","2.7681"
"","78.6000","3.3227","2.7703"
"","78.7000","3.3267","2.7714"
"","78.8000","3.3310","2.7735"
"","78.9000","3.3349","2.7744"
"","79.0000","3.3394","2.7768"
"","79.1000","3.3435","2.7779"
"","79.2000","3.3479","2.7797"
"","79.3000","3.3521","2.7814"
"","79.4000","3.3564","2.7830"
"","79.5000","3.3606","2.7848"
"","79.6000","3.3648","2.7862"
"","79.7000","3.3693","2.7880"
"","79.8000","3.3733","2.7892"
"","79.9000","3.3778","2.7912"
"","80.0000","3.3817","2.7924"
"","80.1000","3.3860","2.7940"
"","80.2000","3.3899","2.7955"
"","80.3000","3.3946","2.7978"
"","80.4000","3.3983","2.7981"
"","80.5000","3.4034","2.8010"
"","80.6000","3.4070","2.8016"
"","80.7000","3.4118","2.8038"
"","80.8000","3.4153","2.8046"
"","80.9000","3.4203","2.8072"
"","81.0000","3.4238","2.8076"
"","81.1000","3.4285","2.8097"
"","81.2000","3.4321","2.8106"
"","81.3000","3.4371","2.8129"
"","81.4000","3.4406","2.8136"
"","81.5000","3.4454","2.8161"
"","81.6000","3.4492","2.8170"
"","81.7000","3.4539","2.8191"
"","81.8000","3.4579","2.8203"
"","81.9000","3.4626","2.8221"
"","82.0000","3.4664","2.8230"
"","82.1000","3.4710","2.8251"
"","82.2000","3.4748","2.8261"
"","82.3000","3.4792","2.8281"
"","82.4000","3.4832","2.8290"
"","82.5000","3.4876","2.8306"
"","82.6000","3.4915","2.8319"
"","82.7000","3.4962","2.8336"
"","82.8000","3.5003","2.8353"
"","82.9000","3.5047","2.8368"
"","83.0000","3.5088","2.8381"
"","83.1000","3.5131","2.8395"
"","83.2000","3.5172","2.8409"
"","83.3000","3.5216","2.8424"
"","83.4000","3.5254","2.8432"
"","83.5000","3.5301","2.8455"
"","83.6000","3.5340","2.8463"
"","83.7000","3.5385","2.8481"
"","83.8000","3.5423","2.8491"
"","83.9000","3.5472","2.8515"
"","84.0000","3.5509","2.8520"
"","84.1000","3.5559","2.8540"
"","84.2000","3.5592","2.8544"
"","84.3000","3.5644","2.8575"
"","84.4000","3.5678","2.8576"
"","84.5000","3.5727","2.8600"
"","84.6000","3.5761","2.8600"
"","84.7000","3.5812","2.8626"
"","84.8000","3.5844","2.8626"
"","84.9000","3.5895","2.8653"
"","85.0000","3.5930","2.8657"
"","85.1000","3.5981","2.8682"
"","85.2000","3.6018","2.8687"
"","85.3000","3.6065","2.8708"
"","85.4000","3.6100","2.8709"
"","85.5000","3.6150","2.8734"
"","85.6000","3.6185","2.8738"
"","85.7000","3.6232","2.8758"
"","85.8000","3.6271","2.8767"
"","85.9000","3.6315","2.8783"
"","86.0000","3.6355","2.8793"
"","86.1000","3.6400","2.8810"
"","86.2000","3.6442","2.8821"
"","86.3000","3.6487","2.8839"
"","86.4000","3.6528","2.8850"
"","86.5000","3.6570","2.8864"
"","86.6000","3.6614","2.8878"
"","86.7000","3.6654","2.8888"
"","86.8000","3.6696","2.8904"
"","86.9000","3.6738","2.8916"
"","87.0000","3.6780","2.8927"
"","87.1000","3.6821","2.8940"
"","87.2000","3.6865","2.8951"
"","87.3000","3.6907","2.8967"
"","87.4000","3.6952","2.8982"
"","87.5000","3.6994","2.8993"
"","87.6000","3.7034","2.9001"
"","87.7000","3.7078","2.9017"
"","87.8000","3.7119","2.9028"
"","87.9000","3.7162","2.9043"
"","88.0000","3.7202","2.9051"
"","88.1000","3.7247","2.9070"
"","88.2000","3.7286","2.9077"
"","88.3000","3.7331","2.9096"
"","88.4000","3.7371","2.9102"
"","88.5000","3.7418","2.9120"
"","88.6000","3.7458","2.9130"
"","88.7000","3.7503","2.9146"
"","88.8000","3.7542","2.9153"
"","88.9000","3.7588","2.9173"
"","89.0000","3.7627","2.9180"
"","89.1000","3.7671","2.9197"
"","89.2000","3.7709","2.9203"
"","89.3000","3.7755","2.9218"
"","89.4000","3.7795","2.9227"
"","89.5000","3.7839","2.9240"
"","89.6000","3.7882","2.9257"
"","89.7000","3.7926","2.9268"
"","89.8000","3.7968","2.9281"
"","89.9000","3.8008","2.9286"
"","90.0000","3.8051","2.9301"
"","90.1000","3.8092","2.9314"
"","90.2000","3.8136","2.9324"
"","90.3000","3.8176","2.9335"
"","90.4000","3.8222","2.9353"
"","90.5000","3.8260","2.9358"
"","90.6000","3.8306","2.9376"
"","90.7000","3.8344","2.9381"
"","90.8000","3.8393","2.9402"
"","90.9000","3.8431","2.9405"
"","91.0000","3.8477","2.9424"
"","91.1000","3.8514","2.9431"
"","91.2000","3.8564","2.9449"
"","91.3000","3.8600","2.9455"
"","91.4000","3.8646","2.9466"
"","91.5000","3.8684","2.9477"
"","91.6000","3.8729","2.9491"
"","91.7000","3.8768","2.9499"
"","91.8000","3.8814","2.9513"
"","91.9000","3.8854","2.9521"
"","92.0000","3.8902","2.9540"
"","92.1000","3.8940","2.9548"
"","92.2000","3.8983","2.9555"
"","92.3000","3.9024","2.9567"
"","92.4000","3.9067","2.9580"
"","92.5000","3.9108","2.9588"
"","92.6000","3.9153","2.9601"
"","92.7000","3.9192","2.9610"
"","92.8000","3.9236","2.9624"
"","92.9000","3.9277","2.9635"
"","93.0000","3.9322","2.9648"
"","93.1000","3.9364","2.9658"
"","93.2000","3.9408","2.9671"
"","93.3000","3.9447","2.9677"
"","93.4000","3.9493","2.9692"
"","93.5000","3.9532","2.9700"
"","93.6000","3.9578","2.9714"
"","93.7000","3.9616","2.9718"
"","93.8000","3.9662","2.9735"
"","93.9000","3.9698","2.9736"
"","94.0000","3.9746","2.9756"
"","94.1000","3.9782","2.9756"
"","94.2000","3.9834","2.9783"
"","94.3000","3.9870","2.9781"
"","94.4000","3.9918","2.9797"
"","94.5000","3.9952","2.9799"
"","94.6000","4.0003","2.9820"
"","94.7000","4.0037","2.9821"
"","94.8000","4.0087","2.9841"
"","94.9000","4.0120","2.9843"
"","95.0000","4.0171","2.9862"
"","95.1000","4.0205","2.9863"
"","95.2000","4.0255","2.9882"
"","95.3000","4.0291","2.9883"
"","95.4000","4.0343","2.9905"
"","95.5000","4.0376","2.9902"
"","95.6000","4.0426","2.9922"
"","95.7000","4.0461","2.9926"
"","95.8000","4.0511","2.9944"
"","95.9000","4.0547","2.9945"
"","96.0000","4.0593","2.9960"
"","96.1000","4.0630","2.9964"
"","96.2000","4.0677","2.9979"
"","96.3000","4.0715","2.9982"
"","96.4000","4.0761","3.0000"
"","96.5000","4.0803","3.0004"
"","96.6000","4.0847","3.0021"
"","96.7000","4.0886","3.0024"
"","96.8000","4.0930","3.0038"
"","96.9000","4.0972","3.0048"
"","97.0000","4.1015","3.0058"
"","97.1000","4.1055","3.0066"
"","97.2000","4.1099","3.0074"
"","97.3000","4.1139","3.0082"
"","97.4000","4.1183","3.0094"
"","97.5000","4.1224","3.0101"
"","97.6000","4.1270","3.0115"
"","97.7000","4.1310","3.0122"
"","97.8000","4.1356","3.0135"
"","97.9000","4.1393","3.0137"
"","98.0000","4.1442","3.0157"
"","98.1000","4.1480","3.0159"
"","98.2000","4.1526","3.0174"
"","98.3000","4.1561","3.0172"
"","98.4000","4.1609","3.0191"
"","98.5000","4.1645","3.0192"
"","98.6000","4.1693","3.0208"
"","98.7000","4.1731","3.0212"
"","98.8000","4.1781","3.0231"
"","98.9000","4.1817","3.0229"
"","99.0000","4.1864","3.0247"
"","99.1000","4.1901","3.0248"
"","99.2000","4.1949","3.0264"
"","99.3000","4.1985","3.0268"
"","99.4000","4.2032","3.0283"
"","99.5000","4.2069","3.0285"
"","99.6000","4.2115","3.0299"
"","99.7000","4.2155","3.0304"
"","99.8000","4.2200","3.0316"
"","99.9000","4.2242","3.0323"
"","100.0000","4.2286","3.0335"
"","100.1000","4.2326","3.0341"
"","100.2000","4.2369","3.0351"
"","100.3000","4.2414","3.0362"
"","100.4000","4.2454","3.0367"
"","100.5000","4.2499","3.0378"
"","100.6000","4.2536","3.0380"
"","100.7000","4.2582","3.0395"
"","100.8000","4.2620","3.0400"
"","100.9000","4.2666","3.0409"
"","101.0000","4.2705","3.0414"
"","101.1000","4.2754","3.0434"
"","101.2000","4.2790","3.0431"
"","101.3000","4.2837","3.0448"
"","101.4000","4.2875","3.0449"
"","101.5000","4.2921","3.0460"
"","101.6000","4.2960","3.0467"
"","101.7000","4.3003","3.0476"
"","101.8000","4.3042","3.0482"
"","101.9000","4.3090","3.0496"
"","102.0000","4.3128","3.0500"
"","102.1000","4.3173","3.0510"
"","102.2000","4.3215","3.0515"
"","102.3000","4.3259","3.0528"
"","102.4000","4.3301","3.0535"
"","102.5000","4.3344","3.0544"
"","102.6000","4.3385","3.0551"
"","102.7000","4.3430","3.0559"
"","102.8000","4.3470","3.0566"
"","102.9000","4.3511","3.0573"
"","103.0000","4.3553","3.0583"
"","103.1000","4.3595","3.0589"
"","103.2000","4.3637","3.0595"
"","103.3000","4.3682","3.0608"
"","103.4000","4.3723","3.0616"
"","103.5000","4.3768","3.0627"
"","103.6000","4.3807","3.0630"
"","103.7000","4.3852","3.0641"
"","103.8000","4.3892","3.0647"
"","103.9000","4.3938","3.0657"
"","104.0000","4.3974","3.0659"
"","104.1000","4.4022","3.0672"
"","104.2000","4.4059","3.0671"
"","104.3000","4.4106","3.0686"
"","104.4000","4.4143","3.0688"
"","104.5000","4.4194","3.0706"
"","104.6000","4.4229","3.0704"
"","104.7000","4.4279","3.0719"
"","104.8000","4.4313","3.0719"
"","104.9000","4.4365","3.0735"
"","105.0000","4.4399","3.0733"
"","105.1000","4.4447","3.0747"
"","105.2000","4.4482","3.0747"
"","105.3000","4.4531","3.0763"
"","105.4000","4.4565","3.0758"
"","105.5000","4.4616","3.0776"
"","105.6000","4.4652","3.0776"
"","105.7000","4.4701","3.0793"
"","105.8000","4.4738","3.0793"
"","105.9000","4.4785","3.0805"
"","106.0000","4.4821","3.0806"
"","106.1000","4.4871","3.0823"
"","106.2000","4.4907","3.0821"
"","106.3000","4.4953","3.0830"
"","106.4000","4.4991","3.0832"
"","106.5000","4.5036","3.0845"
"","106.6000","4.5076","3.0848"
"","106.7000","4.5123","3.0860"
"","106.8000","4.5163","3.0864"
"","106.9000","4.5208","3.0878"
"","107.0000","4.5247","3.0877"
"","107.1000","4.5292","3.0890"
"","107.2000","4.5333","3.0893"
"","107.3000","4.5378","3.0903"
"","107.4000","4.5415","3.0906"
"","107.5000","4.5461","3.0913"
"","107.6000","4.5499","3.0914"
"","107.7000","4.5544","3.0926"
"","107.8000","4.5584","3.0930"
"","107.9000","4.5631","3.0943"
"","108.0000","4.5671","3.0943"
"","108.1000","4.5716","3.0958"
"","108.2000","4.5751","3.0954"
"","108.3000","4.5801","3.0972"
"","108.4000","4.5837","3.0965"
"","108.5000","4.5886","3.0983"
"","108.6000","4.5919","3.0978"
"","108.7000","4.5971","3.0996"
"","108.8000","4.6005","3.0993"
"","108.9000","4.6055","3.1007"
"","109.0000","4.6090","3.1005"
"","109.1000","4.6142","3.1026"
"","109.2000","4.6175","3.1015"
"","109.3000","4.6227","3.1036"
"","109.4000","4.6261","3.1035"
"","109.5000","4.6312","3.1050"
"","109.6000","4.6346","3.1043"
"","109.7000","4.6393","3.1059"
"","109.8000","4.6430","3.1059"
"","109.9000","4.6476","3.1068"
"","110.0000","4.6514","3.1068"
"","110.1000","4.6561","3.1080"
"","110.2000","4.6601","3.1085"
"","110.3000","4.6647","3.1098"
"","110.4000","4.6687","3.1097"
"","110.5000","4.6730","3.1106"
"","110.6000","4.6772","3.1109"
"","110.7000","4.6816","3.1119"
"","110.8000","4.6854","3.1118"
"","110.9000","4.6897","3.1128"
"","111.0000","4.6941","3.1135"
"","111.1000","4.6981","3.1138"
"","111.2000","4.7025","3.1147"
"","111.3000","4.7066","3.1149"
"","111.4000","4.7111","3.1160"
"","111.5000","4.7154","3.1167"
"","111.6000","4.7195","3.1167"
"","111.7000","4.7238","3.1177"
"","111.8000","4.7282","3.1183"
"","111.9000","4.7322","3.1187"
"","112.0000","4.7364","3.1190"
"","112.1000","4.7406","3.1198"
"","112.2000","4.7447","3.1203"
"","112.3000","4.7493","3.1211"
"","112.4000","4.7530","3.1210"
"","112.5000","4.7576","3.1222"
"","112.6000","4.7620","3.1226"
"","112.7000","4.7662","3.1232"
"","112.8000","4.7701","3.1234"
"","112.9000","4.7748","3.1246"
"","113.0000","4.7786","3.1244"
"","113.1000","4.7831","3.1257"
"","113.2000","4.7872","3.1257"
"","113.3000","4.7914","3.1265"
"","113.4000","4.7955","3.1268"
"","113.5000","4.7999","3.1275"
"","113.6000","4.8041","3.1282"
"","113.7000","4.8086","3.1290"
"","113.8000","4.8127","3.1293"
"","113.9000","4.8169","3.1298"
"","114.0000","4.8214","3.1307"
"","114.1000","4.8253","3.1307"
"","114.2000","4.8299","3.1317"
"","114.3000","4.8336","3.1316"
"","114.4000","4.8382","3.1322"
"","114.5000","4.8419","3.1325"
"","114.6000","4.8466","3.1335"
"","114.7000","4.8503","3.1335"
"","114.8000","4.8555","3.1349"
"","114.9000","4.8590","3.1345"
"","115.0000","4.8638","3.1358"
"","115.1000","4.8674","3.1352"
"","115.2000","4.8722","3.1366"
"","115.3000","4.8758","3.1365"
"","115.4000","4.8807","3.1377"
"","115.5000","4.8842","3.1373"
"","115.6000","4.8890","3.1383"
"","115.7000","4.8926","3.1383"
"","115.8000","4.8974","3.1394"
"","115.9000","4.9013","3.1392"
"","116.0000","4.9061","3.1407"
"","116.1000","4.9098","3.1406"
"","116.2000","4.9145","3.1418"
"","116.3000","4.9183","3.1413"
"","116.4000","4.9230","3.1423"
"","116.5000","4.9269","3.1426"
"","116.6000","4.9313","3.1431"
"","116.7000","4.9352","3.1436"
"","116.8000","4.9396","3.1438"
"","116.9000","4.9436","3.1443"
"","117.0000","4.9483","3.1453"
"","117.1000","4.9524","3.1454"
"","117.2000","4.9568","3.1462"
"","117.3000","4.9607","3.1462"
"","117.4000","4.9651","3.1471"
"","117.5000","4.9691","3.1471"
"","117.6000","4.9737","3.1480"
"","117.7000","4.9774","3.1478"
"","117.8000","4.9821","3.1487"
"","117.9000","4.9859","3.1487"
"","118.0000","4.9904","3.1495"
"","118.1000","4.9943","3.1493"
"","118.2000","4.9993","3.1512"
"","118.3000","5.0030","3.1504"
"","118.4000","5.0078","3.1519"
"","118.5000","5.0112","3.1511"
"","118.6000","5.0164","3.1530"
"","118.7000","5.0200","3.1522"
"","118.8000","5.0248","3.1535"
"","118.9000","5.0281","3.1529"
"","119.0000","5.0331","3.1539"
"","119.1000","5.0364","3.1535"
"","119.2000","5.0415","3.1549"
"","119.3000","5.0451","3.1545"
"","119.4000","5.0503","3.1560"
"","119.5000","5.0537","3.1557"
"","119.6000","5.0586","3.1568"
"","119.7000","5.0620","3.1561"
"","119.8000","5.0670","3.1576"
"","119.9000","5.0707","3.0953"
"","119.9160","5.0715","1.8933"
2,Time,Displacement,Force
,(s),(mm),(kN)
"","0.0000","0.0000","0.0775"
"","0.0200","0.0000","0.0775"
"","0.0400","0.0005","0.0781"
"","0.0600","0.0028","0.0821"
"","0.0800","0.0085","0.0923"
"","0.1000","0.0141","0.1019"
"","0.1200","0.0185","0.1089"
"","0.1400","0.0241","0.1181"
"","0.1600","0.0327","0.1329"
"","0.1800","0.0439","0.1514"
"","0.2000","0.0560","0.1710"
"","0.2200","0.0675","0.1891"
"","0.2400","0.0777","0.2044"
"","0.2600","0.0864","0.2172"
"","0.2800","0.0943","0.2288"
"","0.3000","0.1022","0.2406"
"","0.3200","0.1103","0.2525"
"","0.3400","0.1187","0.2647"
"","0.3600","0.1270","0.2770"
"","0.3800","0.1354","0.2891"
"","0.4000","0.1439","0.3012"
"","0.4200","0.1527","0.3137"
"","0.4400","0.1615","0.3266"
"","0.4600","0.1703","0.3389"
"","0.4800","0.1787","0.3508"
"","0.5000","0.1869","0.3624"
"","0.5200","0.1951","0.3737"
"","0.5400","0.2036","0.3857"
"","0.5600","0.2121","0.3975"
"","0.5800","0.2205","0.4093"
"","0.6000","0.2288","0.4206"
"","0.6200","0.2371","0.4321"
"","0.6400","0.2456","0.4439"
"","0.6600","0.2544","0.4558"
"","0.6800","0.2632","0.4678"
"","0.7000","0.2718","0.4793"
"","0.7200","0.2801","0.4905"
"","0.7400","0.2883","0.5014"
"","0.7600","0.2967","0.5124"
"","0.7800","0.3052","0.5237"
"","0.8000","0.3136","0.5347"
"","0.8200","0.3219","0.5456"
"","0.8400","0.3302","0.5562"
"","0.8600","0.3386","0.5675"
"","0.8800","0.3473","0.5789"
"","0.9000","0.3562","0.5904"
"","0.9200","0.3649","0.6016"
"","0.9400","0.3732","0.6120"
"","0.9600","0.3814","0.6224"
"","0.9800","0.3897","0.6326"
"","1.0000","0.3982","0.6433"
"","1.0200","0.4066","0.6541"
"","1.0400","0.4150","0.6645"
"","1.0600","0.4232","0.6746"
"","1.0800","0.4315","0.6848"
"","1.1000","0.4401","0.6956"
"","1.1200","0.4490","0.7069"
"","1.1400","0.4578","0.7180"
"","1.1600","0.4663","0.7283"
"","1.1800","0.4745","0.7382"
"","1.2000","0.4828","0.7484"
"","1.2200","0.4912","0.7585"
"","1.2400","0.4997","0.7691"
"","1.2600","0.5081","0.7795"
"","1.2800","0.5164","0.7896"
"","1.3000","0.5246","0.7997"
"","1.3200","0.5331","0.8099"
"","1.3400","0.5418","0.8210"
"","1.3600","0.5507","0.8318"
"","1.3800","0.5595","0.8425"
"","1.4000","0.5680","0.8528"
"","1.4200","0.5764","0.8628"
"","1.4400","0.5848","0.8729"
"","1.4600","0.5932","0.8829"
"","1.4800","0.6015","0.8929"
"","1.5000","0.6097","0.9027"
[...]
"","19.1200","8.0660","1.2931"
"","19.1600","8.0830","1.2916"
"","19.2000","8.0999","1.2898"
"","19.2400","8.1162","1.2876"
"","19.2800","8.1335","1.2866"
"","19.3200","8.1509","1.2851"
"","19.3600","8.1674","1.2832"
"","19.4000","8.1841","1.2817"
"","19.4400","8.2008","1.2802"
"","19.4800","8.2175","1.2787"
"","19.5200","8.2351","1.2772"
"","19.5600","8.2522","1.2757"
"","19.6000","8.2688","1.2742"
"","19.6400","8.2858","1.2728"
"","19.6800","8.3024","1.2711"
"","19.7200","8.3193","1.2694"
"","19.7600","8.3370","1.2683"
"","19.8000","8.3538","1.2669"
"","19.8400","8.3705","1.2653"
"","19.8800","8.3875","1.2636"
"","19.9200","8.4040","1.2619"
"","19.9600","8.4212","1.2609"
"","20.0000","8.4389","1.2600"
"","20.0400","8.4553","1.2576"
"","20.0800","8.4720","1.2561"
"","20.1200","8.4888","1.2548"
"","20.1600","8.5052","1.2528"
"","20.2000","8.5228","1.2518"
"","20.2400","8.5403","1.2504"
"","20.2800","8.5568","1.2490"
"","20.3200","8.5738","1.2476"
"","20.3600","8.5903","1.2456"
"","20.4000","8.6071","1.2439"
"","20.4400","8.6249","1.2435"
"","20.4800","8.6419","1.2420"
"","20.5200","8.6584","1.2398"
"","20.5600","8.6754","1.2385"
"","20.6000","8.6919","1.2368"
"","20.6400","8.7091","1.2355"
"","20.6800","8.7267","1.2347"
"","20.7200","8.7433","1.2328"
"","20.7600","8.7599","1.2314"
"","20.8000","8.7768","1.2298"
"","20.8400","8.7935","1.2281"
"","20.8800","8.8109","1.2269"
"","20.9200","8.8281","1.2257"
"","20.9600","8.8446","1.2240"
"","21.0000","8.8614","1.2224"
"","21.0400","8.8781","1.2206"
"","21.0800","8.8950","1.2193"
"","21.1200","8.9126","1.2186"
"","21.1600","8.9295","1.2167"
"","21.2000","8.9461","1.2150"
"","21.2400","8.9632","1.2141"
"","21.2800","8.9799","1.2127"
"","21.3200","8.9967","1.2110"
"","21.3600","9.0143","1.2102"
"","21.4000","9.0313","1.2088"
"","21.4400","9.0480","1.2071"
"","21.4800","9.0647","1.2054"
"","21.5200","9.0811","1.2039"
"","21.5600","9.0984","1.2029"
"","21.6000","9.1159","1.2018"
"","21.6400","9.1325","1.2001"
"","21.6800","9.1494","1.1987"
"","21.7200","9.1662","1.1976"
"","21.7600","9.1829","1.1959"
"","21.8000","9.2003","1.1949"
"","21.8400","9.2177","1.1940"
"","21.8800","9.2344","1.1920"
"","21.9200","9.2513","1.1912"
"","21.9600","9.2678","1.1889"
"","22.0000","9.2846","1.1876"
"","22.0400","9.3023","1.1872"
"","22.0800","9.3192","1.1855"
"","22.1200","9.3357","1.1838"
"","22.1600","9.3525","1.1825"
"","22.2000","9.3692","1.1811"
"","22.2400","9.3863","1.1800"
"","22.2800","9.4039","1.1789"
"","22.3200","9.4206","1.1774"
"","22.3600","9.4373","1.1763"
"","22.4000","9.4541","1.1747"
"","22.4400","9.4707","1.1729"
"","22.4800","9.4880","1.1723"
"","22.5200","9.5055","1.1715"
"","22.5600","9.5222","1.1697"
"","22.6000","9.5390","1.1681"
"","22.6400","9.5556","1.1671"
"","22.6800","9.5723","1.1654"
"","22.7200","9.5897","1.1646"
"","22.7600","9.6069","1.1636"
"","22.8000","9.6235","1.1622"
"","22.8400","9.6404","1.1609"
"","22.8800","9.6569","1.1591"
"","22.9200","9.6738","1.1581"
"","22.9600","9.6916","1.1575"
"","23.0000","9.7085","1.1562"
"","23.0400","9.7250","1.1551"
"","23.0800","9.7419","1.1538"
"","23.1200","9.7586","1.1519"
"","23.1600","9.7759","1.1513"
"","23.2000","9.7935","1.1506"
"","23.2400","9.8102","1.1492"
"","23.2800","9.8269","1.1477"
"","23.3200","9.8436","1.1466"
"","23.3600","9.8602","1.1449"
"","23.4000","9.8778","1.1440"
"","23.4400","9.8951","1.1435"
"","23.4800","9.9115","1.1420"
"","23.5200","9.9283","1.1406"
"","23.5600","9.9450","1.1394"
"","23.6000","9.9619","1.1381"
"","23.6400","9.9795","1.1373"
"","23.6800","9.9965","1.1364"
"","23.7200","10.0130","1.1347"
"","23.7600","10.0298","1.1335"
"","23.8000","10.0465","1.1323"
"","23.8400","10.0636","1.1314"
"","23.8800","10.0812","1.1309"
"","23.9200","10.0980","1.1294"
"","23.9600","10.1147","1.1280"
"","24.0000","10.1315","1.1272"
"","24.0400","10.1481","1.1258"
"","24.0800","10.1655","1.1250"
"","24.1200","10.1829","1.1242"
"","24.1600","10.1994","1.1228"
"","24.2000","10.2162","1.1217"
"","24.2400","10.2330","1.1205"
"","24.2800","10.2497","1.1194"
"","24.3200","10.2672","1.1184"
"","24.3600","10.2841","1.1174"
"","24.4000","10.3004","1.1158"
"","24.4400","10.3175","1.1153"
"","24.4800","10.3344","1.1140"
"","24.5200","10.3514","1.1128"
"","24.5600","10.3691","1.1124"
"","24.6000","10.3860","1.1114"
"","24.6400","10.4028","1.1105"
"","24.6800","10.4197","1.1090"
"","24.7200","10.4361","1.1079"
"","24.7600","10.4532","1.1072"
"","24.8000","10.4708","1.1064"
"","24.8400","10.4874","1.1052"
"","24.8800","10.5042","1.1040"
"","24.9200","10.5209","1.1032"
"","24.9600","10.5375","1.1015"
"","25.0000","10.5549","1.1010"
"","25.0400","10.5723","1.1004"
"","25.0800","10.5889","1.0992"
"","25.1200","10.6058","1.0984"
"","25.1600","10.6224","1.0972"
"","25.2000","10.6391","1.0961"
"","25.2400","10.6567","1.0956"
"","25.2800","10.6739","1.0949"
"","25.3200","10.6904","1.0935"
"","25.3600","10.7073","1.0925"
"","25.4000","10.7239","1.0916"
"","25.4400","10.7410","1.0906"
"","25.4800","10.7586","1.0901"
"","25.5200","10.7752","1.0887"
"","25.5600","10.7918","1.0875"
"","25.6000","10.8087","1.0871"
"","25.6400","10.8254","1.0860"
"","25.6800","10.8427","1.0854"
"","25.7200","10.8600","1.0845"
"","25.7600","10.8766","1.0834"
"","25.8000","10.8935","1.0826"
"","25.8400","10.9103","1.0817"
"","25.8800","10.9269","1.0807"
"","25.9200","10.9446","1.0805"
"","25.9600","10.9618","1.0797"
"","26.0000","10.9784","1.0783"
"","26.0400","10.9953","1.0778"
"","26.0800","11.0119","1.0766"
"","26.1200","11.0288","1.0758"
"","26.1600","11.0464","1.0755"
"","26.2000","11.0633","1.0746"
"","26.2400","11.0798","1.0731"
"","26.2800","11.0966","1.0726"
"","26.3200","11.1133","1.0716"
"","26.3600","11.1305","1.0708"
"","26.4000","11.1481","1.0705"
"","26.4400","11.1647","1.0696"
"","26.4800","11.1814","1.0685"
"","26.5200","11.1983","1.0676"
"","26.5600","11.2149","1.0666"
"","26.6000","11.2323","1.0662"
"","26.6400","11.2497","1.0657"
"","26.6800","11.2663","1.0651"
"","26.7200","11.2832","1.0640"
"","26.7600","11.2998","1.0631"
"","26.8000","11.3165","1.0622"
"","26.8400","11.3342","1.0619"
"","26.8800","11.3512","1.0614"
"","26.9200","11.3677","1.0604"
"","26.9600","11.3845","1.0593"
"","27.0000","11.4011","1.0584"
"","27.0400","11.4182","1.0579"
"","27.0800","11.4358","1.0576"
"","27.1200","11.4523","1.0565"
"","27.1600","11.4692","1.0556"
"","27.2000","11.4861","1.0552"
"","27.2400","11.5027","1.0544"
"","27.2800","11.5201","1.0539"
"","27.3200","11.5376","1.0536"
"","27.3600","11.5541","1.0526"
"","27.4000","11.5710","1.0519"
"","27.4400","11.5878","1.0512"
"","27.4800","11.6045","1.0501"
"","27.5200","11.6220","1.0500"
"","27.5600","11.6391","1.0496"
"","27.6000","11.6554","1.0484"
"","27.6400","11.6722","1.0478"
"","27.6800","11.6890","1.0473"
"","27.7200","11.7060","1.0464"
"","27.7600","11.7237","1.0463"
"","27.8000","11.7405","1.0457"
"","27.8400","11.7572","1.0448"
"","27.8800","11.7742","1.0443"
"","27.9200","11.7907","1.0434"
"","27.9600","11.8077","1.0428"
"","28.0000","11.8254","1.0428"
"","28.0400","11.8421","1.0419"
"","28.0800","11.8589","1.0415"
"","28.1200","11.8758","1.0411"
"","28.1600","11.8922","1.0402"
"","28.2000","11.9096","1.0398"
"","28.2400","11.9270","1.0394"
"","28.2800","11.9434","1.0384"
"","28.3200","11.9603","1.0379"
"","28.3600","11.9770","1.0373"
"","28.4000","11.9937","1.0363"
"","28.4400","12.0114","1.0366"
"","28.4800","12.0285","1.0360"
"","28.5200","12.0449","1.0350"
"","28.5600","12.0618","1.0346"
"","28.6000","12.0784","1.0337"
"","28.6400","12.0955","1.0336"
"","28.6800","12.1133","1.0336"
"","28.7200","12.1301","1.0330"
"","28.7600","12.1468","1.0325"
"","28.8000","12.1637","1.0319"
"","28.8400","12.1801","1.0311"
"","28.8800","12.1974","1.0309"
"","28.9200","12.2149","1.0305"
"","28.9600","12.2313","1.0298"
"","29.0000","12.2481","1.0291"
"","29.0400","12.2650","1.0286"
"","29.0800","12.2817","1.0280"
"","29.1200","12.2993","1.0280"
"","29.1600","12.3165","1.0278"
"","29.2000","12.3328","1.0263"
"","29.2400","12.3497","1.0262"
"","29.2800","12.3666","1.0257"
"","29.3200","12.3836","1.0253"
"","29.3600","12.4011","1.0251"
"","29.4000","12.4179","1.0244"
"","29.4400","12.4344","1.0239"
"","29.4800","12.4513","1.0233"
"","29.5200","12.4679","1.0225"
"","29.5600","12.4852","1.0224"
"","29.6000","12.5028","1.0225"
"","29.6400","12.5193","1.0215"
"","29.6800","12.5361","1.0209"
"","29.7200","12.5529","1.0204"
"","29.7600","12.5695","1.0198"
"","29.8000","12.5867","1.0199"
"","29.8400","12.6040","1.0195"
"","29.8800","12.6208","1.0188"
"","29.9200","12.6378","1.0183"
"","29.9600","12.6543","1.0178"
"","30.0000","12.6711","1.0172"
"","30.0400","12.6887","1.0172"
"","30.0800","12.7058","1.0168"
"","30.1200","12.7224","1.0161"
"","30.1600","12.7394","1.0160"
"","30.2000","12.7560","1.0152"
"","30.2400","12.7730","1.0151"
"","30.2800","12.7905","1.0151"
"","30.3200","12.8071","1.0143"
"","30.3600","12.8240","1.0141"
"","30.4000","12.8410","1.0135"
"","30.4400","12.8574","1.0129"
"","30.4800","12.8746","1.0130"
"","30.5200","12.8923","1.0128"
"","30.5600","12.9089","1.0123"
"","30.6000","12.9257","1.0117"
"","30.6400","12.9423","1.0112"
"","30.6800","12.9590","1.0108"
"","30.7200","12.9766","1.0109"
"","30.7600","12.9939","1.0105"
"","30.8000","13.0104","1.0100"
"","30.8400","13.0270","1.0093"
"","30.8800","13.0435","1.0088"
"","30.9200","13.0606","1.0085"
"","30.9600","13.0784","1.0086"
"","31.0000","13.0953","1.0082"
"","31.0400","13.1118","1.0078"
"","31.0800","13.1287","1.0075"
"","31.1200","13.1453","1.0067"
"","31.1600","13.1624","1.0064"
"","31.2000","13.1798","1.0063"
"","31.2400","13.1964","1.0058"
"","31.2800","13.2133","1.0055"
"","31.3200","13.2302","1.0051"
"","31.3600","13.2468","1.0048"
"","31.4000","13.2642","1.0049"
"","31.4400","13.2817","1.0046"
"","31.4800","13.2984","1.0041"
"","31.5200","13.3151","1.0038"
"","31.5600","13.3318","1.0031"
"","31.6000","13.3485","1.0030"
"","31.6400","13.3662","1.0032"
"","31.6800","13.3832","1.0028"
"","31.7200","13.3997","1.0021"
"","31.7600","13.4165","1.0019"
"","31.8000","13.4331","1.0012"
"","31.8400","13.4502","1.0012"
"","31.8800","13.4679","1.0012"
"","31.9200","13.4847","1.0006"
"","31.9600","13.5013","1.0004"
"","32.0000","13.5182","0.9999"
"","32.0400","13.5349","0.9995"
"","32.0800","13.5522","0.9997"
"","32.1200","13.5698","0.9996"
"","32.1600","13.5861","0.9988"
"","32.2000","13.6029","0.9985"
"","32.2400","13.6196","0.9979"
"","32.2800","13.6363","0.9975"
"","32.3200","13.6539","0.9978"
"","32.3600","13.6711","0.9973"
"","32.4000","13.6875","0.9967"
"","32.4400","13.7043","0.9966"
"","32.4800","13.7210","0.9960"
"","32.5200","13.7379","0.9957"
"","32.5600","13.7555","0.9958"
"","32.6000","13.7724","0.9954"
"","32.6400","13.7891","0.9953"
"","32.6800","13.8061","0.9948"
"","32.7200","13.8226","0.9941"
"","32.7600","13.8397","0.9945"
"","32.8000","13.8573","0.9943"
"","32.8400","13.8741","0.9940"
"","32.8800","13.8910","0.9937"
"","32.9200","13.9078","0.9933"
"","32.9600","13.9244","0.9929"
"","33.0000","13.9416","0.9930"
"","33.0400","13.9589","0.9927"
"","33.0800","13.9755","0.9924"
"","33.1200","13.9924","0.9920"
"","33.1600","14.0091","0.9917"
"","33.2000","14.0258","0.9916"
"","33.2400","14.0434","0.9918"
"","33.2800","14.0606","0.9912"
"","33.3200","14.0772","0.9911"
"","33.3600","14.0940","0.9907"
"","33.4000","14.1106","0.9903"
"","33.4400","14.1275","0.9903"
"","33.4800","14.1452","0.9903"
"","33.5200","14.1621","0.9898"
"","33.5600","14.1787","0.9897"
"","33.6000","14.1956","0.9893"
"","33.6400","14.2121","0.9888"
"","33.6800","14.2292","0.9890"
"","33.7200","14.2469","0.9891"
"","33.7600","14.2636","0.9890"
"","33.8000","14.2803","0.9884"
"","33.8400","14.2969","0.9878"
"","33.8800","14.3135","0.9876"
"","33.9200","14.3311","0.9878"
"","33.9600","14.3484","0.9877"
"","34.0000","14.3649","0.9875"
"","34.0400","14.3816","0.9873"
"","34.0800","14.3981","0.9862"
"","34.1200","14.4150","0.9867"
"","34.1600","14.4329","0.9870"
"","34.2000","14.4500","0.9868"
"","34.2400","14.4666","0.9863"
"","34.2800","14.4835","0.9860"
"","34.3200","14.5001","0.9856"
"","34.3600","14.5173","0.9854"
"","34.4000","14.5348","0.9856"
"","34.4400","14.5513","0.9853"
"","34.4800","14.5680","0.9849"
"","34.5200","14.5848","0.9848"
"","34.5600","14.6016","0.9845"
"","34.6000","14.6190","0.9843"
"","34.6400","14.6363","0.9844"
"","34.6800","14.6529","0.9842"
"","34.7200","14.6697","0.9836"
"","34.7600","14.6865","0.9832"
"","34.8000","14.7033","0.9832"
"","34.8400","14.7209","0.9837"
"","34.8800","14.7380","0.9833"
"","34.9200","14.7545","0.9828"
"","34.9600","14.7715","0.9825"
"","35.0000","14.7881","0.9820"
"","35.0400","14.8049","0.9821"
"","35.0800","14.8225","0.9823"
"","35.1200","14.8393","0.9819"
"","35.1600","14.8560","0.9815"
"","35.2000","14.8729","0.9813"
"","35.2400","14.8894","0.9810"
"","35.2800","14.9065","0.9808"
"","35.3200","14.9241","0.9812"
"","35.3600","14.9407","0.9806"
"","35.4000","14.9574","0.9803"
"","35.4400","14.9743","0.9801"
"","35.4800","14.9910","0.9798"
"","35.5200","15.0085","0.9798"
"","35.5600","15.0257","0.9800"
"","35.6000","15.0422","0.9798"
"","35.6400","15.0592","0.9796"
"","35.6800","15.0759","0.9792"
"","35.7200","15.0927","0.9789"
"","35.7600","15.1103","0.9791"
"","35.8000","15.1272","0.9792"
"","35.8400","15.1438","0.9785"
"","35.8800","15.1607","0.9783"
"","35.9200","15.1771","0.9780"
"","35.9600","15.1941","0.9778"
"","36.0000","15.2119","0.9781"
"","36.0400","15.2287","0.9779"
"","36.0800","15.2455","0.9777"
"","36.1200","15.2624","0.9775"
"","36.1600","15.2790","0.9769"
"","36.2000","15.2963","0.9772"
"","36.2400","15.3138","0.9773"
"","36.2800","15.3303","0.9767"
"","36.3200","15.3472","0.9765"
"","36.3600","15.3638","0.9764"
"","36.4000","15.3805","0.9762"
"","36.4400","15.3981","0.9762"
"","36.4800","15.4152","0.9762"
"","36.5200","15.4317","0.9756"
"","36.5600","15.4486","0.9760"
"","36.6000","15.4652","0.9755"
"","36.6400","15.4820","0.9752"
"","36.6800","15.4997","0.9754"
"","36.7200","15.5166","0.9754"
"","36.7600","15.5331","0.9749"
"","36.8000","15.5499","0.9750"
"","36.8400","15.5667","0.9746"
"","36.8800","15.5840","0.9746"
"","36.9200","15.6016","0.9752"
"","36.9600","15.6183","0.9747"
"","37.0000","15.6350","0.9744"
"","37.0400","15.6517","0.9745"
"","37.0800","15.6683","0.9740"
"","37.1200","15.6858","0.9743"
"","37.1600","15.7032","0.9742"
"","37.2000","15.7196","0.9737"
"","37.2400","15.7364","0.9733"
"","37.2800","15.7530","0.9732"
"","37.3200","15.7695","0.9725"
"","37.3600","15.7872","0.9732"
"","37.4000","15.8046","0.9736"
"","37.4400","15.8211","0.9731"
"","37.4800","15.8380","0.9729"
"","37.5200","15.8548","0.9730"
"","37.5600","15.8720","0.9730"
"","37.6000","15.8897","0.9732"
"","37.6400","15.9062","0.9731"
"","37.6800","15.9228","0.9728"
"","37.7200","15.9397","0.9726"
"","37.7600","15.9565","0.9722"
"","37.8000","15.9738","0.9725"
"","37.8400","15.9910","0.9725"
"","37.8800","16.0074","0.9720"
"","37.9200","16.0243","0.9717"
"","37.9600","16.0409","0.9714"
"","38.0000","16.0576","0.9714"
"","38.0400","16.0753","0.9718"
"","38.0800","16.0925","0.9716"
"","38.1200","16.1091","0.9716"
"","38.1600","16.1260","0.9716"
"","38.2000","16.1425","0.9711"
"","38.2400","16.1594","0.9710"
"","38.2800","16.1770","0.9716"
"","38.3200","16.1940","0.9710"
"","38.3600","16.2109","0.9712"
"","38.4000","16.2277","0.9710"
"","38.4400","16.2441","0.9706"
"","38.4800","16.2613","0.9705"
"","38.5200","16.2788","0.9708"
"","38.5600","16.2955","0.9704"
"","38.6000","16.3121","0.9703"
"","38.6400","16.3288","0.9701"
"","38.6800","16.3455","0.9698"
"","38.7200","16.3630","0.9699"
"","38.7600","16.3803","0.9702"
"","38.8000","16.3969","0.9700"
"","38.8400","16.4139","0.9698"
"","38.8800","16.4305","0.9693"
"","38.9200","16.4473","0.9692"
"","38.9600","16.4650","0.9698"
"","39.0000","16.4822","0.9698"
"","39.0400","16.4987","0.9694"
"","39.0800","16.5155","0.9690"
"","39.1200","16.5319","0.9686"
"","39.1600","16.5490","0.9685"
"","39.2000","16.5668","0.9691"
"","39.2400","16.5835","0.9689"
"","39.2800","16.6001","0.9684"
"","39.3200","16.6169","0.9684"
"","39.3600","16.6334","0.9681"
"","39.4000","16.6508","0.9681"
"","39.4400","16.6683","0.9684"
"","39.4800","16.6848","0.9681"
"","39.5200","16.7016","0.9676"
"","39.5600","16.7183","0.9675"
"","39.6000","16.7352","0.9675"
"","39.6400","16.7527","0.9680"
"","39.6800","16.7698","0.9677"
"","39.7200","16.7863","0.9674"
"","39.7600","16.8034","0.9675"
"","39.8000","16.8201","0.9669"
"","39.8400","16.8370","0.9668"
"","39.8800","16.8545","0.9670"
"","39.9200","16.8713","0.9666"
"","39.9600","16.8879","0.9663"
"","40.0000","16.9046","0.9660"
"","40.0400","16.9212","0.9658"
"","40.0800","16.9385","0.9659"
"","40.1200","16.9561","0.9663"
"","40.1600","16.9727","0.9653"
"","40.2000","16.9897","0.9651"
"","40.2400","17.0065","0.9652"
"","40.2800","17.0231","0.9645"
"","40.3200","17.0405","0.9644"
"","40.3600","17.0579","0.9648"
"","40.4000","17.0745","0.9639"
"","40.4400","17.0914","0.9636"
"","40.4800","17.1080","0.9632"
"","40.5200","17.1245","0.9626"
"","40.5600","17.1421","0.9628"
"","40.6000","17.1592","0.9625"
"","40.6400","17.1759","0.9619"
"","40.6800","17.1927","0.9613"
"","40.7200","17.2092","0.9606"
"","40.7600","17.2263","0.9602"
"","40.8000","17.2440","0.9602"
"","40.8400","17.2607","0.9593"
"","40.8800","17.2773","0.9584"
"","40.9200","17.2942","0.9577"
"","40.9600","17.3108","0.9567"
"","41.0000","17.3282","0.9559"
"","41.0400","17.3457","0.9551"
"","41.0800","17.3623","0.9534"
"","41.1200","17.3792","0.9519"
"","41.1600","17.3959","0.9497"
"","41.2000","17.4125","0.9479"
"","41.2400","17.4300","0.9459"
"","41.2800","17.4472","0.9428"
"","41.3200","17.4638","0.9387"
"","41.3600","17.4806","0.9333"
"","41.4000","17.4972","0.9256"
"","41.4400","17.5139","0.9085"
"","41.4730","17.5285","0.5902"
"","41.5000","17.5404","0.0659"
"","41.5400","17.5573","-0.0335"
"","41.5800","17.5741","-0.0036"
"","41.6200","17.5906","-0.0031"
"","41.6600","17.6072","-0.0035"
"","41.7000","17.6249","-0.0036"
"","41.7400","17.6421","-0.0039"
"","41.7800","17.6588","-0.0041"
"","41.8200","17.6756","-0.0038"
"","41.8600","17.6920","-0.0040"
"","41.9000","17.7090","-0.0038"
"","41.9400","17.7267","-0.0037"
"","41.9800","17.7435","-0.0037"
"","42.0200","17.7600","-0.0038"
"","42.0600","17.7768","-0.0038"
"","42.1000","17.7932","-0.0040"
"","42.1400","17.8105","-0.0038"
"","42.1800","17.8282","-0.0037"
"","42.2200","17.8449","-0.0040"
"","42.2600","17.8616","-0.0037"
"","42.3000","17.8782","-0.0036"
"","42.3400","17.8949","-0.0040"
"","42.3800","17.9125","-0.0037"
"","42.4200","17.9298","-0.0037"
"","42.4600","17.9464","-0.0038"
"","42.5000","17.9633","-0.0039"
"","42.5400","17.9800","-0.0038"
"","42.5800","17.9968","-0.0040"
"","42.6200","18.0145","-0.0037"
"","42.6600","18.0313","-0.0038"
"","42.7000","18.0477","-0.0038"
"","42.7400","18.0646","-0.0038"
"","42.7800","18.0813","-0.0035"
"","42.8200","18.0985","-0.0036"
"","42.8600","18.1161","-0.0038"
"","42.9000","18.1327","-0.0039"
"","42.9400","18.1493","-0.0037"
"","42.9800","18.1663","-0.0039"
"","43.0200","18.1831","-0.0040"
"","43.0600","18.2005","-0.0036"
"","43.1000","18.2179","-0.0036"
"","43.1400","18.2344","-0.0038"
"","43.1800","18.2512","-0.0036"
"","43.2200","18.2679","-0.0036"
"","43.2600","18.2845","-0.0040"
"","43.3000","18.3022","-0.0039"
"","43.3400","18.3193","-0.0037"
"","43.3800","18.3358","-0.0035"
"","43.4200","18.3529","-0.0036"
"","43.4600","18.3695","-0.0037"
"","43.5000","18.3862","-0.0034"
"","43.5400","18.4037","-0.0039"
"","43.5800","18.4206","-0.0038"
"","43.6200","18.4374","-0.0034"
"","43.6600","18.4544","-0.0037"
"","43.7000","18.4708","-0.0037"
"","43.7400","18.4877","-0.0038"
"","43.7800","18.5051","-0.0038"
"","43.8200","18.5221","-0.0037"
"","43.8600","18.5392","-0.0039"
"","43.9000","18.5559","-0.0037"
"","43.9400","18.5723","-0.0037"
"","43.9800","18.5899","-0.0038"
"","44.0200","18.6073","-0.0038"
"","44.0600","18.6238","-0.0037"
"","44.0960","18.6387","-0.0037"